Workbook

Sheet Summary
A1: Brazil: average new-vehicle price by vehicle type and forecast to 2050
A2: All values are live formulas. Change the scenario and statistic on the Assumptions sheet. Base year 2022; prices per vehicle.
A3: Scenario: | B3: =Assumptions!B7 -> Base | C3: =Assumptions!B10&" used for road base prices; real R$ = constant 2022 prices" -> Mean used for road base prices; real R$ = constant 2022 prices
G4: Real R$ per vehicle (constant 2022 prices)
A5: Mode | B5: Vehicle type | C5: What the price represents | D5: Observations / benchmarks (n) | E5: 2022 base, R$ (constant) | F5: 2022 base, US$ (constant) | G5: 2030 | H5: 2035 | I5: 2040 | J5: 2045 | K5: 2050 | L5: 2050 nominal, R$ | M5: Real CAGR 2022-2050 | N5: Confidence | O5: Main sources
A6: Road | B6: Road - Passenger LDV | C6: Cars, SUVs, sports cars, luxury (FIPE 0-km listings, 2022) | D6: ='Road Avg'!$B$6 -> 8968 | E6: =Forecast!$E$10 -> 427911.79 | F6: =Forecast!$E$38 -> 82852.105 | G6: {=INDEX(Forecast!$E$10:$AG$10,MATCH(G$5,Forecast!$E$5:$AG$5,0))} -> 427911.79 | H6: {=INDEX(Forecast!$E$10:$AG$10,MATCH(H$5,Forecast!$E$5:$AG$5,0))} -> 427911.79 | I6: {=INDEX(Forecast!$E$10:$AG$10,MATCH(I$5,Forecast!$E$5:$AG$5,0))} -> 427911.79 | J6: {=INDEX(Forecast!$E$10:$AG$10,MATCH(J$5,Forecast!$E$5:$AG$5,0))} -> 427911.79 | K6: {=INDEX(Forecast!$E$10:$AG$10,MATCH(K$5,Forecast!$E$5:$AG$5,0))} -> 427911.79 | L6: {=INDEX(Forecast!$E$24:$AG$24,MATCH(Assumptions!$B$5,Forecast!$E$5:$AG$5,0))} -> 1036613.2 | M6: =(K6/E6)^(1/(Assumptions!$B$5-Assumptions!$B$4))-1 -> 0 | N6: High | O6: FIPE (your file)
A7: Road | B7: Road - Passenger HDV | C7: Minibuses / passenger vans > 3,856 kg GVW (Sprinter 416/516 VAN, Ducato Multi, Transit Minibus). No full-size buses in dataset | D7: ='Road Avg'!$B$7 -> 281 | E7: =Forecast!$E$11 -> 298836.74 | F7: =Forecast!$E$39 -> 57860.648 | G7: {=INDEX(Forecast!$E$11:$AG$11,MATCH(G$5,Forecast!$E$5:$AG$5,0))} -> 298836.74 | H7: {=INDEX(Forecast!$E$11:$AG$11,MATCH(H$5,Forecast!$E$5:$AG$5,0))} -> 298836.74 | I7: {=INDEX(Forecast!$E$11:$AG$11,MATCH(I$5,Forecast!$E$5:$AG$5,0))} -> 298836.74 | J7: {=INDEX(Forecast!$E$11:$AG$11,MATCH(J$5,Forecast!$E$5:$AG$5,0))} -> 298836.74 | K7: {=INDEX(Forecast!$E$11:$AG$11,MATCH(K$5,Forecast!$E$5:$AG$5,0))} -> 298836.74 | L7: {=INDEX(Forecast!$E$25:$AG$25,MATCH(Assumptions!$B$5,Forecast!$E$5:$AG$5,0))} -> 723929.84 | M7: =(K7/E7)^(1/(Assumptions!$B$5-Assumptions!$B$4))-1 -> 0 | N7: Medium | O7: FIPE (your file)
A8: Road | B8: Road - Freight LDV | C8: Pickups, cargo vans, light trucks <= 3,856 kg GVW | D8: ='Road Avg'!$B$8 -> 2030 | E8: =Forecast!$E$12 -> 212826.35 | F8: =Forecast!$E$40 -> 41207.35 | G8: {=INDEX(Forecast!$E$12:$AG$12,MATCH(G$5,Forecast!$E$5:$AG$5,0))} -> 212826.35 | H8: {=INDEX(Forecast!$E$12:$AG$12,MATCH(H$5,Forecast!$E$5:$AG$5,0))} -> 212826.35 | I8: {=INDEX(Forecast!$E$12:$AG$12,MATCH(I$5,Forecast!$E$5:$AG$5,0))} -> 212826.35 | J8: {=INDEX(Forecast!$E$12:$AG$12,MATCH(J$5,Forecast!$E$5:$AG$5,0))} -> 212826.35 | K8: {=INDEX(Forecast!$E$12:$AG$12,MATCH(K$5,Forecast!$E$5:$AG$5,0))} -> 212826.35 | L8: {=INDEX(Forecast!$E$26:$AG$26,MATCH(Assumptions!$B$5,Forecast!$E$5:$AG$5,0))} -> 515570.28 | M8: =(K8/E8)^(1/(Assumptions!$B$5-Assumptions!$B$4))-1 -> 0 | N8: High | O8: FIPE (your file)
A9: Road | B9: Road - Freight HDV | C9: Iveco Daily 45-70, Sprinter 416/516 chassis & vans, Ram 2500/3500 (> 3,856 kg GVW). No heavy trucks in dataset | D9: ='Road Avg'!$B$9 -> 353 | E9: =Forecast!$E$13 -> 295851.61 | F9: =Forecast!$E$41 -> 57282.668 | G9: {=INDEX(Forecast!$E$13:$AG$13,MATCH(G$5,Forecast!$E$5:$AG$5,0))} -> 295851.61 | H9: {=INDEX(Forecast!$E$13:$AG$13,MATCH(H$5,Forecast!$E$5:$AG$5,0))} -> 295851.61 | I9: {=INDEX(Forecast!$E$13:$AG$13,MATCH(I$5,Forecast!$E$5:$AG$5,0))} -> 295851.61 | J9: {=INDEX(Forecast!$E$13:$AG$13,MATCH(J$5,Forecast!$E$5:$AG$5,0))} -> 295851.61 | K9: {=INDEX(Forecast!$E$13:$AG$13,MATCH(K$5,Forecast!$E$5:$AG$5,0))} -> 295851.61 | L9: {=INDEX(Forecast!$E$27:$AG$27,MATCH(Assumptions!$B$5,Forecast!$E$5:$AG$5,0))} -> 716698.38 | M9: =(K9/E9)^(1/(Assumptions!$B$5-Assumptions!$B$4))-1 -> 0 | N9: Medium | O9: FIPE (your file)
A10: Motorbike | B10: Motorbike - Passenger | C10: Honda CG 160, Biz, Pop 110i weighted by 2022 registrations | D10: ='NonRoad Avg'!$C$6 -> 6 | E10: =Forecast!$E$14 -> 11475.445 | F10: =Forecast!$E$42 -> 2221.8709 | G10: {=INDEX(Forecast!$E$14:$AG$14,MATCH(G$5,Forecast!$E$5:$AG$5,0))} -> 11475.445 | H10: {=INDEX(Forecast!$E$14:$AG$14,MATCH(H$5,Forecast!$E$5:$AG$5,0))} -> 11475.445 | I10: {=INDEX(Forecast!$E$14:$AG$14,MATCH(I$5,Forecast!$E$5:$AG$5,0))} -> 11475.445 | J10: {=INDEX(Forecast!$E$14:$AG$14,MATCH(J$5,Forecast!$E$5:$AG$5,0))} -> 11475.445 | K10: {=INDEX(Forecast!$E$14:$AG$14,MATCH(K$5,Forecast!$E$5:$AG$5,0))} -> 11475.445 | L10: {=INDEX(Forecast!$E$28:$AG$28,MATCH(Assumptions!$B$5,Forecast!$E$5:$AG$5,0))} -> 27799.182 | M10: =(K10/E10)^(1/(Assumptions!$B$5-Assumptions!$B$4))-1 -> 0 | N10: Medium | O10: Bem Parana; Motonline; Tabela FIPE Brasil (Fenabrave)
A11: Motorbike | B11: Motorbike - Freight | C11: Honda CG 160 Cargo | D11: ='NonRoad Avg'!$C$7 -> 1 | E11: =Forecast!$E$15 -> 12587.82 | F11: =Forecast!$E$43 -> 2437.2485 | G11: {=INDEX(Forecast!$E$15:$AG$15,MATCH(G$5,Forecast!$E$5:$AG$5,0))} -> 12587.82 | H11: {=INDEX(Forecast!$E$15:$AG$15,MATCH(H$5,Forecast!$E$5:$AG$5,0))} -> 12587.82 | I11: {=INDEX(Forecast!$E$15:$AG$15,MATCH(I$5,Forecast!$E$5:$AG$5,0))} -> 12587.82 | J11: {=INDEX(Forecast!$E$15:$AG$15,MATCH(J$5,Forecast!$E$5:$AG$5,0))} -> 12587.82 | K11: {=INDEX(Forecast!$E$15:$AG$15,MATCH(K$5,Forecast!$E$5:$AG$5,0))} -> 12587.82 | L11: {=INDEX(Forecast!$E$29:$AG$29,MATCH(Assumptions!$B$5,Forecast!$E$5:$AG$5,0))} -> 30493.903 | M11: =(K11/E11)^(1/(Assumptions!$B$5-Assumptions!$B$4))-1 -> 0 | N11: Low | O11: Bem Parana
A12: Aircraft | B12: Aircraft - Passenger | C12: A320neo, 737 MAX 8, E195-E2 | D12: ='NonRoad Avg'!$C$8 -> 3 | E12: =Forecast!$E$16 -> 2.2354408e+08 | F12: =Forecast!$E$44 -> 43282513 | G12: {=INDEX(Forecast!$E$16:$AG$16,MATCH(G$5,Forecast!$E$5:$AG$5,0))} -> 2.2354408e+08 | H12: {=INDEX(Forecast!$E$16:$AG$16,MATCH(H$5,Forecast!$E$5:$AG$5,0))} -> 2.2354408e+08 | I12: {=INDEX(Forecast!$E$16:$AG$16,MATCH(I$5,Forecast!$E$5:$AG$5,0))} -> 2.2354408e+08 | J12: {=INDEX(Forecast!$E$16:$AG$16,MATCH(J$5,Forecast!$E$5:$AG$5,0))} -> 2.2354408e+08 | K12: {=INDEX(Forecast!$E$16:$AG$16,MATCH(K$5,Forecast!$E$5:$AG$5,0))} -> 2.2354408e+08 | L12: {=INDEX(Forecast!$E$30:$AG$30,MATCH(Assumptions!$B$5,Forecast!$E$5:$AG$5,0))} -> 5.4153391e+08 | M12: =(K12/E12)^(1/(Assumptions!$B$5-Assumptions!$B$4))-1 -> 0 | N12: Medium | O12: InsideFlyer; AirDataNews
A13: Aircraft | B13: Aircraft - Freight | C13: Converted 737-800BCF and A321P2F freighters | D13: ='NonRoad Avg'!$C$9 -> 2 | E13: =Forecast!$E$17 -> 1.1367651e+08 | F13: =Forecast!$E$45 -> 22010000 | G13: {=INDEX(Forecast!$E$17:$AG$17,MATCH(G$5,Forecast!$E$5:$AG$5,0))} -> 1.1367651e+08 | H13: {=INDEX(Forecast!$E$17:$AG$17,MATCH(H$5,Forecast!$E$5:$AG$5,0))} -> 1.1367651e+08 | I13: {=INDEX(Forecast!$E$17:$AG$17,MATCH(I$5,Forecast!$E$5:$AG$5,0))} -> 1.1367651e+08 | J13: {=INDEX(Forecast!$E$17:$AG$17,MATCH(J$5,Forecast!$E$5:$AG$5,0))} -> 1.1367651e+08 | K13: {=INDEX(Forecast!$E$17:$AG$17,MATCH(K$5,Forecast!$E$5:$AG$5,0))} -> 1.1367651e+08 | L13: {=INDEX(Forecast!$E$31:$AG$31,MATCH(Assumptions!$B$5,Forecast!$E$5:$AG$5,0))} -> 2.7538053e+08 | M13: =(K13/E13)^(1/(Assumptions!$B$5-Assumptions!$B$4))-1 -> 0 | N13: Medium | O13: IBA; STAT Times
A14: Ship | B14: Ship - Passenger | C14: Bahia ferry-boat (1,254 pax + 168 vehicles), used | D14: ='NonRoad Avg'!$C$10 -> 1 | E14: =Forecast!$E$18 -> 75018509 | F14: =Forecast!$E$46 -> 14525053 | G14: {=INDEX(Forecast!$E$18:$AG$18,MATCH(G$5,Forecast!$E$5:$AG$5,0))} -> 75018509 | H14: {=INDEX(Forecast!$E$18:$AG$18,MATCH(H$5,Forecast!$E$5:$AG$5,0))} -> 75018509 | I14: {=INDEX(Forecast!$E$18:$AG$18,MATCH(I$5,Forecast!$E$5:$AG$5,0))} -> 75018509 | J14: {=INDEX(Forecast!$E$18:$AG$18,MATCH(J$5,Forecast!$E$5:$AG$5,0))} -> 75018509 | K14: {=INDEX(Forecast!$E$18:$AG$18,MATCH(K$5,Forecast!$E$5:$AG$5,0))} -> 75018509 | L14: {=INDEX(Forecast!$E$32:$AG$32,MATCH(Assumptions!$B$5,Forecast!$E$5:$AG$5,0))} -> 1.8173179e+08 | M14: =(K14/E14)^(1/(Assumptions!$B$5-Assumptions!$B$4))-1 -> 0 | N14: Low | O14: Bahia Noticias
A15: Ship | B15: Ship - Freight | C15: Transpetro Handy and MR1 tankers (Brazilian yards) | D15: ='NonRoad Avg'!$C$11 -> 2 | E15: =Forecast!$E$19 -> 4.0037794e+08 | F15: =Forecast!$E$47 -> 77521012 | G15: {=INDEX(Forecast!$E$19:$AG$19,MATCH(G$5,Forecast!$E$5:$AG$5,0))} -> 4.0037794e+08 | H15: {=INDEX(Forecast!$E$19:$AG$19,MATCH(H$5,Forecast!$E$5:$AG$5,0))} -> 4.0037794e+08 | I15: {=INDEX(Forecast!$E$19:$AG$19,MATCH(I$5,Forecast!$E$5:$AG$5,0))} -> 4.0037794e+08 | J15: {=INDEX(Forecast!$E$19:$AG$19,MATCH(J$5,Forecast!$E$5:$AG$5,0))} -> 4.0037794e+08 | K15: {=INDEX(Forecast!$E$19:$AG$19,MATCH(K$5,Forecast!$E$5:$AG$5,0))} -> 4.0037794e+08 | L15: {=INDEX(Forecast!$E$33:$AG$33,MATCH(Assumptions!$B$5,Forecast!$E$5:$AG$5,0))} -> 9.6991265e+08 | M15: =(K15/E15)^(1/(Assumptions!$B$5-Assumptions!$B$4))-1 -> 0 | N15: Medium | O15: Eixos; Times Brasil
A16: Rail | B16: Rail - Passenger | C16: Metro SP six-car trainset | D16: ='NonRoad Avg'!$C$12 -> 1 | E16: =Forecast!$E$20 -> 64329558 | F16: =Forecast!$E$48 -> 12455463 | G16: {=INDEX(Forecast!$E$20:$AG$20,MATCH(G$5,Forecast!$E$5:$AG$5,0))} -> 64329558 | H16: {=INDEX(Forecast!$E$20:$AG$20,MATCH(H$5,Forecast!$E$5:$AG$5,0))} -> 64329558 | I16: {=INDEX(Forecast!$E$20:$AG$20,MATCH(I$5,Forecast!$E$5:$AG$5,0))} -> 64329558 | J16: {=INDEX(Forecast!$E$20:$AG$20,MATCH(J$5,Forecast!$E$5:$AG$5,0))} -> 64329558 | K16: {=INDEX(Forecast!$E$20:$AG$20,MATCH(K$5,Forecast!$E$5:$AG$5,0))} -> 64329558 | L16: {=INDEX(Forecast!$E$34:$AG$34,MATCH(Assumptions!$B$5,Forecast!$E$5:$AG$5,0))} -> 1.5583789e+08 | M16: =(K16/E16)^(1/(Assumptions!$B$5-Assumptions!$B$4))-1 -> 0 | N16: Low | O16: Diario do Transporte
A17: Rail | B17: Rail - Freight | C17: Locomotives (MRS, VLI purchases) | D17: ='NonRoad Avg'!$C$13 -> 4 | E17: =Forecast!$E$21 -> 19501752 | F17: =Forecast!$E$49 -> 3775921.1 | G17: {=INDEX(Forecast!$E$21:$AG$21,MATCH(G$5,Forecast!$E$5:$AG$5,0))} -> 19501752 | H17: {=INDEX(Forecast!$E$21:$AG$21,MATCH(H$5,Forecast!$E$5:$AG$5,0))} -> 19501752 | I17: {=INDEX(Forecast!$E$21:$AG$21,MATCH(I$5,Forecast!$E$5:$AG$5,0))} -> 19501752 | J17: {=INDEX(Forecast!$E$21:$AG$21,MATCH(J$5,Forecast!$E$5:$AG$5,0))} -> 19501752 | K17: {=INDEX(Forecast!$E$21:$AG$21,MATCH(K$5,Forecast!$E$5:$AG$5,0))} -> 19501752 | L17: {=INDEX(Forecast!$E$35:$AG$35,MATCH(Assumptions!$B$5,Forecast!$E$5:$AG$5,0))} -> 47242852 | M17: =(K17/E17)^(1/(Assumptions!$B$5-Assumptions!$B$4))-1 -> 0 | N17: Medium | O17: Mundo Logistica; Diario do Comercio
A19: Read before using the numbers
A20: 1. The FIPE file is 0-km cars and light commercial vehicles (model-year 2023, Jan-Dec 2022). It has no full-size buses or heavy trucks, so 'HDV' here means FIPE-listed vehicles above 3,856 kg GVW (large vans, Iveco Daily 45-70, Sprinter 416/516, Ram 2500/3500).
A21: 2. The Passenger LDV mean is pulled up by supercars and ultra-luxury cars (Rolls-Royce, Ferrari, McLaren). The median (Road_Avg column E) is much lower; switch with Assumptions!B9.
A22: 3. Aircraft, ship and rail prices come from a small number of public contracts and valuations (one row per source in Bench_NonRoad). Single-benchmark categories are marked Low confidence. Change Include (1/0) or add rows there and everything updates.
A23: 4. Motorbike prices are manufacturer-suggested prices (DF base), which sit below FIPE market prices. Passenger motorbike covers 52% of 2022 registrations (Honda CG 160, Biz, Pop).
A24: 5. Real growth rates are analyst assumptions (Base = flat real price; Low/High = -1/+1 pp). No sourced long-run price trend exists in the data. Nominal series add IPCA (actual to 2026, then the 3% target).
A25: 6. Freight rail = locomotive price (no wagons). Passenger rail = one six-car trainset. Ships and aircraft are per vessel / per aircraft.
A26: 7. Prices by fuel (BEV, NGV, gasoline, diesel, PHEV, LPG, hydrogen) are on Fuel_Price and Fuel_Forecast. Only road gasoline/diesel/PHEV come from your FIPE file; BEV, NGV and hydrogen rest on the few Brazilian sources on Fuel_Evidence; cells marked 'Analyst' are indicative placeholders.

Sheet Assumptions
A1: Assumptions and scenario controls
A2: Blue = input. Yellow fill = cells you are meant to change. Black = formula. Green = link to another sheet.
A3: General | B3: Value | F3: Note / source
A4: Base year (FIPE data year; do not change) | B4: 2022 | F4: The FIPE workbook covers Jan-Dec 2022. Base prices are nominal 2022 R$ = constant 2022 R$.
A5: Final forecast year | B5: =Forecast!AG5 -> 2050 | F5: Horizon is fixed at 29 columns (2022-2050) on the Forecast sheet.
A6: Scenario for real price growth (1 = Low, 2 = Base, 3 = High) | B6: 2 | F6: Drop-down. Picks the Low / Base / High column of the growth table below.
A7: Scenario name | B7: =CHOOSE(B6,"Low","Base","High") -> Base
A8: Long-run inflation after the last actual IPCA year (%/yr) | B8: 0.03 | F8: Brazil's continuous inflation target of 3.0% (CMN, from 2025). Actual IPCA is used up to the last year in Macro.
A9: Statistic for road base prices (1 = Mean, 2 = Median) | B9: 1 | F9: Mean = "average price". The median is far lower for Passenger LDV because supercars (up to R$ 8.6 m) skew the mean.
A10: Statistic name | B10: =CHOOSE(B9,"Mean","Median") -> Mean
A11: PROCONVE light / heavy threshold (kg GVW) | B11: 3856 | F11: Informational: defines LDV (<= 3,856 kg) vs HDV in Class_Rules.
A12: Average PTAX in base year (R$ per US$) | B12: {=INDEX(Macro!$L$6:$L$17,MATCH(B4,Macro!$K$6:$K$17,0))} -> 5.1647667 | F12: Used for the constant-price US$ view. No future FX forecast is made.
A13: Last year with actual IPCA in Macro | B13: =Macro!K17 -> 2026 | F13: 2026 is partial (12-month rate to Aug-2026).
F14: Source for the 3% target: CNN Brasil, continuous inflation target from 2025
A16: Real price growth by vehicle type (% per year, constant 2022 R$, applied 2023-2050)
A17: Vehicle type | B17: Low | C17: Base | D17: High | E17: Selected | F17: Rationale
A18: Road - Passenger LDV | B18: -0.01 | C18: 0 | D18: 0.01 | E18: =INDEX(B18:D18,1,$B$6) -> 0 | F18: Analyst assumption. The dataset covers one year (2022), so it cannot support a sourced long-run trend. Base = constant real price; +/-1 pp brackets emissions/safety content (PROCONVE L8/P8) against scale and local-content cost-downs.
A19: Road - Passenger HDV | B19: -0.01 | C19: 0 | D19: 0.01 | E19: =INDEX(B19:D19,1,$B$6) -> 0 | F19: Analyst assumption. The dataset covers one year (2022), so it cannot support a sourced long-run trend. Base = constant real price; +/-1 pp brackets emissions/safety content (PROCONVE L8/P8) against scale and local-content cost-downs.
A20: Road - Freight LDV | B20: -0.01 | C20: 0 | D20: 0.01 | E20: =INDEX(B20:D20,1,$B$6) -> 0 | F20: Analyst assumption. The dataset covers one year (2022), so it cannot support a sourced long-run trend. Base = constant real price; +/-1 pp brackets emissions/safety content (PROCONVE L8/P8) against scale and local-content cost-downs.
A21: Road - Freight HDV | B21: -0.01 | C21: 0 | D21: 0.01 | E21: =INDEX(B21:D21,1,$B$6) -> 0 | F21: Analyst assumption. The dataset covers one year (2022), so it cannot support a sourced long-run trend. Base = constant real price; +/-1 pp brackets emissions/safety content (PROCONVE L8/P8) against scale and local-content cost-downs.
A22: Motorbike - Passenger | B22: -0.015 | C22: 0 | D22: 0.01 | E22: =INDEX(B22:D22,1,$B$6) -> 0 | F22: Analyst assumption anchored on the FIPE-vs-IPCA cross-check in Macro!K25:Q28: real change of about -1.6%/yr (CG 160 Start, 2021-26) and +0.3%/yr (Pop 110i, 2022-26). Base 0%.
A23: Motorbike - Freight | B23: -0.015 | C23: 0 | D23: 0.01 | E23: =INDEX(B23:D23,1,$B$6) -> 0 | F23: Analyst assumption anchored on the FIPE-vs-IPCA cross-check in Macro!K25:Q28: real change of about -1.6%/yr (CG 160 Start, 2021-26) and +0.3%/yr (Pop 110i, 2022-26). Base 0%.
A24: Aircraft - Passenger | B24: -0.01 | C24: 0 | D24: 0.01 | E24: =INDEX(B24:D24,1,$B$6) -> 0 | F24: Analyst assumption (no sourced long-run trend). Prices are market values / negotiated prices, not list prices.
A25: Aircraft - Freight | B25: -0.01 | C25: 0 | D25: 0.01 | E25: =INDEX(B25:D25,1,$B$6) -> 0 | F25: Analyst assumption (no sourced long-run trend). Prices are market values / negotiated prices, not list prices.
A26: Ship - Passenger | B26: -0.01 | C26: 0 | D26: 0.01 | E26: =INDEX(B26:D26,1,$B$6) -> 0 | F26: Analyst assumption (no sourced long-run trend). Newbuild prices depend on yard, local-content rules and ship type.
A27: Ship - Freight | B27: -0.01 | C27: 0 | D27: 0.01 | E27: =INDEX(B27:D27,1,$B$6) -> 0 | F27: Analyst assumption (no sourced long-run trend). Newbuild prices depend on yard, local-content rules and ship type.
A28: Rail - Passenger | B28: -0.01 | C28: 0 | D28: 0.01 | E28: =INDEX(B28:D28,1,$B$6) -> 0 | F28: Analyst assumption (no sourced long-run trend). Rolling-stock contract prices include systems and services.
A29: Rail - Freight | B29: -0.01 | C29: 0 | D29: 0.01 | E29: =INDEX(B29:D29,1,$B$6) -> 0 | F29: Analyst assumption (no sourced long-run trend). Rolling-stock contract prices include systems and services.
A32: Premium convergence by fuel (annual %, applied to the price premium over the reference vehicle)
A33: Fuel | B33: Convergence (%/yr) | F33: Rationale
A34: BEV | B34: 0.03 | F34: Analyst assumption: battery-cost decline and scale close part of the premium. 3%/yr halves a premium by about 2040.
A35: NGV | B35: 0.01 | F35: Analyst assumption: mature conversion kits; little cost decline.
A36: Gasoline | B36: 0 | F36: Reference technology: no premium.
A37: Diesel | B37: 0 | F37: Reference technology: no premium.
A38: PHEV | B38: 0.02 | F38: Analyst assumption.
A39: LPG | B39: 0.01 | F39: Analyst assumption.
A40: Hydrogen | B40: 0.03 | F40: Analyst assumption: fuel-cell and tank cost decline with scale; starts from a large premium.
A42: Premium(t) = 1 + (Premium(2022) - 1) x (1 - convergence)^(t - 2022) when the 2022 price is above the reference vehicle; otherwise the 2022 ratio is held constant.

Sheet Fuel Price
A1: Average new-vehicle price by fuel / powertrain, 2022 (constant 2022 R$)
A2: Rows = the 12 vehicle types. Columns = BEV, NGV, gasoline, diesel, PHEV, LPG, hydrogen. Method codes: D = FIPE data, B = baseline (Summary base price), S = sourced absolute price, X = multiplier x reference price, P = reference price + additive cost, N = not available.
A3: Method code, evidence class and inputs are editable (yellow / blue). Changing a code or input updates the price, ratio and forecast automatically.
A6: 1. Method code per cell (editable)
A7: ID | B7: Vehicle type | C7: Battery electric vehicle (BEV) | D7: Natural gas vehicle (NGV) | E7: Gasoline vehicle | F7: Diesel vehicle | G7: Plug-in hybrid vehicle (PHEV) | H7: LPG vehicle | I7: Hydrogen (fuel-cell) vehicle
A8: 1 | B8: Road - Passenger LDV | C8: S | D8: P | E8: D | F8: D | G8: D | H8: N | I8: X
A9: 2 | B9: Road - Passenger HDV | C9: X | D9: X | E9: D | F9: D | G9: D | H9: N | I9: X
A10: 3 | B10: Road - Freight LDV | C10: X | D10: P | E10: D | F10: D | G10: D | H10: N | I10: X
A11: 4 | B11: Road - Freight HDV | C11: X | D11: X | E11: D | F11: D | G11: D | H11: N | I11: X
A12: 5 | B12: Motorbike - Passenger | C12: S | D12: N | E12: B | F12: N | G12: N | H12: N | I12: N
A13: 6 | B13: Motorbike - Freight | C13: X | D13: N | E13: B | F13: N | G13: N | H13: N | I13: N
A14: 7 | B14: Aircraft - Passenger | C14: N | D14: N | E14: B | F14: N | G14: N | H14: N | I14: N
A15: 8 | B15: Aircraft - Freight | C15: N | D15: N | E15: B | F15: N | G15: N | H15: N | I15: N
A16: 9 | B16: Ship - Passenger | C16: X | D16: X | E16: N | F16: B | G16: X | H16: X | I16: X
A17: 10 | B17: Ship - Freight | C17: N | D17: X | E17: N | F17: B | G17: X | H17: X | I17: N
A18: 11 | B18: Rail - Passenger | C18: B | D18: N | E18: N | F18: X | G18: N | H18: N | I18: X
A19: 12 | B19: Rail - Freight | C19: X | D19: X | E19: N | F19: B | G19: X | H19: N | I19: X
A21: 2. Evidence class per cell (Data / Baseline / Sourced / Proxy / Analyst / n/a)
A22: ID | B22: Vehicle type | C22: Battery electric vehicle (BEV) | D22: Natural gas vehicle (NGV) | E22: Gasoline vehicle | F22: Diesel vehicle | G22: Plug-in hybrid vehicle (PHEV) | H22: LPG vehicle | I22: Hydrogen (fuel-cell) vehicle
A23: 1 | B23: Road - Passenger LDV | C23: Sourced | D23: Sourced | E23: Data | F23: Data | G23: Data | H23: n/a | I23: Sourced
A24: 2 | B24: Road - Passenger HDV | C24: Sourced | D24: Analyst | E24: Data | F24: Data | G24: Data | H24: n/a | I24: Analyst
A25: 3 | B25: Road - Freight LDV | C25: Proxy | D25: Sourced | E25: Data | F25: Data | G25: Data | H25: n/a | I25: Proxy
A26: 4 | B26: Road - Freight HDV | C26: Proxy | D26: Analyst | E26: Data | F26: Data | G26: Data | H26: n/a | I26: Analyst
A27: 5 | B27: Motorbike - Passenger | C27: Sourced | D27: n/a | E27: Baseline | F27: n/a | G27: n/a | H27: n/a | I27: n/a
A28: 6 | B28: Motorbike - Freight | C28: Proxy | D28: n/a | E28: Baseline | F28: n/a | G28: n/a | H28: n/a | I28: n/a
A29: 7 | B29: Aircraft - Passenger | C29: n/a | D29: n/a | E29: Baseline | F29: n/a | G29: n/a | H29: n/a | I29: n/a
A30: 8 | B30: Aircraft - Freight | C30: n/a | D30: n/a | E30: Baseline | F30: n/a | G30: n/a | H30: n/a | I30: n/a
A31: 9 | B31: Ship - Passenger | C31: Analyst | D31: Analyst | E31: n/a | F31: Baseline | G31: Analyst | H31: Analyst | I31: Analyst
A32: 10 | B32: Ship - Freight | C32: n/a | D32: Analyst | E32: n/a | F32: Baseline | G32: Analyst | H32: Analyst | I32: n/a
A33: 11 | B33: Rail - Passenger | C33: Baseline | D33: n/a | E33: n/a | F33: Analyst | G33: n/a | H33: n/a | I33: Analyst
A34: 12 | B34: Rail - Freight | C34: Analyst | D34: Analyst | E34: n/a | F34: Baseline | G34: Analyst | H34: n/a | I34: Analyst
A36: 3. Inputs used by codes S, X, P: absolute price (R$), multiplier, or additive cost (R$)
A37: ID | B37: Vehicle type | C37: Battery electric vehicle (BEV) | D37: Natural gas vehicle (NGV) | E37: Gasoline vehicle | F37: Diesel vehicle | G37: Plug-in hybrid vehicle (PHEV) | H37: LPG vehicle | I37: Hydrogen (fuel-cell) vehicle
A38: 1 | B38: Road - Passenger LDV | C38: ='Fuel Evidence'!$J$16 -> 147487.33 | D38: ='Fuel Evidence'!$J$17 -> 5000 | I38: ='Fuel Evidence'!$J$23 -> 2.0582121
A39: 2 | B39: Road - Passenger HDV | C39: ='Fuel Evidence'!$J$18 -> 3 | D39: 1.2 | I39: 4.5
A40: 3 | B40: Road - Freight LDV | C40: ='Fuel Evidence'!$J$30 -> 1.4113703 | D40: ='Fuel Evidence'!$J$17 -> 5000 | I40: ='Fuel Evidence'!$J$23 -> 2.0582121
A41: 4 | B41: Road - Freight HDV | C41: ='Fuel Evidence'!$J$18 -> 3 | D41: 1.2 | I41: 4.5
A42: 5 | B42: Motorbike - Passenger | C42: ='Fuel Evidence'!$J$20 -> 16014
A43: 6 | B43: Motorbike - Freight | C43: =C87/E87 -> 1.3955015
A44: 7 | B44: Aircraft - Passenger
...

Sheet Fuel Forecast
A1: Forecast of average price by vehicle type and fuel, 2022-2050
A2: Real price(t) = Price 2022 x (1 + real growth of the type)^(t-2022) x premium factor(t). Premium factor(t) = (1 + (Ratio-1) x (1-convergence)^(t-2022)) / Ratio when Ratio > 1, else 1. Nominal = Real x inflation index (Forecast row 7).
A3: Scenario: | B3: =Assumptions!B7 -> Base
A6: A. Real price by fuel (constant 2022 R$)
A7: ID | B7: Vehicle type | C7: Fuel | D7: Price 2022 (R$) | E7: Reference price (R$) | F7: Ratio to reference | G7: Real growth (%/yr) | H7: Convergence (%/yr) | I7: =Assumptions!$B$4 -> 2022 | J7: =I7+1 -> 2023 | K7: =J7+1 -> 2024 | L7: =K7+1 -> 2025 | M7: =L7+1 -> 2026 | N7: =M7+1 -> 2027 | O7: =N7+1 -> 2028 | P7: =O7+1 -> 2029 | Q7: =P7+1 -> 2030 | ... AK7: =AJ7+1 -> 2050
A8: 1 | B8: Road - Passenger LDV | C8: BEV | D8: ='Fuel Price'!C83 -> 147487.33 | E8: ='Fuel Price'!$J$83 -> 422580.76 | F8: =IF(ISNUMBER(D8),D8/E8,"n/a") -> 0.34901574 | G8: =Assumptions!$E$18 -> 0 | H8: {=INDEX(Assumptions!$B$34:$B$40,MATCH($C8,Assumptions!$A$34:$A$40,0))} -> 0.03 | I8: =IF(ISNUMBER($D8),$D8*(1+$G8)^(I$7-$I$7)*IF($F8>1,(1+($F8-1)*(1-$H8)^(I$7-$I$7))/$F8,1),"n/a") -> 147487.33 | J8: =IF(ISNUMBER($D8),$D8*(1+$G8)^(J$7-$I$7)*IF($F8>1,(1+($F8-1)*(1-$H8)^(J$7-$I$7))/$F8,1),"n/a") -> 147487.33 | K8: =IF(ISNUMBER($D8),$D8*(1+$G8)^(K$7-$I$7)*IF($F8>1,(1+($F8-1)*(1-$H8)^(K$7-$I$7))/$F8,1),"n/a") -> 147487.33 | L8: =IF(ISNUMBER($D8),$D8*(1+$G8)^(L$7-$I$7)*IF($F8>1,(1+($F8-1)*(1-$H8)^(L$7-$I$7))/$F8,1),"n/a") -> 147487.33 | M8: =IF(ISNUMBER($D8),$D8*(1+$G8)^(M$7-$I$7)*IF($F8>1,(1+($F8-1)*(1-$H8)^(M$7-$I$7))/$F8,1),"n/a") -> 147487.33 | N8: =IF(ISNUMBER($D8),$D8*(1+$G8)^(N$7-$I$7)*IF($F8>1,(1+($F8-1)*(1-$H8)^(N$7-$I$7))/$F8,1),"n/a") -> 147487.33 | O8: =IF(ISNUMBER($D8),$D8*(1+$G8)^(O$7-$I$7)*IF($F8>1,(1+($F8-1)*(1-$H8)^(O$7-$I$7))/$F8,1),"n/a") -> 147487.33 | P8: =IF(ISNUMBER($D8),$D8*(1+$G8)^(P$7-$I$7)*IF($F8>1,(1+($F8-1)*(1-$H8)^(P$7-$I$7))/$F8,1),"n/a") -> 147487.33 | ... AK8: =IF(ISNUMBER($D8),$D8*(1+$G8)^(AK$7-$I$7)*IF($F8>1,(1+($F8-1)*(1-$H8)^(AK$7-$I$7))/$F8,1),"n/a") -> 147487.33
A9: 1 | B9: Road - Passenger LDV | C9: NGV | D9: ='Fuel Price'!D83 -> 427580.76 | E9: ='Fuel Price'!$J$83 -> 422580.76 | F9: =IF(ISNUMBER(D9),D9/E9,"n/a") -> 1.0118321 | G9: =Assumptions!$E$18 -> 0 | H9: {=INDEX(Assumptions!$B$34:$B$40,MATCH($C9,Assumptions!$A$34:$A$40,0))} -> 0.01 | I9: =IF(ISNUMBER($D9),$D9*(1+$G9)^(I$7-$I$7)*IF($F9>1,(1+($F9-1)*(1-$H9)^(I$7-$I$7))/$F9,1),"n/a") -> 427580.76 | J9: =IF(ISNUMBER($D9),$D9*(1+$G9)^(J$7-$I$7)*IF($F9>1,(1+($F9-1)*(1-$H9)^(J$7-$I$7))/$F9,1),"n/a") -> 427530.76 | K9: =IF(ISNUMBER($D9),$D9*(1+$G9)^(K$7-$I$7)*IF($F9>1,(1+($F9-1)*(1-$H9)^(K$7-$I$7))/$F9,1),"n/a") -> 427481.26 | L9: =IF(ISNUMBER($D9),$D9*(1+$G9)^(L$7-$I$7)*IF($F9>1,(1+($F9-1)*(1-$H9)^(L$7-$I$7))/$F9,1),"n/a") -> 427432.25 | M9: =IF(ISNUMBER($D9),$D9*(1+$G9)^(M$7-$I$7)*IF($F9>1,(1+($F9-1)*(1-$H9)^(M$7-$I$7))/$F9,1),"n/a") -> 427383.74 | N9: =IF(ISNUMBER($D9),$D9*(1+$G9)^(N$7-$I$7)*IF($F9>1,(1+($F9-1)*(1-$H9)^(N$7-$I$7))/$F9,1),"n/a") -> 427335.71 | O9: =IF(ISNUMBER($D9),$D9*(1+$G9)^(O$7-$I$7)*IF($F9>1,(1+($F9-1)*(1-$H9)^(O$7-$I$7))/$F9,1),"n/a") -> 427288.16 | P9: =IF(ISNUMBER($D9),$D9*(1+$G9)^(P$7-$I$7)*IF($F9>1,(1+($F9-1)*(1-$H9)^(P$7-$I$7))/$F9,1),"n/a") -> 427241.08 | ... AK9: =IF(ISNUMBER($D9),$D9*(1+$G9)^(AK$7-$I$7)*IF($F9>1,(1+($F9-1)*(1-$H9)^(AK$7-$I$7))/$F9,1),"n/a") -> 426354.35
A10: 1 | B10: Road - Passenger LDV | C10: Gasoline | D10: ='Fuel Price'!E83 -> 422580.76 | E10: ='Fuel Price'!$J$83 -> 422580.76 | F10: =IF(ISNUMBER(D10),D10/E10,"n/a") -> 1 | G10: =Assumptions!$E$18 -> 0 | H10: {=INDEX(Assumptions!$B$34:$B$40,MATCH($C10,Assumptions!$A$34:$A$40,0))} -> 0 | I10: =IF(ISNUMBER($D10),$D10*(1+$G10)^(I$7-$I$7)*IF($F10>1,(1+($F10-1)*(1-$H10)^(I$7-$I$7))/$F10,1),"n/a") -> 422580.76 | J10: =IF(ISNUMBER($D10),$D10*(1+$G10)^(J$7-$I$7)*IF($F10>1,(1+($F10-1)*(1-$H10)^(J$7-$I$7))/$F10,1),"n/a") -> 422580.76 | K10: =IF(ISNUMBER($D10),$D10*(1+$G10)^(K$7-$I$7)*IF($F10>1,(1+($F10-1)*(1-$H10)^(K$7-$I$7))/$F10,1),"n/a") -> 422580.76 | L10: =IF(ISNUMBER($D10),$D10*(1+$G10)^(L$7-$I$7)*IF($F10>1,(1+($F10-1)*(1-$H10)^(L$7-$I$7))/$F10,1),"n/a") -> 422580.76 | M10: =IF(ISNUMBER($D10),$D10*(1+$G10)^(M$7-$I$7)*IF($F10>1,(1+($F10-1)*(1-$H10)^(M$7-$I$7))/$F10,1),"n/a") -> 422580.76 | N10: =IF(ISNUMBER($D10),$D10*(1+$G10)^(N$7-$I$7)*IF($F10>1,(1+($F10-1)*(1-$H10)^(N$7-$I$7))/$F10,1),"n/a") -> 422580.76 | O10: =IF(ISNUMBER($D10),$D10*(1+$G10)^(O$7-$I$7)*IF($F10>1,(1+($F10-1)*(1-$H10)^(O$7-$I$7))/$F10,1),"n/a") -> 422580.76 | P10: =IF(ISNUMBER($D10),$D10*(1+$G10)^(P$7-$I$7)*IF($F10>1,(1+($F10-1)*(1-$H10)^(P$7-$I$7))/$F10,1),"n/a") -> 422580.76 | ... AK10: =IF(ISNUMBER($D10),$D10*(1+$G10)^(AK$7-$I$7)*IF($F10>1,(1+($F10-1)*(1-$H10)^(AK$7-$I$7))/$F10,1),"n/a") -> 422580.76
A11: 1 | B11: Road - Passenger LDV | C11: Diesel | D11: ='Fuel Price'!F83 -> 384177.66 | E11: ='Fuel Price'!$J$83 -> 422580.76 | F11: =IF(ISNUMBER(D11),D11/E11,"n/a") -> 0.90912246 | G11: =Assumptions!$E$18 -> 0 | H11: {=INDEX(Assumptions!$B$34:$B$40,MATCH($C11,Assumptions!$A$34:$A$40,0))} -> 0 | I11: =IF(ISNUMBER($D11),$D11*(1+$G11)^(I$7-$I$7)*IF($F11>1,(1+($F11-1)*(1-$H11)^(I$7-$I$7))/$F11,1),"n/a") -> 384177.66 | J11: =IF(ISNUMBER($D11),$D11*(1+$G11)^(J$7-$I$7)*IF($F11>1,(1+($F11-1)*(1-$H11)^(J$7-$I$7))/$F11,1),"n/a") -> 384177.66 | K11: =IF(ISNUMBER($D11),$D11*(1+$G11)^(K$7-$I$7)*IF($F11>1,(1+($F11-1)*(1-$H11)^(K$7-$I$7))/$F11,1),"n/a") -> 384177.66 | L11: =IF(ISNUMBER($D11),$D11*(1+$G11)^(L$7-$I$7)*IF($F11>1,(1+($F11-1)*(1-$H11)^(L$7-$I$7))/$F11,1),"n/a") -> 384177.66 | M11: =IF(ISNUMBER($D11),$D11*(1+$G11)^(M$7-$I$7)*IF($F11>1,(1+($F11-1)*(1-$H11)^(M$7-$I$7))/$F11,1),"n/a") -> 384177.66 | N11: =IF(ISNUMBER($D11),$D11*(1+$G11)^(N$7-$I$7)*IF($F11>1,(1+($F11-1)*(1-$H11)^(N$7-$I$7))/$F11,1),"n/a") -> 384177.66 | O11: =IF(ISNUMBER($D11),$D11*(1+$G11)^(O$7-$I$7)*IF($F11>1,(1+($F11-1)*(1-$H11)^(O$7-$I$7))/$F11,1),"n/a") -> 384177.66 | P11: =IF(ISNUMBER($D11),$D11*(1+$G11)^(P$7-$I$7)*IF($F11>1,(1+($F11-1)*(1-$H11)^(P$7-$I$7))/$F11,1),"n/a") -> 384177.66 | ... AK11: =IF(ISNUMBER($D11),$D11*(1+$G11)^(AK$7-$I$7)*IF($F11>1,(1+($F11-1)*(1-$H11)^(AK$7-$I$7))/$F11,1),"n/a") -> 384177.66
A12: 1 | B12: Road - Passenger LDV | C12: PHEV | D12: ='Fuel Price'!G83 -> 602925.26 | E12: ='Fuel Price'!$J$83 -> 422580.76 | F12: =IF(ISNUMBER(D12),D12/E12,"n/a") -> 1.4267693 | G12: =Assumptions!$E$18 -> 0 | H12: {=INDEX(Assumptions!$B$34:$B$40,MATCH($C12,Assumptions!$A$34:$A$40,0))} -> 0.02 | I12: =IF(ISNUMBER($D12),$D12*(1+$G12)^(I$7-$I$7)*IF($F12>1,(1+($F12-1)*(1-$H12)^(I$7-$I$7))/$F12,1),"n/a") -> 602925.26 | J12: =IF(ISNUMBER($D12),$D12*(1+$G12)^(J$7-$I$7)*IF($F12>1,(1+($F12-1)*(1-$H12)^(J$7-$I$7))/$F12,1),"n/a") -> 599318.37 | K12: =IF(ISNUMBER($D12),$D12*(1+$G12)^(K$7-$I$7)*IF($F12>1,(1+($F12-1)*(1-$H12)^(K$7-$I$7))/$F12,1),"n/a") -> 595783.61 | L12: =IF(ISNUMBER($D12),$D12*(1+$G12)^(L$7-$I$7)*IF($F12>1,(1+($F12-1)*(1-$H12)^(L$7-$I$7))/$F12,1),"n/a") -> 592319.56 | M12: =IF(ISNUMBER($D12),$D12*(1+$G12)^(M$7-$I$7)*IF($F12>1,(1+($F12-1)*(1-$H12)^(M$7-$I$7))/$F12,1),"n/a") -> 588924.78 | N12: =IF(ISNUMBER($D12),$D12*(1+$G12)^(N$7-$I$7)*IF($F12>1,(1+($F12-1)*(1-$H12)^(N$7-$I$7))/$F12,1),"n/a") -> 585597.9 | O12: =IF(ISNUMBER($D12),$D12*(1+$G12)^(O$7-$I$7)*IF($F12>1,(1+($F12-1)*(1-$H12)^(O$7-$I$7))/$F12,1),"n/a") -> 582337.56 | P12: =IF(ISNUMBER($D12),$D12*(1+$G12)^(P$7-$I$7)*IF($F12>1,(1+($F12-1)*(1-$H12)^(P$7-$I$7))/$F12,1),"n/a") -> 579142.42 | ... AK12: =IF(ISNUMBER($D12),$D12*(1+$G12)^(AK$7-$I$7)*IF($F12>1,(1+($F12-1)*(1-$H12)^(AK$7-$I$7))/$F12,1),"n/a") -> 525012.14
A13: 1 | B13: Road - Passenger LDV | C13: LPG | D13: ='Fuel Price'!H83 -> n/a | E13: ='Fuel Price'!$J$83 -> 422580.76 | F13: =IF(ISNUMBER(D13),D13/E13,"n/a") -> n/a | G13: =Assumptions!$E$18 -> 0 | H13: {=INDEX(Assumptions!$B$34:$B$40,MATCH($C13,Assumptions!$A$34:$A$40,0))} -> 0.01 | I13: =IF(ISNUMBER($D13),$D13*(1+$G13)^(I$7-$I$7)*IF($F13>1,(1+($F13-1)*(1-$H13)^(I$7-$I$7))/$F13,1),"n/a") -> n/a | J13: =IF(ISNUMBER($D13),$D13*(1+$G13)^(J$7-$I$7)*IF($F13>1,(1+($F13-1)*(1-$H13)^(J$7-$I$7))/$F13,1),"n/a") -> n/a | K13: =IF(ISNUMBER($D13),$D13*(1+$G13)^(K$7-$I$7)*IF($F13>1,(1+($F13-1)*(1-$H13)^(K$7-$I$7))/$F13,1),"n/a") -> n/a | L13: =IF(ISNUMBER($D13),$D13*(1+$G13)^(L$7-$I$7)*IF($F13>1,(1+($F13-1)*(1-$H13)^(L$7-$I$7))/$F13,1),"n/a") -> n/a | M13: =IF(ISNUMBER($D13),$D13*(1+$G13)^(M$7-$I$7)*IF($F13>1,(1+($F13-1)*(1-$H13)^(M$7-$I$7))/$F13,1),"n/a") -> n/a | N13: =IF(ISNUMBER($D13),$D13*(1+$G13)^(N$7-$I$7)*IF($F13>1,(1+($F13-1)*(1-$H13)^(N$7-$I$7))/$F13,1),"n/a") -> n/a | O13: =IF(ISNUMBER($D13),$D13*(1+$G13)^(O$7-$I$7)*IF($F13>1,(1+($F13-1)*(1-$H13)^(O$7-$I$7))/$F13,1),"n/a") -> n/a | P13: =IF(ISNUMBER($D13),$D13*(1+$G13)^(P$7-$I$7)*IF($F13>1,(1+($F13-1)*(1-$H13)^(P$7-$I$7))/$F13,1),"n/a") -> n/a | ... AK13: =IF(ISNUMBER($D13),$D13*(1+$G13)^(AK$7-$I$7)*IF($F13>1,(1+($F13-1)*(1-$H13)^(AK$7-$I$7))/$F13,1),"n/a") -> n/a
A14: 1 | B14: Road - Passenger LDV | C14: Hydrogen | D14: ='Fuel Price'!I83 -> 869760.81 | E14: ='Fuel Price'!$J$83 -> 422580.76 | F14: =IF(ISNUMBER(D14),D14/E14,"n/a") -> 2.0582121 | G14: =Assumptions!$E$18 -> 0 | H14: {=INDEX(Assumptions!$B$34:$B$40,MATCH($C14,Assumptions!$A$34:$A$40,0))} -> 0.03 | I14: =IF(ISNUMBER($D14),$D14*(1+$G14)^(I$7-$I$7)*IF($F14>1,(1+($F14-1)*(1-$H14)^(I$7-$I$7))/$F14,1),"n/a") -> 869760.81 | J14: =IF(ISNUMBER($D14),$D14*(1+$G14)^(J$7-$I$7)*IF($F14>1,(1+($F14-1)*(1-$H14)^(J$7-$I$7))/$F14,1),"n/a") -> 856345.41 | K14: =IF(ISNUMBER($D14),$D14*(1+$G14)^(K$7-$I$7)*IF($F14>1,(1+($F14-1)*(1-$H14)^(K$7-$I$7))/$F14,1),"n/a") -> 843332.47 | L14: =IF(ISNUMBER($D14),$D14*(1+$G14)^(L$7-$I$7)*IF($F14>1,(1+($F14-1)*(1-$H14)^(L$7-$I$7))/$F14,1),"n/a") -> 830709.92 | M14: =IF(ISNUMBER($D14),$D14*(1+$G14)^(M$7-$I$7)*IF($F14>1,(1+($F14-1)*(1-$H14)^(M$7-$I$7))/$F14,1),"n/a") -> 818466.04 | N14: =IF(ISNUMBER($D14),$D14*(1+$G14)^(N$7-$I$7)*IF($F14>1,(1+($F14-1)*(1-$H14)^(N$7-$I$7))/$F14,1),"n/a") -> 806589.49 | O14: =IF(ISNUMBER($D14),$D14*(1+$G14)^(O$7-$I$7)*IF($F14>1,(1+($F14-1)*(1-$H14)^(O$7-$I$7))/$F14,1),"n/a") -> 795069.22 | P14: =IF(ISNUMBER($D14),$D14*(1+$G14)^(P$7-$I$7)*IF($F14>1,(1+($F14-1)*(1-$H14)^(P$7-$I$7))/$F14,1),"n/a") -> 783894.57 | ... AK14: =IF(ISNUMBER($D14),$D14*(1+$G14)^(AK$7-$I$7)*IF($F14>1,(1+($F14-1)*(1-$H14)^(AK$7-$I$7))/$F14,1),"n/a") -> 613166.75
A15: 2 | B15: Road - Passenger HDV | C15: BEV | D15: ='Fuel Price'!C84 -> 896510.23 | E15: ='Fuel Price'!$J$84 -> 298836.74 | F15: =IF(ISNUMBER(D15),D15/E15,"n/a") -> 3 | G15: =Assumptions!$E$19 -> 0 | H15: {=INDEX(Assumptions!$B$34:$B$40,MATCH($C15,Assumptions!$A$34:$A$40,0))} -> 0.03 | I15: =IF(ISNUMBER($D15),$D15*(1+$G15)^(I$7-$I$7)*IF($F15>1,(1+($F15-1)*(1-$H15)^(I$7-$I$7))/$F15,1),"n/a") -> 896510.23 | J15: =IF(ISNUMBER($D15),$D15*(1+$G15)^(J$7-$I$7)*IF($F15>1,(1+($F15-1)*(1-$H15)^(J$7-$I$7))/$F15,1),"n/a") -> 878580.03 | K15: =IF(ISNUMBER($D15),$D15*(1+$G15)^(K$7-$I$7)*IF($F15>1,(1+($F15-1)*(1-$H15)^(K$7-$I$7))/$F15,1),"n/a") -> 861187.73 | L15: =IF(ISNUMBER($D15),$D15*(1+$G15)^(L$7-$I$7)*IF($F15>1,(1+($F15-1)*(1-$H15)^(L$7-$I$7))/$F15,1),"n/a") -> 844317.2 | M15: =IF(ISNUMBER($D15),$D15*(1+$G15)^(M$7-$I$7)*IF($F15>1,(1+($F15-1)*(1-$H15)^(M$7-$I$7))/$F15,1),"n/a") -> 827952.79 | N15: =IF(ISNUMBER($D15),$D15*(1+$G15)^(N$7-$I$7)*IF($F15>1,(1+($F15-1)*(1-$H15)^(N$7-$I$7))/$F15,1),"n/a") -> 812079.3 | O15: =IF(ISNUMBER($D15),$D15*(1+$G15)^(O$7-$I$7)*IF($F15>1,(1+($F15-1)*(1-$H15)^(O$7-$I$7))/$F15,1),"n/a") -> 796682.03 | P15: =IF(ISNUMBER($D15),$D15*(1+$G15)^(P$7-$I$7)*IF($F15>1,(1+($F15-1)*(1-$H15)^(P$7-$I$7))/$F15,1),"n/a") -> 781746.67 | ... AK15: =IF(ISNUMBER($D15),$D15*(1+$G15)^(AK$7-$I$7)*IF($F15>1,(1+($F15-1)*(1-$H15)^(AK$7-$I$7))/$F15,1),"n/a") -> 553562.32
A16: 2 | B16: Road - Passenger HDV | C16: NGV | D16: ='Fuel Price'!D84 -> 358604.09 | E16: ='Fuel Price'!$J$84 -> 298836.74 | F16: =IF(ISNUMBER(D16),D16/E16,"n/a") -> 1.2 | G16: =Assumptions!$E$19 -> 0 | H16: {=INDEX(Assumptions!$B$34:$B$40,MATCH($C16,Assumptions!$A$34:$A$40,0))} -> 0.01 | I16: =IF(ISNUMBER($D16),$D16*(1+$G16)^(I$7-$I$7)*IF($F16>1,(1+($F16-1)*(1-$H16)^(I$7-$I$7))/$F16,1),"n/a") -> 358604.09 | J16: =IF(ISNUMBER($D16),$D16*(1+$G16)^(J$7-$I$7)*IF($F16>1,(1+($F16-1)*(1-$H16)^(J$7-$I$7))/$F16,1),"n/a") -> 358006.42 | K16: =IF(ISNUMBER($D16),$D16*(1+$G16)^(K$7-$I$7)*IF($F16>1,(1+($F16-1)*(1-$H16)^(K$7-$I$7))/$F16,1),"n/a") -> 357414.72 | L16: =IF(ISNUMBER($D16),$D16*(1+$G16)^(L$7-$I$7)*IF($F16>1,(1+($F16-1)*(1-$H16)^(L$7-$I$7))/$F16,1),"n/a") -> 356828.94 | M16: =IF(ISNUMBER($D16),$D16*(1+$G16)^(M$7-$I$7)*IF($F16>1,(1+($F16-1)*(1-$H16)^(M$7-$I$7))/$F16,1),"n/a") -> 356249.02 | N16: =IF(ISNUMBER($D16),$D16*(1+$G16)^(N$7-$I$7)*IF($F16>1,(1+($F16-1)*(1-$H16)^(N$7-$I$7))/$F16,1),"n/a") -> 355674.9 | O16: =IF(ISNUMBER($D16),$D16*(1+$G16)^(O$7-$I$7)*IF($F16>1,(1+($F16-1)*(1-$H16)^(O$7-$I$7))/$F16,1),"n/a") -> 355106.52 | P16: =IF(ISNUMBER($D16),$D16*(1+$G16)^(P$7-$I$7)*IF($F16>1,(1+($F16-1)*(1-$H16)^(P$7-$I$7))/$F16,1),"n/a") -> 354543.82 | ... AK16: =IF(ISNUMBER($D16),$D16*(1+$G16)^(AK$7-$I$7)*IF($F16>1,(1+($F16-1)*(1-$H16)^(AK$7-$I$7))/$F16,1),"n/a") -> 343944.31
A17: 2 | B17: Road - Passenger HDV | C17: Gasoline | D17: ='Fuel Price'!E84 -> n/a | E17: ='Fuel Price'!$J$84 -> 298836.74 | F17: =IF(ISNUMBER(D17),D17/E17,"n/a") -> n/a | G17: =Assumptions!$E$19 -> 0 | H17: {=INDEX(Assumptions!$B$34:$B$40,MATCH($C17,Assumptions!$A$34:$A$40,0))} -> 0 | I17: =IF(ISNUMBER($D17),$D17*(1+$G17)^(I$7-$I$7)*IF($F17>1,(1+($F17-1)*(1-$H17)^(I$7-$I$7))/$F17,1),"n/a") -> n/a | J17: =IF(ISNUMBER($D17),$D17*(1+$G17)^(J$7-$I$7)*IF($F17>1,(1+($F17-1)*(1-$H17)^(J$7-$I$7))/$F17,1),"n/a") -> n/a | K17: =IF(ISNUMBER($D17),$D17*(1+$G17)^(K$7-$I$7)*IF($F17>1,(1+($F17-1)*(1-$H17)^(K$7-$I$7))/$F17,1),"n/a") -> n/a | L17: =IF(ISNUMBER($D17),$D17*(1+$G17)^(L$7-$I$7)*IF($F17>1,(1+($F17-1)*(1-$H17)^(L$7-$I$7))/$F17,1),"n/a") -> n/a | M17: =IF(ISNUMBER($D17),$D17*(1+$G17)^(M$7-$I$7)*IF($F17>1,(1+($F17-1)*(1-$H17)^(M$7-$I$7))/$F17,1),"n/a") -> n/a | N17: =IF(ISNUMBER($D17),$D17*(1+$G17)^(N$7-$I$7)*IF($F17>1,(1+($F17-1)*(1-$H17)^(N$7-$I$7))/$F17,1),"n/a") -> n/a | O17: =IF(ISNUMBER($D17),$D17*(1+$G17)^(O$7-$I$7)*IF($F17>1,(1+($F17-1)*(1-$H17)^(O$7-$I$7))/$F17,1),"n/a") -> n/a | P17: =IF(ISNUMBER($D17),$D17*(1+$G17)^(P$7-$I$7)*IF($F17>1,(1+($F17-1)*(1-$H17)^(P$7-$I$7))/$F17,1),"n/a") -> n/a | ... AK17: =IF(ISNUMBER($D17),$D17*(1+$G17)^(AK$7-$I$7)*IF($F17>1,(1+($F17-1)*(1-$H17)^(AK$7-$I$7))/$F17,1),"n/a") -> n/a
A18: 2 | B18: Road - Passenger HDV | C18: Diesel | D18: ='Fuel Price'!F84 -> 298836.74 | E18: ='Fuel Price'!$J$84 -> 298836.74 | F18: =IF(ISNUMBER(D18),D18/E18,"n/a") -> 1 | G18: =Assumptions!$E$19 -> 0 | H18: {=INDEX(Assumptions!$B$34:$B$40,MATCH($C18,Assumptions!$A$34:$A$40,0))} -> 0 | I18: =IF(ISNUMBER($D18),$D18*(1+$G18)^(I$7-$I$7)*IF($F18>1,(1+($F18-1)*(1-$H18)^(I$7-$I$7))/$F18,1),"n/a") -> 298836.74 | J18: =IF(ISNUMBER($D18),$D18*(1+$G18)^(J$7-$I$7)*IF($F18>1,(1+($F18-1)*(1-$H18)^(J$7-$I$7))/$F18,1),"n/a") -> 298836.74 | K18: =IF(ISNUMBER($D18),$D18*(1+$G18)^(K$7-$I$7)*IF($F18>1,(1+($F18-1)*(1-$H18)^(K$7-$I$7))/$F18,1),"n/a") -> 298836.74 | L18: =IF(ISNUMBER($D18),$D18*(1+$G18)^(L$7-$I$7)*IF($F18>1,(1+($F18-1)*(1-$H18)^(L$7-$I$7))/$F18,1),"n/a") -> 298836.74 | M18: =IF(ISNUMBER($D18),$D18*(1+$G18)^(M$7-$I$7)*IF($F18>1,(1+($F18-1)*(1-$H18)^(M$7-$I$7))/$F18,1),"n/a") -> 298836.74 | N18: =IF(ISNUMBER($D18),$D18*(1+$G18)^(N$7-$I$7)*IF($F18>1,(1+($F18-1)*(1-$H18)^(N$7-$I$7))/$F18,1),"n/a") -> 298836.74 | O18: =IF(ISNUMBER($D18),$D18*(1+$G18)^(O$7-$I$7)*IF($F18>1,(1+($F18-1)*(1-$H18)^(O$7-$I$7))/$F18,1),"n/a") -> 298836.74 | P18: =IF(ISNUMBER($D18),$D18*(1+$G18)^(P$7-$I$7)*IF($F18>1,(1+($F18-1)*(1-$H18)^(P$7-$I$7))/$F18,1),"n/a") -> 298836.74 | ... AK18: =IF(ISNUMBER($D18),$D18*(1+$G18)^(AK$7-$I$7)*IF($F18>1,(1+($F18-1)*(1-$H18)^(AK$7-$I$7))/$F18,1),"n/a") -> 298836.74
A19: 2 | B19: Road - Passenger HDV | C19: PHEV | D19: ='Fuel Price'!G84 -> n/a | E19: ='Fuel Price'!$J$84 -> 298836.74 | F19: =IF(ISNUMBER(D19),D19/E19,"n/a") -> n/a | G19: =Assumptions!$E$19 -> 0 | H19: {=INDEX(Assumptions!$B$34:$B$40,MATCH($C19,Assumptions!$A$34:$A$40,0))} -> 0.02 | I19: =IF(ISNUMBER($D19),$D19*(1+$G19)^(I$7-$I$7)*IF($F19>1,(1+($F19-1)*(1-$H19)^(I$7-$I$7))/$F19,1),"n/a") -> n/a | J19: =IF(ISNUMBER($D19),$D19*(1+$G19)^(J$7-$I$7)*IF($F19>1,(1+($F19-1)*(1-$H19)^(J$7-$I$7))/$F19,1),"n/a") -> n/a | K19: =IF(ISNUMBER($D19),$D19*(1+$G19)^(K$7-$I$7)*IF($F19>1,(1+($F19-1)*(1-$H19)^(K$7-$I$7))/$F19,1),"n/a") -> n/a | L19: =IF(ISNUMBER($D19),$D19*(1+$G19)^(L$7-$I$7)*IF($F19>1,(1+($F19-1)*(1-$H19)^(L$7-$I$7))/$F19,1),"n/a") -> n/a | M19: =IF(ISNUMBER($D19),$D19*(1+$G19)^(M$7-$I$7)*IF($F19>1,(1+($F19-1)*(1-$H19)^(M$7-$I$7))/$F19,1),"n/a") -> n/a | N19: =IF(ISNUMBER($D19),$D19*(1+$G19)^(N$7-$I$7)*IF($F19>1,(1+($F19-1)*(1-$H19)^(N$7-$I$7))/$F19,1),"n/a") -> n/a | O19: =IF(ISNUMBER($D19),$D19*(1+$G19)^(O$7-$I$7)*IF($F19>1,(1+($F19-1)*(1-$H19)^(O$7-$I$7))/$F19,1),"n/a") -> n/a | P19: =IF(ISNUMBER($D19),$D19*(1+$G19)^(P$7-$I$7)*IF($F19>1,(1+($F19-1)*(1-$H19)^(P$7-$I$7))/$F19,1),"n/a") -> n/a | ... AK19: =IF(ISNUMBER($D19),$D19*(1+$G19)^(AK$7-$I$7)*IF($F19>1,(1+($F19-1)*(1-$H19)^(AK$7-$I$7))/$F19,1),"n/a") -> n/a
A20: 2 | B20: Road - Passenger HDV | C20: LPG | D20: ='Fuel Price'!H84 -> n/a | E20: ='Fuel Price'!$J$84 -> 298836.74 | F20: =IF(ISNUMBER(D20),D20/E20,"n/a") -> n/a | G20: =Assumptions!$E$19 -> 0 | H20: {=INDEX(Assumptions!$B$34:$B$40,MATCH($C20,Assumptions!$A$34:$A$40,0))} -> 0.01 | I20: =IF(ISNUMBER($D20),$D20*(1+$G20)^(I$7-$I$7)*IF($F20>1,(1+($F20-1)*(1-$H20)^(I$7-$I$7))/$F20,1),"n/a") -> n/a | J20: =IF(ISNUMBER($D20),$D20*(1+$G20)^(J$7-$I$7)*IF($F20>1,(1+($F20-1)*(1-$H20)^(J$7-$I$7))/$F20,1),"n/a") -> n/a | K20: =IF(ISNUMBER($D20),$D20*(1+$G20)^(K$7-$I$7)*IF($F20>1,(1+($F20-1)*(1-$H20)^(K$7-$I$7))/$F20,1),"n/a") -> n/a | L20: =IF(ISNUMBER($D20),$D20*(1+$G20)^(L$7-$I$7)*IF($F20>1,(1+($F20-1)*(1-$H20)^(L$7-$I$7))/$F20,1),"n/a") -> n/a | M20: =IF(ISNUMBER($D20),$D20*(1+$G20)^(M$7-$I$7)*IF($F20>1,(1+($F20-1)*(1-$H20)^(M$7-$I$7))/$F20,1),"n/a") -> n/a | N20: =IF(ISNUMBER($D20),$D20*(1+$G20)^(N$7-$I$7)*IF($F20>1,(1+($F20-1)*(1-$H20)^(N$7-$I$7))/$F20,1),"n/a") -> n/a | O20: =IF(ISNUMBER($D20),$D20*(1+$G20)^(O$7-$I$7)*IF($F20>1,(1+($F20-1)*(1-$H20)^(O$7-$I$7))/$F20,1),"n/a") -> n/a | P20: =IF(ISNUMBER($D20),$D20*(1+$G20)^(P$7-$I$7)*IF($F20>1,(1+($F20-1)*(1-$H20)^(P$7-$I$7))/$F20,1),"n/a") -> n/a | ... AK20: =IF(ISNUMBER($D20),$D20*(1+$G20)^(AK$7-$I$7)*IF($F20>1,(1+($F20-1)*(1-$H20)^(AK$7-$I$7))/$F20,1),"n/a") -> n/a
A21: 2 | B21: Road - Passenger HDV | C21: Hydrogen | D21: ='Fuel Price'!I84 -> 1344765.3 | E21: ='Fuel Price'!$J$84 -> 298836.74 | F21: =IF(ISNUMBER(D21),D21/E21,"n/a") -> 4.5 | G21: =Assumptions!$E$19 -> 0 | H21: {=INDEX(Assumptions!$B$34:$B$40,MATCH($C21,Assumptions!$A$34:$A$40,0))} -> 0.03 | I21: =IF(ISNUMBER($D21),$D21*(1+$G21)^(I$7-$I$7)*IF($F21>1,(1+($F21-1)*(1-$H21)^(I$7-$I$7))/$F21,1),"n/a") -> 1344765.3 | J21: =IF(ISNUMBER($D21),$D21*(1+$G21)^(J$7-$I$7)*IF($F21>1,(1+($F21-1)*(1-$H21)^(J$7-$I$7))/$F21,1),"n/a") -> 1313387.5 | K21: =IF(ISNUMBER($D21),$D21*(1+$G21)^(K$7-$I$7)*IF($F21>1,(1+($F21-1)*(1-$H21)^(K$7-$I$7))/$F21,1),"n/a") -> 1282951 | L21: =IF(ISNUMBER($D21),$D21*(1+$G21)^(L$7-$I$7)*IF($F21>1,(1+($F21-1)*(1-$H21)^(L$7-$I$7))/$F21,1),"n/a") -> 1253427.5 | M21: =IF(ISNUMBER($D21),$D21*(1+$G21)^(M$7-$I$7)*IF($F21>1,(1+($F21-1)*(1-$H21)^(M$7-$I$7))/$F21,1),"n/a") -> 1224789.8 | N21: =IF(ISNUMBER($D21),$D21*(1+$G21)^(N$7-$I$7)*IF($F21>1,(1+($F21-1)*(1-$H21)^(N$7-$I$7))/$F21,1),"n/a") -> 1197011.2 | O21: =IF(ISNUMBER($D21),$D21*(1+$G21)^(O$7-$I$7)*IF($F21>1,(1+($F21-1)*(1-$H21)^(O$7-$I$7))/$F21,1),"n/a") -> 1170066 | P21: =IF(ISNUMBER($D21),$D21*(1+$G21)^(P$7-$I$7)*IF($F21>1,(1+($F21-1)*(1-$H21)^(P$7-$I$7))/$F21,1),"n/a") -> 1143929.1 | ... AK21: =IF(ISNUMBER($D21),$D21*(1+$G21)^(AK$7-$I$7)*IF($F21>1,(1+($F21-1)*(1-$H21)^(AK$7-$I$7))/$F21,1),"n/a") -> 744606.5
A22: 3 | B22: Road - Freight LDV | C22: BEV | D22: ='Fuel Price'!C85 -> 192448.68 | E22: ='Fuel Price'!$J$85 -> 136355.91 | F22: =IF(ISNUMBER(D22),D22/E22,"n/a") -> 1.4113703 | G22: =Assumptions!$E$20 -> 0 | H22: {=INDEX(Assumptions!$B$34:$B$40,MATCH($C22,Assumptions!$A$34:$A$40,0))} -> 0.03 | I22: =IF(ISNUMBER($D22),$D22*(1+$G22)^(I$7-$I$7)*IF($F22>1,(1+($F22-1)*(1-$H22)^(I$7-$I$7))/$F22,1),"n/a") -> 192448.68 | J22: =IF(ISNUMBER($D22),$D22*(1+$G22)^(J$7-$I$7)*IF($F22>1,(1+($F22-1)*(1-$H22)^(J$7-$I$7))/$F22,1),"n/a") -> 190765.9 | K22: =IF(ISNUMBER($D22),$D22*(1+$G22)^(K$7-$I$7)*IF($F22>1,(1+($F22-1)*(1-$H22)^(K$7-$I$7))/$F22,1),"n/a") -> 189133.6 | L22: =IF(ISNUMBER($D22),$D22*(1+$G22)^(L$7-$I$7)*IF($F22>1,(1+($F22-1)*(1-$H22)^(L$7-$I$7))/$F22,1),"n/a") -> 187550.27 | M22: =IF(ISNUMBER($D22),$D22*(1+$G22)^(M$7-$I$7)*IF($F22>1,(1+($F22-1)*(1-$H22)^(M$7-$I$7))/$F22,1),"n/a") -> 186014.44 | N22: =IF(ISNUMBER($D22),$D22*(1+$G22)^(N$7-$I$7)*IF($F22>1,(1+($F22-1)*(1-$H22)^(N$7-$I$7))/$F22,1),"n/a") -> 184524.68 | O22: =IF(ISNUMBER($D22),$D22*(1+$G22)^(O$7-$I$7)*IF($F22>1,(1+($F22-1)*(1-$H22)^(O$7-$I$7))/$F22,1),"n/a") -> 183079.62 | P22: =IF(ISNUMBER($D22),$D22*(1+$G22)^(P$7-$I$7)*IF($F22>1,(1+($F22-1)*(1-$H22)^(P$7-$I$7))/$F22,1),"n/a") -> 181677.91 | ... AK22: =IF(ISNUMBER($D22),$D22*(1+$G22)^(AK$7-$I$7)*IF($F22>1,(1+($F22-1)*(1-$H22)^(AK$7-$I$7))/$F22,1),"n/a") -> 160262.38
A23: 3 | B23: Road - Freight LDV | C23: NGV | D23: ='Fuel Price'!D85 -> 141355.91 | E23: ='Fuel Price'!$J$85 -> 136355.91 | F23: =IF(ISNUMBER(D23),D23/E23,"n/a") -> 1.0366687 | G23: =Assumptions!$E$20 -> 0 | H23: {=INDEX(Assumptions!$B$34:$B$40,MATCH($C23,Assumptions!$A$34:$A$40,0))} -> 0.01 | I23: =IF(ISNUMBER($D23),$D23*(1+$G23)^(I$7-$I$7)*IF($F23>1,(1+($F23-1)*(1-$H23)^(I$7-$I$7))/$F23,1),"n/a") -> 141355.91 | J23: =IF(ISNUMBER($D23),$D23*(1+$G23)^(J$7-$I$7)*IF($F23>1,(1+($F23-1)*(1-$H23)^(J$7-$I$7))/$F23,1),"n/a") -> 141305.91 | K23: =IF(ISNUMBER($D23),$D23*(1+$G23)^(K$7-$I$7)*IF($F23>1,(1+($F23-1)*(1-$H23)^(K$7-$I$7))/$F23,1),"n/a") -> 141256.41 | L23: =IF(ISNUMBER($D23),$D23*(1+$G23)^(L$7-$I$7)*IF($F23>1,(1+($F23-1)*(1-$H23)^(L$7-$I$7))/$F23,1),"n/a") -> 141207.41 | M23: =IF(ISNUMBER($D23),$D23*(1+$G23)^(M$7-$I$7)*IF($F23>1,(1+($F23-1)*(1-$H23)^(M$7-$I$7))/$F23,1),"n/a") -> 141158.89 | N23: =IF(ISNUMBER($D23),$D23*(1+$G23)^(N$7-$I$7)*IF($F23>1,(1+($F23-1)*(1-$H23)^(N$7-$I$7))/$F23,1),"n/a") -> 141110.86 | O23: =IF(ISNUMBER($D23),$D23*(1+$G23)^(O$7-$I$7)*IF($F23>1,(1+($F23-1)*(1-$H23)^(O$7-$I$7))/$F23,1),"n/a") -> 141063.31 | P23: =IF(ISNUMBER($D23),$D23*(1+$G23)^(P$7-$I$7)*IF($F23>1,(1+($F23-1)*(1-$H23)^(P$7-$I$7))/$F23,1),"n/a") -> 141016.24 | ... AK23: =IF(ISNUMBER($D23),$D23*(1+$G23)^(AK$7-$I$7)*IF($F23>1,(1+($F23-1)*(1-$H23)^(AK$7-$I$7))/$F23,1),"n/a") -> 140129.51
A24: 3 | B24: Road - Freight LDV | C24: Gasoline | D24: ='Fuel Price'!E85 -> 136355.91 | E24: ='Fuel Price'!$J$85 -> 136355.91 | F24: =IF(ISNUMBER(D24),D24/E24,"n/a") -> 1 | G24: =Assumptions!$E$20 -> 0 | H24: {=INDEX(Assumptions!$B$34:$B$40,MATCH($C24,Assumptions!$A$34:$A$40,0))} -> 0 | I24: =IF(ISNUMBER($D24),$D24*(1+$G24)^(I$7-$I$7)*IF($F24>1,(1+($F24-1)*(1-$H24)^(I$7-$I$7))/$F24,1),"n/a") -> 136355.91 | J24: =IF(ISNUMBER($D24),$D24*(1+$G24)^(J$7-$I$7)*IF($F24>1,(1+($F24-1)*(1-$H24)^(J$7-$I$7))/$F24,1),"n/a") -> 136355.91 | K24: =IF(ISNUMBER($D24),$D24*(1+$G24)^(K$7-$I$7)*IF($F24>1,(1+($F24-1)*(1-$H24)^(K$7-$I$7))/$F24,1),"n/a") -> 136355.91 | L24: =IF(ISNUMBER($D24),$D24*(1+$G24)^(L$7-$I$7)*IF($F24>1,(1+($F24-1)*(1-$H24)^(L$7-$I$7))/$F24,1),"n/a") -> 136355.91 | M24: =IF(ISNUMBER($D24),$D24*(1+$G24)^(M$7-$I$7)*IF($F24>1,(1+($F24-1)*(1-$H24)^(M$7-$I$7))/$F24,1),"n/a") -> 136355.91 | N24: =IF(ISNUMBER($D24),$D24*(1+$G24)^(N$7-$I$7)*IF($F24>1,(1+($F24-1)*(1-$H24)^(N$7-$I$7))/$F24,1),"n/a") -> 136355.91 | O24: =IF(ISNUMBER($D24),$D24*(1+$G24)^(O$7-$I$7)*IF($F24>1,(1+($F24-1)*(1-$H24)^(O$7-$I$7))/$F24,1),"n/a") -> 136355.91 | P24: =IF(ISNUMBER($D24),$D24*(1+$G24)^(P$7-$I$7)*IF($F24>1,(1+($F24-1)*(1-$H24)^(P$7-$I$7))/$F24,1),"n/a") -> 136355.91 | ... AK24: =IF(ISNUMBER($D24),$D24*(1+$G24)^(AK$7-$I$7)*IF($F24>1,(1+($F24-1)*(1-$H24)^(AK$7-$I$7))/$F24,1),"n/a") -> 136355.91
A25: 3 | B25: Road - Freight LDV | C25: Diesel | D25: ='Fuel Price'!F85 -> 239296.88 | E25: ='Fuel Price'!$J$85 -> 136355.91 | F25: =IF(ISNUMBER(D25),D25/E25,"n/a") -> 1.7549432 | G25: =Assumptions!$E$20 -> 0 | H25: {=INDEX(Assumptions!$B$34:$B$40,MATCH($C25,Assumptions!$A$34:$A$40,0))} -> 0 | I25: =IF(ISNUMBER($D25),$D25*(1+$G25)^(I$7-$I$7)*IF($F25>1,(1+($F25-1)*(1-$H25)^(I$7-$I$7))/$F25,1),"n/a") -> 239296.88 | J25: =IF(ISNUMBER($D25),$D25*(1+$G25)^(J$7-$I$7)*IF($F25>1,(1+($F25-1)*(1-$H25)^(J$7-$I$7))/$F25,1),"n/a") -> 239296.88 | K25: =IF(ISNUMBER($D25),$D25*(1+$G25)^(K$7-$I$7)*IF($F25>1,(1+($F25-1)*(1-$H25)^(K$7-$I$7))/$F25,1),"n/a") -> 239296.88 | L25: =IF(ISNUMBER($D25),$D25*(1+$G25)^(L$7-$I$7)*IF($F25>1,(1+($F25-1)*(1-$H25)^(L$7-$I$7))/$F25,1),"n/a") -> 239296.88 | M25: =IF(ISNUMBER($D25),$D25*(1+$G25)^(M$7-$I$7)*IF($F25>1,(1+($F25-1)*(1-$H25)^(M$7-$I$7))/$F25,1),"n/a") -> 239296.88 | N25: =IF(ISNUMBER($D25),$D25*(1+$G25)^(N$7-$I$7)*IF($F25>1,(1+($F25-1)*(1-$H25)^(N$7-$I$7))/$F25,1),"n/a") -> 239296.88 | O25: =IF(ISNUMBER($D25),$D25*(1+$G25)^(O$7-$I$7)*IF($F25>1,(1+($F25-1)*(1-$H25)^(O$7-$I$7))/$F25,1),"n/a") -> 239296.88 | P25: =IF(ISNUMBER($D25),$D25*(1+$G25)^(P$7-$I$7)*IF($F25>1,(1+($F25-1)*(1-$H25)^(P$7-$I$7))/$F25,1),"n/a") -> 239296.88 | ... AK25: =IF(ISNUMBER($D25),$D25*(1+$G25)^(AK$7-$I$7)*IF($F25>1,(1+($F25-1)*(1-$H25)^(AK$7-$I$7))/$F25,1),"n/a") -> 239296.88
A26: 3 | B26: Road - Freight LDV | C26: PHEV | D26: ='Fuel Price'!G85 -> n/a | E26: ='Fuel Price'!$J$85 -> 136355.91 | F26: =IF(ISNUMBER(D26),D26/E26,"n/a") -> n/a | G26: =Assumptions!$E$20 -> 0 | H26: {=INDEX(Assumptions!$B$34:$B$40,MATCH($C26,Assumptions!$A$34:$A$40,0))} -> 0.02 | I26: =IF(ISNUMBER($D26),$D26*(1+$G26)^(I$7-$I$7)*IF($F26>1,(1+($F26-1)*(1-$H26)^(I$7-$I$7))/$F26,1),"n/a") -> n/a | J26: =IF(ISNUMBER($D26),$D26*(1+$G26)^(J$7-$I$7)*IF($F26>1,(1+($F26-1)*(1-$H26)^(J$7-$I$7))/$F26,1),"n/a") -> n/a | K26: =IF(ISNUMBER($D26),$D26*(1+$G26)^(K$7-$I$7)*IF($F26>1,(1+($F26-1)*(1-$H26)^(K$7-$I$7))/$F26,1),"n/a") -> n/a | L26: =IF(ISNUMBER($D26),$D26*(1+$G26)^(L$7-$I$7)*IF($F26>1,(1+($F26-1)*(1-$H26)^(L$7-$I$7))/$F26,1),"n/a") -> n/a | M26: =IF(ISNUMBER($D26),$D26*(1+$G26)^(M$7-$I$7)*IF($F26>1,(1+($F26-1)*(1-$H26)^(M$7-$I$7))/$F26,1),"n/a") -> n/a | N26: =IF(ISNUMBER($D26),$D26*(1+$G26)^(N$7-$I$7)*IF($F26>1,(1+($F26-1)*(1-$H26)^(N$7-$I$7))/$F26,1),"n/a") -> n/a | O26: =IF(ISNUMBER($D26),$D26*(1+$G26)^(O$7-$I$7)*IF($F26>1,(1+($F26-1)*(1-$H26)^(O$7-$I$7))/$F26,1),"n/a") -> n/a | P26: =IF(ISNUMBER($D26),$D26*(1+$G26)^(P$7-$I$7)*IF($F26>1,(1+($F26-1)*(1-$H26)^(P$7-$I$7))/$F26,1),"n/a") -> n/a | ... AK26: =IF(ISNUMBER($D26),$D26*(1+$G26)^(AK$7-$I$7)*IF($F26>1,(1+($F26-1)*(1-$H26)^(AK$7-$I$7))/$F26,1),"n/a") -> n/a
A27: 3 | B27: Road - Freight LDV | C27: LPG | D27: ='Fuel Price'!H85 -> n/a | E27: ='Fuel Price'!$J$85 -> 136355.91 | F27: =IF(ISNUMBER(D27),D27/E27,"n/a") -> n/a | G27: =Assumptions!$E$20 -> 0 | H27: {=INDEX(Assumptions!$B$34:$B$40,MATCH($C27,Assumptions!$A$34:$A$40,0))} -> 0.01 | I27: =IF(ISNUMBER($D27),$D27*(1+$G27)^(I$7-$I$7)*IF($F27>1,(1+($F27-1)*(1-$H27)^(I$7-$I$7))/$F27,1),"n/a") -> n/a | J27: =IF(ISNUMBER($D27),$D27*(1+$G27)^(J$7-$I$7)*IF($F27>1,(1+($F27-1)*(1-$H27)^(J$7-$I$7))/$F27,1),"n/a") -> n/a | K27: =IF(ISNUMBER($D27),$D27*(1+$G27)^(K$7-$I$7)*IF($F27>1,(1+($F27-1)*(1-$H27)^(K$7-$I$7))/$F27,1),"n/a") -> n/a | L27: =IF(ISNUMBER($D27),$D27*(1+$G27)^(L$7-$I$7)*IF($F27>1,(1+($F27-1)*(1-$H27)^(L$7-$I$7))/$F27,1),"n/a") -> n/a | M27: =IF(ISNUMBER($D27),$D27*(1+$G27)^(M$7-$I$7)*IF($F27>1,(1+($F27-1)*(1-$H27)^(M$7-$I$7))/$F27,1),"n/a") -> n/a | N27: =IF(ISNUMBER($D27),$D27*(1+$G27)^(N$7-$I$7)*IF($F27>1,(1+($F27-1)*(1-$H27)^(N$7-$I$7))/$F27,1),"n/a") -> n/a | O27: =IF(ISNUMBER($D27),$D27*(1+$G27)^(O$7-$I$7)*IF($F27>1,(1+($F27-1)*(1-$H27)^(O$7-$I$7))/$F27,1),"n/a") -> n/a | P27: =IF(ISNUMBER($D27),$D27*(1+$G27)^(P$7-$I$7)*IF($F27>1,(1+($F27-1)*(1-$H27)^(P$7-$I$7))/$F27,1),"n/a") -> n/a | ... AK27: =IF(ISNUMBER($D27),$D27*(1+$G27)^(AK$7-$I$7)*IF($F27>1,(1+($F27-1)*(1-$H27)^(AK$7-$I$7))/$F27,1),"n/a") -> n/a
A28: 3 | B28: Road - Freight LDV | C28: Hydrogen | D28: ='Fuel Price'!I85 -> 280649.38 | E28: ='Fuel Price'!$J$85 -> 136355.91 | F28: =IF(ISNUMBER(D28),D28/E28,"n/a") -> 2.0582121 | G28: =Assumptions!$E$20 -> 0 | H28: {=INDEX(Assumptions!$B$34:$B$40,MATCH($C28,Assumptions!$A$34:$A$40,0))} -> 0.03 | I28: =IF(ISNUMBER($D28),$D28*(1+$G28)^(I$7-$I$7)*IF($F28>1,(1+($F28-1)*(1-$H28)^(I$7-$I$7))/$F28,1),"n/a") -> 280649.38 | J28: =IF(ISNUMBER($D28),$D28*(1+$G28)^(J$7-$I$7)*IF($F28>1,(1+($F28-1)*(1-$H28)^(J$7-$I$7))/$F28,1),"n/a") -> 276320.58 | K28: =IF(ISNUMBER($D28),$D28*(1+$G28)^(K$7-$I$7)*IF($F28>1,(1+($F28-1)*(1-$H28)^(K$7-$I$7))/$F28,1),"n/a") -> 272121.64 | L28: =IF(ISNUMBER($D28),$D28*(1+$G28)^(L$7-$I$7)*IF($F28>1,(1+($F28-1)*(1-$H28)^(L$7-$I$7))/$F28,1),"n/a") -> 268048.67 | M28: =IF(ISNUMBER($D28),$D28*(1+$G28)^(M$7-$I$7)*IF($F28>1,(1+($F28-1)*(1-$H28)^(M$7-$I$7))/$F28,1),"n/a") -> 264097.88 | N28: =IF(ISNUMBER($D28),$D28*(1+$G28)^(N$7-$I$7)*IF($F28>1,(1+($F28-1)*(1-$H28)^(N$7-$I$7))/$F28,1),"n/a") -> 260265.62 | O28: =IF(ISNUMBER($D28),$D28*(1+$G28)^(O$7-$I$7)*IF($F28>1,(1+($F28-1)*(1-$H28)^(O$7-$I$7))/$F28,1),"n/a") -> 256548.33 | P28: =IF(ISNUMBER($D28),$D28*(1+$G28)^(P$7-$I$7)*IF($F28>1,(1+($F28-1)*(1-$H28)^(P$7-$I$7))/$F28,1),"n/a") -> 252942.56 | ... AK28: =IF(ISNUMBER($D28),$D28*(1+$G28)^(AK$7-$I$7)*IF($F28>1,(1+($F28-1)*(1-$H28)^(AK$7-$I$7))/$F28,1),"n/a") -> 197853.1
A29: 4 | B29: Road - Freight HDV | C29: BEV | D29: ='Fuel Price'!C86 -> 887554.84 | E29: ='Fuel Price'!$J$86 -> 295851.61 | F29: =IF(ISNUMBER(D29),D29/E29,"n/a") -> 3 | G29: =Assumptions!$E$21 -> 0 | H29: {=INDEX(Assumptions!$B$34:$B$40,MATCH($C29,Assumptions!$A$34:$A$40,0))} -> 0.03 | I29: =IF(ISNUMBER($D29),$D29*(1+$G29)^(I$7-$I$7)*IF($F29>1,(1+($F29-1)*(1-$H29)^(I$7-$I$7))/$F29,1),"n/a") -> 887554.84 | J29: =IF(ISNUMBER($D29),$D29*(1+$G29)^(J$7-$I$7)*IF($F29>1,(1+($F29-1)*(1-$H29)^(J$7-$I$7))/$F29,1),"n/a") -> 869803.74 | K29: =IF(ISNUMBER($D29),$D29*(1+$G29)^(K$7-$I$7)*IF($F29>1,(1+($F29-1)*(1-$H29)^(K$7-$I$7))/$F29,1),"n/a") -> 852585.18 | L29: =IF(ISNUMBER($D29),$D29*(1+$G29)^(L$7-$I$7)*IF($F29>1,(1+($F29-1)*(1-$H29)^(L$7-$I$7))/$F29,1),"n/a") -> 835883.17 | M29: =IF(ISNUMBER($D29),$D29*(1+$G29)^(M$7-$I$7)*IF($F29>1,(1+($F29-1)*(1-$H29)^(M$7-$I$7))/$F29,1),"n/a") -> 819682.22 | N29: =IF(ISNUMBER($D29),$D29*(1+$G29)^(N$7-$I$7)*IF($F29>1,(1+($F29-1)*(1-$H29)^(N$7-$I$7))/$F29,1),"n/a") -> 803967.3 | O29: =IF(ISNUMBER($D29),$D29*(1+$G29)^(O$7-$I$7)*IF($F29>1,(1+($F29-1)*(1-$H29)^(O$7-$I$7))/$F29,1),"n/a") -> 788723.83 | P29: =IF(ISNUMBER($D29),$D29*(1+$G29)^(P$7-$I$7)*IF($F29>1,(1+($F29-1)*(1-$H29)^(P$7-$I$7))/$F29,1),"n/a") -> 773937.67 | ... AK29: =IF(ISNUMBER($D29),$D29*(1+$G29)^(AK$7-$I$7)*IF($F29>1,(1+($F29-1)*(1-$H29)^(AK$7-$I$7))/$F29,1),"n/a") -> 548032.69
A30: 4 | B30: Road - Freight HDV | C30: NGV | D30: ='Fuel Price'!D86 -> 355021.93 | E30: ='Fuel Price'!$J$86 -> 295851.61 | F30: =IF(ISNUMBER(D30),D30/E30,"n/a") -> 1.2 | G30: =Assumptions!$E$21 -> 0 | H30: {=INDEX(Assumptions!$B$34:$B$40,MATCH($C30,Assumptions!$A$34:$A$40,0))} -> 0.01 | I30: =IF(ISNUMBER($D30),$D30*(1+$G30)^(I$7-$I$7)*IF($F30>1,(1+($F30-1)*(1-$H30)^(I$7-$I$7))/$F30,1),"n/a") -> 355021.93 | J30: =IF(ISNUMBER($D30),$D30*(1+$G30)^(J$7-$I$7)*IF($F30>1,(1+($F30-1)*(1-$H30)^(J$7-$I$7))/$F30,1),"n/a") -> 354430.23 | K30: =IF(ISNUMBER($D30),$D30*(1+$G30)^(K$7-$I$7)*IF($F30>1,(1+($F30-1)*(1-$H30)^(K$7-$I$7))/$F30,1),"n/a") -> 353844.44 | L30: =IF(ISNUMBER($D30),$D30*(1+$G30)^(L$7-$I$7)*IF($F30>1,(1+($F30-1)*(1-$H30)^(L$7-$I$7))/$F30,1),"n/a") -> 353264.52 | M30: =IF(ISNUMBER($D30),$D30*(1+$G30)^(M$7-$I$7)*IF($F30>1,(1+($F30-1)*(1-$H30)^(M$7-$I$7))/$F30,1),"n/a") -> 352690.39 | N30: =IF(ISNUMBER($D30),$D30*(1+$G30)^(N$7-$I$7)*IF($F30>1,(1+($F30-1)*(1-$H30)^(N$7-$I$7))/$F30,1),"n/a") -> 352122 | O30: =IF(ISNUMBER($D30),$D30*(1+$G30)^(O$7-$I$7)*IF($F30>1,(1+($F30-1)*(1-$H30)^(O$7-$I$7))/$F30,1),"n/a") -> 351559.3 | P30: =IF(ISNUMBER($D30),$D30*(1+$G30)^(P$7-$I$7)*IF($F30>1,(1+($F30-1)*(1-$H30)^(P$7-$I$7))/$F30,1),"n/a") -> 351002.22 | ... AK30: =IF(ISNUMBER($D30),$D30*(1+$G30)^(AK$7-$I$7)*IF($F30>1,(1+($F30-1)*(1-$H30)^(AK$7-$I$7))/$F30,1),"n/a") -> 340508.6
A31: 4 | B31: Road - Freight HDV | C31: Gasoline | D31: ='Fuel Price'!E86 -> n/a | E31: ='Fuel Price'!$J$86 -> 295851.61 | F31: =IF(ISNUMBER(D31),D31/E31,"n/a") -> n/a | G31: =Assumptions!$E$21 -> 0 | H31: {=INDEX(Assumptions!$B$34:$B$40,MATCH($C31,Assumptions!$A$34:$A$40,0))} -> 0 | I31: =IF(ISNUMBER($D31),$D31*(1+$G31)^(I$7-$I$7)*IF($F31>1,(1+($F31-1)*(1-$H31)^(I$7-$I$7))/$F31,1),"n/a") -> n/a | J31: =IF(ISNUMBER($D31),$D31*(1+$G31)^(J$7-$I$7)*IF($F31>1,(1+($F31-1)*(1-$H31)^(J$7-$I$7))/$F31,1),"n/a") -> n/a | K31: =IF(ISNUMBER($D31),$D31*(1+$G31)^(K$7-$I$7)*IF($F31>1,(1+($F31-1)*(1-$H31)^(K$7-$I$7))/$F31,1),"n/a") -> n/a | L31: =IF(ISNUMBER($D31),$D31*(1+$G31)^(L$7-$I$7)*IF($F31>1,(1+($F31-1)*(1-$H31)^(L$7-$I$7))/$F31,1),"n/a") -> n/a | M31: =IF(ISNUMBER($D31),$D31*(1+$G31)^(M$7-$I$7)*IF($F31>1,(1+($F31-1)*(1-$H31)^(M$7-$I$7))/$F31,1),"n/a") -> n/a | N31: =IF(ISNUMBER($D31),$D31*(1+$G31)^(N$7-$I$7)*IF($F31>1,(1+($F31-1)*(1-$H31)^(N$7-$I$7))/$F31,1),"n/a") -> n/a | O31: =IF(ISNUMBER($D31),$D31*(1+$G31)^(O$7-$I$7)*IF($F31>1,(1+($F31-1)*(1-$H31)^(O$7-$I$7))/$F31,1),"n/a") -> n/a | P31: =IF(ISNUMBER($D31),$D31*(1+$G31)^(P$7-$I$7)*IF($F31>1,(1+($F31-1)*(1-$H31)^(P$7-$I$7))/$F31,1),"n/a") -> n/a | ... AK31: =IF(ISNUMBER($D31),$D31*(1+$G31)^(AK$7-$I$7)*IF($F31>1,(1+($F31-1)*(1-$H31)^(AK$7-$I$7))/$F31,1),"n/a") -> n/a
A32: 4 | B32: Road - Freight HDV | C32: Diesel | D32: ='Fuel Price'!F86 -> 295851.61 | E32: ='Fuel Price'!$J$86 -> 295851.61 | F32: =IF(ISNUMBER(D32),D32/E32,"n/a") -> 1 | G32: =Assumptions!$E$21 -> 0 | H32: {=INDEX(Assumptions!$B$34:$B$40,MATCH($C32,Assumptions!$A$34:$A$40,0))} -> 0 | I32: =IF(ISNUMBER($D32),$D32*(1+$G32)^(I$7-$I$7)*IF($F32>1,(1+($F32-1)*(1-$H32)^(I$7-$I$7))/$F32,1),"n/a") -> 295851.61 | J32: =IF(ISNUMBER($D32),$D32*(1+$G32)^(J$7-$I$7)*IF($F32>1,(1+($F32-1)*(1-$H32)^(J$7-$I$7))/$F32,1),"n/a") -> 295851.61 | K32: =IF(ISNUMBER($D32),$D32*(1+$G32)^(K$7-$I$7)*IF($F32>1,(1+($F32-1)*(1-$H32)^(K$7-$I$7))/$F32,1),"n/a") -> 295851.61 | L32: =IF(ISNUMBER($D32),$D32*(1+$G32)^(L$7-$I$7)*IF($F32>1,(1+($F32-1)*(1-$H32)^(L$7-$I$7))/$F32,1),"n/a") -> 295851.61 | M32: =IF(ISNUMBER($D32),$D32*(1+$G32)^(M$7-$I$7)*IF($F32>1,(1+($F32-1)*(1-$H32)^(M$7-$I$7))/$F32,1),"n/a") -> 295851.61 | N32: =IF(ISNUMBER($D32),$D32*(1+$G32)^(N$7-$I$7)*IF($F32>1,(1+($F32-1)*(1-$H32)^(N$7-$I$7))/$F32,1),"n/a") -> 295851.61 | O32: =IF(ISNUMBER($D32),$D32*(1+$G32)^(O$7-$I$7)*IF($F32>1,(1+($F32-1)*(1-$H32)^(O$7-$I$7))/$F32,1),"n/a") -> 295851.61 | P32: =IF(ISNUMBER($D32),$D32*(1+$G32)^(P$7-$I$7)*IF($F32>1,(1+($F32-1)*(1-$H32)^(P$7-$I$7))/$F32,1),"n/a") -> 295851.61 | ... AK32: =IF(ISNUMBER($D32),$D32*(1+$G32)^(AK$7-$I$7)*IF($F32>1,(1+($F32-1)*(1-$H32)^(AK$7-$I$7))/$F32,1),"n/a") -> 295851.61
A33: 4 | B33: Road - Freight HDV | C33: PHEV | D33: ='Fuel Price'!G86 -> n/a | E33: ='Fuel Price'!$J$86 -> 295851.61 | F33: =IF(ISNUMBER(D33),D33/E33,"n/a") -> n/a | G33: =Assumptions!$E$21 -> 0 | H33: {=INDEX(Assumptions!$B$34:$B$40,MATCH($C33,Assumptions!$A$34:$A$40,0))} -> 0.02 | I33: =IF(ISNUMBER($D33),$D33*(1+$G33)^(I$7-$I$7)*IF($F33>1,(1+($F33-1)*(1-$H33)^(I$7-$I$7))/$F33,1),"n/a") -> n/a | J33: =IF(ISNUMBER($D33),$D33*(1+$G33)^(J$7-$I$7)*IF($F33>1,(1+($F33-1)*(1-$H33)^(J$7-$I$7))/$F33,1),"n/a") -> n/a | K33: =IF(ISNUMBER($D33),$D33*(1+$G33)^(K$7-$I$7)*IF($F33>1,(1+($F33-1)*(1-$H33)^(K$7-$I$7))/$F33,1),"n/a") -> n/a | L33: =IF(ISNUMBER($D33),$D33*(1+$G33)^(L$7-$I$7)*IF($F33>1,(1+($F33-1)*(1-$H33)^(L$7-$I$7))/$F33,1),"n/a") -> n/a | M33: =IF(ISNUMBER($D33),$D33*(1+$G33)^(M$7-$I$7)*IF($F33>1,(1+($F33-1)*(1-$H33)^(M$7-$I$7))/$F33,1),"n/a") -> n/a | N33: =IF(ISNUMBER($D33),$D33*(1+$G33)^(N$7-$I$7)*IF($F33>1,(1+($F33-1)*(1-$H33)^(N$7-$I$7))/$F33,1),"n/a") -> n/a | O33: =IF(ISNUMBER($D33),$D33*(1+$G33)^(O$7-$I$7)*IF($F33>1,(1+($F33-1)*(1-$H33)^(O$7-$I$7))/$F33,1),"n/a") -> n/a | P33: =IF(ISNUMBER($D33),$D33*(1+$G33)^(P$7-$I$7)*IF($F33>1,(1+($F33-1)*(1-$H33)^(P$7-$I$7))/$F33,1),"n/a") -> n/a | ... AK33: =IF(ISNUMBER($D33),$D33*(1+$G33)^(AK$7-$I$7)*IF($F33>1,(1+($F33-1)*(1-$H33)^(AK$7-$I$7))/$F33,1),"n/a") -> n/a
