Workbook
Name gal_per_barrel: About!$A$122
Name toe_to_BTU: About!$A$123

Sheet About
A1: BIFUbC BAU Industrial Fuel Use before CCS
A3: Sources: | B3: National Energy Balance - BEN 2023
B4: Empresa de Pesquisa Energética - official Energy Research Office
B5: all fuels
B6: 2023 edition with data up to 2022
B7: https://www.epe.gov.br/pt/publicacoes-dados-abertos/publicacoes/balanco-energetico-nacional-2023
B8: Area: Brazil, Period: Annual 2023
B10: All Subscripts
B11: Opções de mitigação de emissões de gases de efeito estufa em setores-chave do Brasil
B12: 2017
B13: Ministério da Ciência, Tecnologia, Inovações e Comunicações, ONU Meio Ambiente
B14: http://www.mctic.gov.br/mctic/opencms/ciencia/SEPED/clima/opcoes_mitigacao/Opcoes_de_Mitigacao_de_Emissoes_de_Gases_de_Efeito_Estufa_GEE_em_SetoresChave_do_Brasil.html
B16: BNEF
B17: 2020-2050
B18: https://about.bnef.com/insights/clean-energy/new-energy-outlook/
B20: IEA
B21: 2000-2050
B22: https://www.iea.org/countries/brazil/oil
B24: Ministério de Minas e Energia (MME)
B25: Empresa de Pesquisa Energética (EPE)
B26: Demand Scenarios for the National Energy Plan 2050
B27: 2020-2050
B28: https://www.gov.br/mme/pt-br/assuntos/secretarias/sntep/publicacoes/estudos-do-pne-2050/02-relatorios-epe/06-relatorio-parcial-2-cenarios-de-demanda.pdf
A31: Note:
A32: The words "before CCS" in this variable name indicate that this is the fuel use by industry, excluding
A33: any fuel used to power the energy-intensive process of carbon capture and sequestration. If any CCS
A34: is performed by Industry in the BAU case, this is handled in CCS sector input variables, not here.
A36: BEN and MOP Data Source and Adjustments
A37: Brazil sectorial data is not broke down as EPS requires.
A38: The following table provides how BEN sectors are mapped in to EPS Industry Categories:
B40: BEN sector | C40: EPS Industry Category
B41: REFINARIAS DE PETRÓLEO | C41: refined petroleum and coke 19
B42: PLANTAS DE GÁS NATURAL | C42: refined petroleum and coke 19
B43: COQUERIAS | C43: refined petroleum and coke 19
B44: AGRICULTURE AND LIVESTOCK | C44: agriculture and forestry 01T03
B45: CEMENT | C45: cement and other nonmetallic minerals 239
B46: PIG-IRON AND STEEL | C46: iron and steel 241
B47: IRON-ALLOYS | C47: iron and steel 241
B48: MINING/PELLETIZATION | C48: other mining and quarrying 07T08
B49: NON-FERROUS/ OTHER METALLURGICAL | C49: cement and other nonmetallic minerals 239
...

Sheet BEN sectors
B2: Brazlian Energy Balance 2023 (data up to 2022)
B3: Table 1.5.a – Final Energy Consumption by Sector
B5: IDENTIFICAÇÃO | C5: 2013 | D5: 2014 | E5: 2015 | F5: 2016 | G5: 2017 | H5: 2018 | I5: 2019 | J5: 2020 | K5: 2021 | L5: 2022 | M5: IDENTIFICATION
B6: CONSUMO FINAL | C6: 259166 | D6: 264703 | E6: 260221 | F6: 254784 | G6: 258830 | H6: 257468 | I6: 259042 | J6: 253785 | K6: 263799 | L6: 271317 | M6: FINAL CONSUMPTION
B7: CONSUMO FINAL NÃO-ENERGÉTICO | C7: 16329 | D7: 16009 | E7: 15110 | F7: 14771 | G7: 15048 | H7: 14130 | I7: 14253 | J7: 12563 | K7: 13785 | L7: 15942 | M7: FINAL NON-ENERGY CONSUMPTION
B8: CONSUMO FINAL ENERGÉTICO | C8: 242837 | D8: 248694 | E8: 245110 | F8: 240013 | G8: 243782 | H8: 243338 | I8: 244789 | J8: 241222 | K8: 250014 | L8: 255375 | M8: FINAL ENERGY CONSUMPTION
B9: SETOR ENERGÉTICO | C9: 25079 | D9: 26540 | E9: 26919 | F9: 25419 | G9: 24983 | H9: 27660 | I9: 27718 | J9: 26317 | K9: 24863 | L9: 23496 | M9: ENERGY SECTOR
B10: RESIDENCIAL | C10: 24125 | D10: 25256 | E10: 25438 | F10: 25393 | G10: 26001 | H10: 27063 | I10: 27354 | J10: 28298 | K10: 28577 | L10: 28963 | M10: RESIDENTIAL
B11: COMERCIAL | C11: 8135 | D11: 8714 | E11: 8681 | F11: 8480 | G11: 8564 | H11: 8630 | I11: 8996 | J11: 8061 | K11: 8659 | L11: 9330 | M11: COMMERCIAL
B12: PÚBLICO | C12: 3872 | D12: 3997 | E12: 4048 | F12: 4032 | G12: 4035 | H12: 4204 | I12: 4268 | J12: 3976 | K12: 3968 | L12: 4128 | M12: PUBLIC
B13: AGROPECUÁRIO | C13: 10614 | D13: 11174 | E13: 11452 | F13: 11244 | G13: 12292 | H13: 12348 | I13: 12631 | J13: 13012 | K13: 13143 | L13: 13082 | M13: AGRICULTURE AND LIVESTOCK
B14: TRANSPORTES -TOTAL | C14: 83022 | D14: 86027 | E14: 84203 | F14: 81987 | G14: 82890 | H14: 82189 | I14: 84685 | J14: 79375 | K14: 85187 | L14: 89426 | M14: TRANSPORTATION - TOTAL
B15: RODOVIÁRIO | C15: 76880 | D15: 79798 | E15: 78095 | F15: 76325 | G15: 77109 | H15: 76158 | I15: 78946 | J15: 75086 | K15: 80291 | L15: 83940 | M15: HIGHWAYS
B16: FERROVIÁRIO | C16: 1178 | D16: 1172 | E16: 1143 | F16: 1120 | G16: 1204 | H16: 1317 | I16: 1219 | J16: 1225 | K16: 1213 | L16: 1224 | M16: RAILROADS
... B31: CONSUMO NÃO-IDENTIFICADO | C31: 0 | D31: 0 | E31: 0 | F31: 0 | G31: 0 | H31: 0 | I31: 0 | J31: 0 | K31: 0 | L31: 0 | M31: UNIDENTIFIED CONSUMPTION

Sheet BEN2020
B10: BALANÇO ENERGÉTICO NACIONAL - CONSOLIDADO
B11: 2020 - 10³ tep | C11: 10^3 toe
C12: 3 | D12: =1+C12 -> 4 | E12: =1+D12 -> 5 | F12: =1+E12 -> 6 | G12: =1+F12 -> 7 | H12: =1+G12 -> 8 | I12: =1+H12 -> 9 | J12: =1+I12 -> 10 | K12: =1+J12 -> 11 | ... AB12: =1+AA12 -> 28
B13: CONTA | C13: PETRÓLEO | D13: GÁS NATURAL | E13: CARVÃO VAPOR | F13: CARVÃO METALÚRGICO | G13: URÂNIO U3O8 | H13: ENERGIA HIDRÁULICA | I13: LENHA | J13: PRODUTOS DA CANA | K13: OUTRAS FONTES PRIMÁRIAS | L13: ENERGIA PRIMÁRIA TOTAL | M13: BIODIESEL | N13: ÓLEO DIESEL | O13: ÓLEO COMBUSTÍVEL | P13: GASOLINA | Q13: GLP | R13: NAFTA | S13: QUEROSENE | T13: GÁS DE CIDADE E DE COQUERIA | U13: COQUE DE CARVÃO MINERAL | V13: URÂNIO CONTIDO NO UO2 | W13: ELETRICIDADE | X13: CARVÃO VEGETAL | Y13: ÁLCOOL ETÍLICO ANIDRO E HIDRATADO | Z13: OUTRAS SECUNDÁRIAS DE PETRÓLEO | AA13: PRODUTOS NÃO ENERGÉTICOS DE PETRÓLEO | AB13: ALCATRÃO | AC13: ENERGIA SECUNDÁRIA TOTAL | AD13: TOTAL
B14: PRODUÇÃO | C14: 152634.9 | D14: 46298.913 | E14: 2084.7667 | F14: 0 | G14: 205.82271 | H14: 34088.783 | I14: 26456.694 | J14: 55597.402 | K14: 25171.043 | L14: 342538.33 | M14: 0 | N14: 0 | O14: 0 | P14: 0 | Q14: 0 | R14: 0 | S14: 0 | T14: 0 | U14: 0 | V14: 0 | W14: 0 | X14: 0 | Y14: 0 | Z14: 0 | AA14: 0 | AB14: 0 | AC14: 0 | AD14: 342538.33
B15: IMPORTAÇÃO | C15: 8684.4665 | D15: 8457.8208 | E15: 3897.3721 | F15: 6814.5709 | G15: 4698.8758 | H15: 0 | I15: 0 | J15: 0 | K15: 0 | L15: 32553.106 | M15: 0 | N15: 10171.386 | O15: 37.244526 | P15: 3805.0646 | Q15: 2234.6115 | R15: 2932.03 | S15: 268.53589 | T15: 0 | U15: 936.75256 | V15: 2593.8118 | W15: 2159.7112 | X15: 0 | Y15: 511.4385 | Z15: 2057.1886 | AA15: 1235.5358 | AB15: 0 | AC15: 28943.311 | AD15: 61496.417
B16: VARIAÇÃO DE ESTOQUES | C16: 765.40642 | D16: 0 | E16: 72.400573 | F16: 59.2 | G16: -857.54392 | H16: 0 | I16: 0 | J16: 0 | K16: 0 | L16: 39.463078 | M16: -14.256 | N16: 40.469952 | O16: -65.404251 | P16: 62.726006 | Q16: 14.812473 | R16: -51.984045 | S16: 30.867744 | T16: 0 | U16: 89.834172 | V16: -2914.1532 | W16: 0 | X16: 0 | Y16: -113.12252 | Z16: -50.823302 | AA16: -18.04949 | AB16: 0 | AC16: -2989.0825 | AD16: -2949.6194
B17: OFERTA TOTAL | C17: 162084.78 | D17: 54756.733 | E17: 6054.5394 | F17: 6873.7709 | G17: 4047.1546 | H17: 34088.783 | I17: 26456.694 | J17: 55597.402 | K17: 25171.043 | L17: 375130.9 | M17: -14.256 | N17: 10211.856 | O17: -28.159725 | P17: 3867.7906 | Q17: 2249.424 | R17: 2880.046 | S17: 299.40364 | T17: 0 | U17: 1026.5867 | V17: -320.34137 | W17: 2159.7112 | X17: 0 | Y17: 398.31598 | Z17: 2006.3653 | AA17: 1217.4863 | AB17: 0 | AC17: 25954.229 | AD17: 401085.12
B18: EXPORTAÇÃO | C18: -70885.07 | D18: 0 | E18: 0 | F18: 0 | G18: 0 | H18: 0 | I18: 0 | J18: 0 | K18: 0 | L18: -70885.07 | M18: 0 | N18: -805.92749 | O18: -13883.928 | P18: -1824.3025 | Q18: -0.125255 | R18: -58.902705 | S18: -1135.3571 | T18: 0 | U18: 0 | V18: 0 | W18: -33.98978 | X18: 0 | Y18: -1062.5193 | Z18: -566.65188 | AA18: -381.85078 | AB18: 0 | AC18: -19753.555 | AD18: -90638.625
B19: NÃO-APROVEITADA | C19: 0 | D19: -1224.3687 | E19: 0 | F19: 0 | G19: 0 | H19: 0 | I19: 0 | J19: 0 | K19: 0 | L19: -1224.3687 | M19: 0 | N19: 0 | O19: 0 | P19: 0 | Q19: 0 | R19: 0 | S19: 0 | T19: 0 | U19: 0 | V19: 0 | W19: 0 | X19: 0 | Y19: 0 | Z19: 0 | AA19: 0 | AB19: 0 | AC19: 0 | AD19: -1224.3687
B20: REINJEÇÃO | C20: 0 | D20: -19708.326 | E20: 0 | F20: 0 | G20: 0 | H20: 0 | I20: 0 | J20: 0 | K20: 0 | L20: -19708.326 | M20: 0 | N20: 0 | O20: 0 | P20: 0 | Q20: 0 | R20: 0 | S20: 0 | T20: 0 | U20: 0 | V20: 0 | W20: 0 | X20: 0 | Y20: 0 | Z20: 0 | AA20: 0 | AB20: 0 | AC20: 0 | AD20: -19708.326
B21: OFERTA INTERNA BRUTA | C21: 91199.705 | D21: 33824.039 | E21: 6054.5394 | F21: 6873.7709 | G21: 4047.1546 | H21: 34088.783 | I21: 26456.694 | J21: 55597.402 | K21: 25171.043 | L21: 283313.13 | M21: -14.256 | N21: 9405.9285 | O21: -13912.088 | P21: 2043.4881 | Q21: 2249.2987 | R21: 2821.1433 | S21: -835.95345 | T21: 0 | U21: 1026.5867 | V21: -320.34137 | W21: 2125.7214 | X21: 0 | Y21: -664.20332 | Z21: 1439.7134 | AA21: 835.63551 | AB21: 0 | AC21: 6200.6738 | AD21: 289513.8
B22: TOTAL TRANSFORMAÇÃO | C22: -91051.077 | D22: -18769.498 | E22: -2818.5074 | F22: -6862.6709 | G22: -4047.1546 | H22: -34088.783 | I22: -8733.6754 | J22: -23481.862 | K22: -15897.938 | L22: -205751.17 | M22: 4975.2681 | N22: 33712.964 | O22: 16263.863 | P22: 18131.358 | Q22: 6056.9133 | R22: 1862.7815 | S22: 2743.8985 | T22: 1210.7658 | U22: 5873.4375 | V22: 320.34137 | W22: 54073.68 | X22: 4413.1203 | Y22: 16875.3 | Z22: 7604.2169 | AA22: 6039.003 | AB22: 211.22933 | AC22: 180368.14 | AD22: -25383.026
B23: REFINARIAS DE PETRÓLEO | C23: -89531.484 | D23: 0 | E23: 0 | F23: 0 | G23: 0 | H23: 0 | I23: 0 | J23: 0 | K23: -5965.6982 | L23: -95497.182 | M23: 0 | N23: 35798.423 | O23: 16763.396 | P23: 16714.79 | Q23: 4496.0722 | R23: 4766.3417 | S23: 2743.8985 | T23: 0 | U23: 0 | V23: 0 | W23: 0 | X23: 0 | Y23: 0 | Z23: 7794.715 | AA23: 5274.8341 | AB23: 0 | AC23: 94352.47 | AD23: -1144.7117
B24: PLANTAS DE GÁS NATURAL | C24: 0 | D24: -3763.7604 | E24: 0 | F24: 0 | G24: 0 | H24: 0 | I24: 0 | J24: 0 | K24: 973.60712 | L24: -2790.1533 | M24: 0 | N24: 0 | O24: 0 | P24: 115.5 | Q24: 1463.6022 | R24: 0 | S24: 0 | T24: 0 | U24: 0 | V24: 0 | W24: 0 | X24: 0 | Y24: 0 | Z24: 0 | AA24: 958.92904 | AB24: 0 | AC24: 2538.0313 | AD24: -252.12198
B25: USINAS DE GASEIFICAÇÃO | C25: 0 | D25: 0 | E25: 0 | F25: 0 | G25: 0 | H25: 0 | I25: 0 | J25: 0 | K25: 0 | L25: 0 | M25: 0 | N25: 0 | O25: 0 | P25: 0 | Q25: 0 | R25: 0 | S25: 0 | T25: 0 | U25: 0 | V25: 0 | W25: 0 | X25: 0 | Y25: 0 | Z25: 0 | AA25: 0 | AB25: 0 | AC25: 0 | AD25: 0
... B60: AJUSTES | C60: -148.62785 | D60: -27.579022 | E60: -12.420024 | F60: 0 | G60: 0 | H60: 0 | I60: -2.2555469e-12 | J60: 0 | K60: 8.1432154e-13 | L60: -188.6269 | M60: 12.761063 | N60: -169.14641 | O60: 33.137141 | P60: -8.6368553 | Q60: 51.223641 | R60: -75.175785 | S60: -8.9075274 | T60: 25.42377 | U60: 0 | V60: 0 | W60: 0 | X60: 0 | Y60: -79.09218 | Z60: -251.73183 | AA60: -6.1708465 | AB60: -2.4300562e-14 | AC60: -476.31582 | AD60: -664.94272

Sheet BEN2021
B10: BALANÇO ENERGÉTICO NACIONAL - CONSOLIDADO
B11: 2021 - 10³ tep | C11: 10^3 toe
C12: FONTES DE ENERGIA PRIMÁRIA | M12: FONTES DE ENERGIA SECUNDÁRIA
B13: CONTA | C13: PETRÓLEO | D13: GÁS NATURAL | E13: CARVÃO VAPOR | F13: CARVÃO METALÚRGICO | G13: URÂNIO U3O8 | H13: ENERGIA HIDRÁULICA | I13: LENHA | J13: PRODUTOS DA CANA | K13: OUTRAS FONTES PRIMÁRIAS | L13: ENERGIA PRIMÁRIA TOTAL | M13: BIODIESEL | N13: ÓLEO DIESEL | O13: ÓLEO COMBUSTÍVEL | P13: GASOLINA | Q13: GLP | R13: NAFTA | S13: QUEROSENE | T13: GÁS DE CIDADE E DE COQUERIA | U13: COQUE DE CARVÃO MINERAL | V13: URÂNIO CONTIDO NO UO2 | W13: ELETRICIDADE | X13: CARVÃO VEGETAL | Y13: ÁLCOOL ETÍLICO ANIDRO E HIDRATADO | Z13: OUTRAS SECUNDÁRIAS DE PETRÓLEO | AA13: PRODUTOS NÃO ENERGÉTICOS DE PETRÓLEO | AB13: ALCATRÃO | AC13: ENERGIA SECUNDÁRIA TOTAL | AD13: TOTAL
B14: PRODUÇÃO | C14: 150386.11 | D14: 48462.373 | E14: 2639.6247 | F14: 0 | G14: 342.64919 | H14: 31202.387 | I14: 27406.732 | J14: 49425.409 | K14: 28436.73 | L14: 338302.02 | M14: 0 | N14: 0 | O14: 0 | P14: 0 | Q14: 0 | R14: 0 | S14: 0 | T14: 0 | U14: 0 | V14: 0 | W14: 0 | X14: 0 | Y14: 0 | Z14: 0 | AA14: 0 | AB14: 0 | AC14: 0 | AD14: 338302.02
B15: IMPORTAÇÃO | C15: 7247.0563 | D15: 14833.016 | E15: 5372.347 | F15: 7893.3912 | G15: 4722.7887 | H15: 0 | I15: 0 | J15: 0 | K15: 0 | L15: 40068.599 | M15: 0 | N15: 12242.283 | O15: 595.08748 | P15: 2121.3223 | Q15: 2454.4701 | R15: 6051.8783 | S15: 307.30059 | T15: 0 | U15: 1153.0173 | V15: 3128.7673 | W15: 1990.6326 | X15: 0 | Y15: 230.688 | Z15: 2898.4257 | AA15: 1710.7362 | AB15: 0 | AC15: 34884.609 | AD15: 74953.208
B16: VARIAÇÃO DE ESTOQUES | C16: -308.26462 | D16: 176 | E16: 41.551514 | F16: 59.2 | G16: -786.51308 | H16: 0 | I16: 0 | J16: 0 | K16: 0 | L16: -818.02618 | M16: -14.256 | N16: -7.457312 | O16: -441.61339 | P16: -200.61696 | Q16: -63.834225 | R16: 107.96368 | S16: -53.777706 | T16: 0 | U16: -214.3914 | V16: -3507.2658 | W16: 0 | X16: 0 | Y16: 755.29728 | Z16: -25.281859 | AA16: -8.193238 | AB16: 0 | AC16: -3673.4269 | AD16: -4491.4531
B17: OFERTA TOTAL | C17: 157324.9 | D17: 63471.389 | E17: 8053.5233 | F17: 7952.5912 | G17: 4278.9248 | H17: 31202.387 | I17: 27406.732 | J17: 49425.409 | K17: 28436.73 | L17: 377552.59 | M17: -14.256 | N17: 12234.825 | O17: 153.47409 | P17: 1920.7053 | Q17: 2390.6359 | R17: 6159.842 | S17: 253.52288 | T17: 0 | U17: 938.62589 | V17: -378.49846 | W17: 1990.6326 | X17: 0 | Y17: 985.98528 | Z17: 2873.1439 | AA17: 1702.543 | AB17: 0 | AC17: 31211.182 | AD17: 408763.77
B18: EXPORTAÇÃO | C18: -64722.453 | D18: 0 | E18: 0 | F18: 0 | G18: 0 | H18: 0 | I18: 0 | J18: 0 | K18: 0 | L18: -64722.453 | M18: 0 | N18: -500.53636 | O18: -12237.573 | P18: -1381.822 | Q18: -0.125255 | R18: -230.63297 | S18: -1088.753 | T18: 0 | U18: 0 | V18: 0 | W18: -3.79905 | X18: 0 | Y18: -967.18264 | Z18: -841.03422 | AA18: -385.39723 | AB18: 0 | AC18: -17636.856 | AD18: -82359.309
B19: NÃO-APROVEITADA | C19: 0 | D19: -1220.896 | E19: 0 | F19: 0 | G19: 0 | H19: 0 | I19: 0 | J19: 0 | K19: 0 | L19: -1220.896 | M19: 0 | N19: 0 | O19: 0 | P19: 0 | Q19: 0 | R19: 0 | S19: 0 | T19: 0 | U19: 0 | V19: 0 | W19: 0 | X19: 0 | Y19: 0 | Z19: 0 | AA19: 0 | AB19: 0 | AC19: 0 | AD19: -1220.896
B20: REINJEÇÃO | C20: 0 | D20: -22025.333 | E20: 0 | F20: 0 | G20: 0 | H20: 0 | I20: 0 | J20: 0 | K20: 0 | L20: -22025.333 | M20: 0 | N20: 0 | O20: 0 | P20: 0 | Q20: 0 | R20: 0 | S20: 0 | T20: 0 | U20: 0 | V20: 0 | W20: 0 | X20: 0 | Y20: 0 | Z20: 0 | AA20: 0 | AB20: 0 | AC20: 0 | AD20: -22025.333
B21: OFERTA INTERNA BRUTA | C21: 92602.452 | D21: 40225.16 | E21: 8053.5233 | F21: 7952.5912 | G21: 4278.9248 | H21: 31202.387 | I21: 27406.732 | J21: 49425.409 | K21: 28436.73 | L21: 289583.91 | M21: -14.256 | N21: 11734.289 | O21: -12084.099 | P21: 538.88334 | Q21: 2390.5106 | R21: 5929.209 | S21: -835.23009 | T21: 0 | U21: 938.62589 | V21: -378.49846 | W21: 1986.8336 | X21: 0 | Y21: 18.802638 | Z21: 2032.1096 | AA21: 1317.1458 | AB21: 0 | AC21: 13574.326 | AD21: 303158.23
B22: TOTAL TRANSFORMAÇÃO | C22: -92548.701 | D22: -23366.316 | E22: -4416.4028 | F22: -7941.4912 | G22: -4278.9248 | H22: -31202.387 | I22: -9118.9396 | J22: -21146.698 | K22: -18557.444 | L22: -212577.3 | M22: 5211.1387 | N22: 34559.175 | O22: 14553.887 | P22: 21636.378 | Q22: 5871.5236 | R22: -230.16867 | S22: 3353.4781 | T22: 1433.6054 | U22: 6945.6675 | V22: 378.49846 | W22: 56425.387 | X22: 4632.4834 | Y22: 15525.213 | Z22: 7185.6154 | AA22: 5392.5708 | AB22: 248.93729 | AC22: 183123.39 | AD22: -29453.913
B23: REFINARIAS DE PETRÓLEO | C23: -91825.434 | D23: 0 | E23: 0 | F23: 0 | G23: 0 | H23: 0 | I23: 0 | J23: 0 | K23: -4539.2889 | L23: -96364.723 | M23: 0 | N23: 36339.327 | O23: 16478.873 | P23: 19602.856 | Q23: 4421.8033 | R23: 3558.2238 | S23: 3353.4781 | T23: 0 | U23: 0 | V23: 0 | W23: 0 | X23: 0 | Y23: 0 | Z23: 7521.1503 | AA23: 4705.9953 | AB23: 0 | AC23: 95981.707 | AD23: -383.01633
B24: PLANTAS DE GÁS NATURAL | C24: 0 | D24: -3480.2547 | E24: 0 | F24: 0 | G24: 0 | H24: 0 | I24: 0 | J24: 0 | K24: 889.24396 | L24: -2591.0108 | M24: 0 | N24: 0 | O24: 0 | P24: 115.5 | Q24: 1321.6541 | R24: 0 | S24: 0 | T24: 0 | U24: 0 | V24: 0 | W24: 0 | X24: 0 | Y24: 0 | Z24: 0 | AA24: 919.6136 | AB24: 0 | AC24: 2356.7677 | AD24: -234.24306
B25: USINAS DE GASEIFICAÇÃO | C25: 0 | D25: 0 | E25: 0 | F25: 0 | G25: 0 | H25: 0 | I25: 0 | J25: 0 | K25: 0 | L25: 0 | M25: 0 | N25: 0 | O25: 0 | P25: 0 | Q25: 0 | R25: 0 | S25: 0 | T25: 0 | U25: 0 | V25: 0 | W25: 0 | X25: 0 | Y25: 0 | Z25: 0 | AA25: 0 | AB25: 0 | AC25: 0 | AD25: 0
... B60: AJUSTES | C60: -53.750288 | D60: 55.651742 | E60: -0.49454757 | F60: 0 | G60: 0 | H60: -5.0058588e-12 | I60: -2.2555469e-12 | J60: 0 | K60: 1.1368684e-13 | L60: 1.406907 | M60: 41.923521 | N60: 6.1041845 | O60: 0.43817909 | P60: -38.517982 | Q60: 35.569852 | R60: -148.65128 | S60: 2.084181 | T60: 19.064517 | U60: -1.2551027e-12 | V60: 0 | W60: 0 | X60: 0 | Y60: 63.33603 | Z60: -223.1568 | AA60: -89.320419 | AB60: 0 | AC60: -331.12602 | AD60: -329.71911

Sheet BEN2022
B10: BALANÇO ENERGÉTICO NACIONAL - CONSOLIDADO
B11: 2022 - 10³ tep | C11: 10^3 toe
C12: FONTES DE ENERGIA PRIMÁRIA | M12: FONTES DE ENERGIA SECUNDÁRIA
B13: CONTA | C13: PETRÓLEO | D13: GÁS NATURAL | E13: CARVÃO VAPOR | F13: CARVÃO METALÚRGICO | G13: URÂNIO U3O8 | H13: ENERGIA HIDRÁULICA | I13: LENHA | J13: PRODUTOS DA CANA | K13: OUTRAS FONTES PRIMÁRIAS | L13: ENERGIA PRIMÁRIA TOTAL | M13: BIODIESEL | N13: ÓLEO DIESEL | O13: ÓLEO COMBUSTÍVEL | P13: GASOLINA | Q13: GLP | R13: NAFTA | S13: QUEROSENE | T13: GÁS DE CIDADE E DE COQUERIA | U13: COQUE DE CARVÃO MINERAL | V13: URÂNIO CONTIDO NO UO2 | W13: ELETRICIDADE | X13: CARVÃO VEGETAL | Y13: ÁLCOOL ETÍLICO ANIDRO E HIDRATADO | Z13: OUTRAS SECUNDÁRIAS DE PETRÓLEO | AA13: PRODUTOS NÃO ENERGÉTICOS DE PETRÓLEO | AB13: ALCATRÃO | AC13: ENERGIA SECUNDÁRIA TOTAL | AD13: TOTAL
B14: PRODUÇÃO | C14: 156397.8 | D14: 49970.612 | E14: 2311.0422 | F14: 0 | G14: 516.23987 | H14: 36731.765 | I14: 27283.262 | J14: 47740.204 | K14: 33597.363 | L14: 354548.29 | M14: 0 | N14: 0 | O14: 0 | P14: 0 | Q14: 0 | R14: 0 | S14: 0 | T14: 0 | U14: 0 | V14: 0 | W14: 0 | X14: 0 | Y14: 0 | Z14: 0 | AA14: 0 | AB14: 0 | AC14: 0 | AD14: 354548.29
B15: IMPORTAÇÃO | C15: 12723.559 | D15: 7721.648 | E15: 3257.3705 | F15: 7404.8992 | G15: 3159.6227 | H15: 0 | I15: 0 | J15: 0 | K15: 0 | L15: 34267.1 | M15: 0 | N15: 12198.195 | O15: 201.92891 | P15: 3192.6472 | Q15: 2143.7943 | R15: 6451.2534 | S15: 1063.9434 | T15: 0 | U15: 1081.6614 | V15: 2780.5657 | W15: 1538.255 | X15: 0 | Y15: 52.79925 | Z15: 2941.2847 | AA15: 1533.4537 | AB15: 0 | AC15: 35179.782 | AD15: 69446.882
B16: VARIAÇÃO DE ESTOQUES | C16: -470.11031 | D16: 0 | E16: 55.416528 | F16: 55.536337 | G16: 534.58131 | H16: 0 | I16: 0 | J16: 0 | K16: 0 | L16: 175.42386 | M16: -14.256 | N16: -506.97595 | O16: -566.89139 | P16: -568.26337 | Q16: -37.610716 | R16: -52.104915 | S16: -148.31017 | T16: 0 | U16: -179.53129 | V16: -3129.6143 | W16: 0 | X16: 0 | Y16: 176.01529 | Z16: 27.567821 | AA16: -60.754524 | AB16: 0 | AC16: -5060.7295 | AD16: -4885.3057
B17: OFERTA TOTAL | C17: 168651.25 | D17: 57692.26 | E17: 5623.8292 | F17: 7460.4356 | G17: 4210.4439 | H17: 36731.765 | I17: 27283.262 | J17: 47740.204 | K17: 33597.363 | L17: 388990.81 | M17: -14.256 | N17: 11691.219 | O17: -364.96248 | P17: 2624.3838 | Q17: 2106.1836 | R17: 6399.1485 | S17: 915.6332 | T17: 0 | U17: 902.13016 | V17: -349.0486 | W17: 1538.255 | X17: 0 | Y17: 228.81454 | Z17: 2968.8525 | AA17: 1472.6992 | AB17: 0 | AC17: 30119.052 | AD17: 419109.87
B18: EXPORTAÇÃO | C18: -69579.633 | D18: 0 | E18: 0 | F18: 0 | G18: 0 | H18: 0 | I18: 0 | J18: 0 | K18: 0 | L18: -69579.633 | M18: 0 | N18: -547.37296 | O18: -14592.464 | P18: -420.42385 | Q18: -0.010998 | R18: -379.1363 | S18: -1772.4408 | T18: 0 | U18: 0 | V18: 0 | W18: -428.17287 | X18: 0 | Y18: -1235.1199 | Z18: -820.43784 | AA18: -282.3412 | AB18: 0 | AC18: -20477.921 | AD18: -90057.553
B19: NÃO-APROVEITADA | C19: 0 | D19: -1253.016 | E19: 0 | F19: 0 | G19: 0 | H19: 0 | I19: 0 | J19: 0 | K19: 0 | L19: -1253.016 | M19: 0 | N19: 0 | O19: 0 | P19: 0 | Q19: 0 | R19: 0 | S19: 0 | T19: 0 | U19: 0 | V19: 0 | W19: 0 | X19: 0 | Y19: 0 | Z19: 0 | AA19: 0 | AB19: 0 | AC19: 0 | AD19: -1253.016
B20: REINJEÇÃO | C20: 0 | D20: -24724.806 | E20: 0 | F20: 0 | G20: 0 | H20: 0 | I20: 0 | J20: 0 | K20: 0 | L20: -24724.806 | M20: 0 | N20: 0 | O20: 0 | P20: 0 | Q20: 0 | R20: 0 | S20: 0 | T20: 0 | U20: 0 | V20: 0 | W20: 0 | X20: 0 | Y20: 0 | Z20: 0 | AA20: 0 | AB20: 0 | AC20: 0 | AD20: -24724.806
B21: OFERTA INTERNA BRUTA | C21: 99071.618 | D21: 31714.438 | E21: 5623.8292 | F21: 7460.4356 | G21: 4210.4439 | H21: 36731.765 | I21: 27283.262 | J21: 47740.204 | K21: 33597.363 | L21: 293433.36 | M21: -14.256 | N21: 11143.846 | O21: -14957.426 | P21: 2203.9599 | Q21: 2106.1726 | R21: 6020.0122 | S21: -856.80759 | T21: 0 | U21: 902.13016 | V21: -349.0486 | W21: 1110.0821 | X21: 0 | Y21: -1006.3054 | Z21: 2148.4146 | AA21: 1190.358 | AB21: 0 | AC21: 9641.1318 | AD21: 303074.49
B22: TOTAL TRANSFORMAÇÃO | C22: -98819.22 | D22: -14847.896 | E22: -2034.585 | F22: -7450.0225 | G22: -4210.4439 | H22: -36731.765 | I22: -8843.0098 | J22: -19722.192 | K22: -22828.822 | L22: -215487.96 | M22: 4870.6069 | N22: 37131.809 | O22: 17449.648 | P22: 22078.368 | Q22: 6125.5506 | R22: 982.19155 | S22: 3997.2167 | T22: 1355.7234 | U22: 6515.8266 | V22: 349.0486 | W22: 58236.881 | X22: 4478.7887 | Y22: 16884.884 | Z22: 6557.3799 | AA22: 6227.3261 | AB22: 236.9795 | AC22: 193478.23 | AD22: -22009.728
B23: REFINARIAS DE PETRÓLEO | C23: -97457.483 | D23: 0 | E23: 0 | F23: 0 | G23: 0 | H23: 0 | I23: 0 | J23: 0 | K23: -5691.5138 | L23: -103149 | M23: 0 | N23: 38608.957 | O23: 17724.09 | P23: 20326.04 | Q23: 4702.1656 | R23: 4465.6623 | S23: 3997.2167 | T23: 0 | U23: 0 | V23: 0 | W23: 0 | X23: 0 | Y23: 0 | Z23: 7660.3697 | AA23: 5378.5193 | AB23: 0 | AC23: 102863.02 | AD23: -285.97609
B24: PLANTAS DE GÁS NATURAL | C24: 0 | D24: -3713.6618 | E24: 0 | F24: 0 | G24: 0 | H24: 0 | I24: 0 | J24: 0 | K24: 1000.7849 | L24: -2712.877 | M24: 0 | N24: 0 | O24: 0 | P24: 0 | Q24: 1304.1844 | R24: 0 | S24: 0 | T24: 0 | U24: 0 | V24: 0 | W24: 0 | X24: 0 | Y24: 0 | Z24: 0 | AA24: 1033.6279 | AB24: 0 | AC24: 2337.8123 | AD24: -375.06473
B25: USINAS DE GASEIFICAÇÃO | C25: 0 | D25: 0 | E25: 0 | F25: 0 | G25: 0 | H25: 0 | I25: 0 | J25: 0 | K25: 0 | L25: 0 | M25: 0 | N25: 0 | O25: 0 | P25: 0 | Q25: 0 | R25: 0 | S25: 0 | T25: 0 | U25: 0 | V25: 0 | W25: 0 | X25: 0 | Y25: 0 | Z25: 0 | AA25: 0 | AB25: 0 | AC25: 0 | AD25: 0
... B60: AJUSTES | C60: -252.39892 | D60: 388.91526 | E60: -4.834647 | F60: 0.68693674 | G60: 0 | H60: 0 | I60: 0 | J60: 0 | K60: 3.9790393e-13 | L60: 132.36863 | M60: 46.750165 | N60: -87.507444 | O60: -61.701538 | P60: -55.325073 | Q60: -20.251962 | R60: -43.164972 | S60: -6.9063503 | T60: 1.5815108 | U60: -4.8034416 | V60: 0 | W60: 0 | X60: 0 | Y60: -0.02856 | Z60: -125.58227 | AA60: -209.8125 | AB60: -1.71 | AC60: -568.46243 | AD60: -436.09381

Sheet Iron and steel
B2: Iron and steel sector
B3: Sectoral modeling of low carbon options for pig iron and steel
B4: Figure 17
A29: 10^6toe | B29: 2010 | C29: 2015 | D29: 2020 | E29: 2025 | F29: 2030 | G29: 2035 | H29: 2040 | I29: 2045 | J29: 2050
B30: 16.293823 | C30: 17.429048 | D30: 19.232053 | E30: 21.691708 | F30: 24.151363 | G30: 26.611018 | H30: 29.070673 | I30: 31.530328 | J30: 33.989983
B31: 14.357262 | C31: 15.225376 | D31: 16.828047 | E31: 18.987201 | F31: 21.146355 | G31: 23.305509 | H31: 25.464663 | I31: 27.623817 | J31: 29.782972
B32: 12.687813 | C32: 13.489149 | D32: 14.824708 | E32: 16.72788 | F32: 18.631052 | G32: 20.534224 | H32: 22.437396 | I32: 24.340568 | J32: 26.24374
B33: 11.686144 | C33: 12.554257 | D33: 13.823038 | E33: 15.592654 | F33: 17.36227 | G33: 19.131886 | H33: 20.901503 | I33: 22.671119 | J33: 24.440735
B34: 11.48581 | C34: 12.287145 | D34: 13.489149 | E34: 15.236505 | F34: 16.983862 | G34: 18.731219 | H34: 20.478575 | I34: 22.225932 | J34: 23.973289
B35: 10.083472 | C35: 10.684474 | D35: 11.819699 | E35: 13.333333 | F35: 14.846967 | G35: 16.360601 | H35: 17.874235 | I35: 19.387869 | J35: 20.901503
B36: 7.1452421 | C36: 7.5459098 | D36: 8.2136895 | E36: 9.3043962 | F36: 10.395103 | G36: 11.48581 | H36: 12.576516 | I36: 13.667223 | J36: 14.75793
A39: 1000 toe | B39: 2010 | C39: 2015 | D39: 2020 | E39: 2025 | F39: 2030 | G39: 2035 | H39: 2040 | I39: 2045 | J39: 2050
A40: coal | B40: =(B30-B31)*1000 -> 1936.5609 | C40: =(C30-C31)*1000 -> 2203.6728 | D40: =(D30-D31)*1000 -> 2404.0067 | E40: =(E30-E31)*1000 -> 2704.5075 | F40: =(F30-F31)*1000 -> 3005.0083 | G40: =(G30-G31)*1000 -> 3305.5092 | H40: =(H30-H31)*1000 -> 3606.01 | I40: =(I30-I31)*1000 -> 3906.5109 | J40: =(J30-J31)*1000 -> 4207.0117
A41: coke oven gas | B41: =(B31-B32)*1000 -> 1669.4491 | C41: =(C31-C32)*1000 -> 1736.227 | D41: =(D31-D32)*1000 -> 2003.3389 | E41: =(E31-E32)*1000 -> 2259.3211 | F41: =(F31-F32)*1000 -> 2515.3033 | G41: =(G31-G32)*1000 -> 2771.2855 | H41: =(H31-H32)*1000 -> 3027.2677 | I41: =(I31-I32)*1000 -> 3283.2499 | J41: =(J31-J32)*1000 -> 3539.2321
A42: natural gas | B42: =(B32-B33)*1000 -> 1001.6694 | C42: =(C32-C33)*1000 -> 934.89149 | D42: =(D32-D33)*1000 -> 1001.6694 | E42: =(E32-E33)*1000 -> 1135.2254 | F42: =(F32-F33)*1000 -> 1268.7813 | G42: =(G32-G33)*1000 -> 1402.3372 | H42: =(H32-H33)*1000 -> 1535.8932 | I42: =(I32-I33)*1000 -> 1669.4491 | J42: =(J32-J33)*1000 -> 1803.005
A43: heavy oil | B43: =(B33-B34)*1000 -> 200.33389 | C43: =(C33-C34)*1000 -> 267.11185 | D43: =(D33-D34)*1000 -> 333.88982 | E43: =(E33-E34)*1000 -> 356.14914 | F43: =(F33-F34)*1000 -> 378.40846 | G43: =(G33-G34)*1000 -> 400.66778 | H43: =(H33-H34)*1000 -> 422.9271 | I43: =(I33-I34)*1000 -> 445.18642 | J43: =(J33-J34)*1000 -> 467.44574
A44: electricity | B44: =(B34-B35)*1000 -> 1402.3372 | C44: =(C34-C35)*1000 -> 1602.6711 | D44: =(D34-D35)*1000 -> 1669.4491 | E44: =(E34-E35)*1000 -> 1903.172 | F44: =(F34-F35)*1000 -> 2136.8948 | G44: =(G34-G35)*1000 -> 2370.6177 | H44: =(H34-H35)*1000 -> 2604.3406 | I44: =(I34-I35)*1000 -> 2838.0634 | J44: =(J34-J35)*1000 -> 3071.7863
A45: charcoal | B45: =(B35-B36)*1000 -> 2938.2304 | C45: =(C35-C36)*1000 -> 3138.5643 | D45: =(D35-D36)*1000 -> 3606.01 | E45: =(E35-E36)*1000 -> 4028.9371 | F45: =(F35-F36)*1000 -> 4451.8642 | G45: =(G35-G36)*1000 -> 4874.7913 | H45: =(H35-H36)*1000 -> 5297.7184 | I45: =(I35-I36)*1000 -> 5720.6455 | J45: =(J35-J36)*1000 -> 6143.5726
A46: coke | B46: =(B36-B37)*1000 -> 7145.2421 | C46: =(C36-C37)*1000 -> 7545.9098 | D46: =(D36-D37)*1000 -> 8213.6895 | E46: =(E36-E37)*1000 -> 9304.3962 | F46: =(F36-F37)*1000 -> 10395.103 | G46: =(G36-G37)*1000 -> 11485.81 | H46: =(H36-H37)*1000 -> 12576.516 | I46: =(I36-I37)*1000 -> 13667.223 | J46: =(J36-J37)*1000 -> 14757.93

Sheet Agriculture
B2: Agriculture
B3: Sectoral modeling of low carbon options for the agriculture, forestry and other land use sector (AFOLU)
B4: Figure 45
L10: 2010 | M10: 2011 | N10: 2012 | O10: 2013 | P10: 2050
L11: 401612.9 | M11: 420967.74 | N11: 417741.94 | O11: 454838.71 | P11: 732258.06
L12: 332258.06 | M12: 345161.29 | N12: 345161.29 | O12: 383870.97 | P12: 600000
L13: 219354.84 | M13: 232258.06 | N13: 229032.26 | O13: 250000 | P13: 329032.26
L14: 0 | M14: 0 | N14: 0 | O14: 0 | P14: 0
A24: TJ | B24: 2010 | C24: 2011 | D24: 2012 | E24: 2013 | F24: 2014 | G24: 2015 | H24: 2016 | I24: 2017 | J24: 2018 | K24: 2019 | L24: 2020 | M24: 2021 | N24: 2022 | O24: 2023 | P24: 2024 | Q24: 2025 | R24: 2026 | S24: 2027 | T24: 2028 | U24: 2029 | V24: 2030 | W24: 2031 | X24: 2032 | Y24: 2033 | Z24: 2034 | AA24: 2035 | AB24: 2036 | AC24: 2037 | AD24: 2038 | AE24: 2039 | AF24: 2040 | AG24: 2041 | AH24: 2042 | AI24: 2043 | AJ24: 2044 | AK24: 2045 | AL24: 2046 | AM24: 2047 | AN24: 2048 | AO24: 2049 | AP24: 2050
A25: electricity | B25: =L11-L12 -> 69354.839 | C25: =M11-M12 -> 75806.452 | D25: =N11-N12 -> 72580.645 | E25: =O11-O12 -> 70967.742 | F25: =$E25+(F24-$E$24)*($AP25-$E25)/($AP$24-$E$24) -> 72624.237 | G25: =$E25+(G24-$E$24)*($AP25-$E25)/($AP$24-$E$24) -> 74280.732 | H25: =$E25+(H24-$E$24)*($AP25-$E25)/($AP$24-$E$24) -> 75937.228 | I25: =$E25+(I24-$E$24)*($AP25-$E25)/($AP$24-$E$24) -> 77593.723 | J25: =$E25+(J24-$E$24)*($AP25-$E25)/($AP$24-$E$24) -> 79250.218 | K25: =$E25+(K24-$E$24)*($AP25-$E25)/($AP$24-$E$24) -> 80906.713 | L25: =$E25+(L24-$E$24)*($AP25-$E25)/($AP$24-$E$24) -> 82563.208 | M25: =$E25+(M24-$E$24)*($AP25-$E25)/($AP$24-$E$24) -> 84219.704 | ... AO25: =$E25+(AO24-$E$24)*($AP25-$E25)/($AP$24-$E$24) -> 130601.57 | AP25: =P11-P12 -> 132258.06
A26: firewood | B26: =L12-L13 -> 112903.23 | C26: =M12-M13 -> 112903.23 | D26: =N12-N13 -> 116129.03 | E26: 133870.97 | F26: =$E26+(F$24-$E$24)*($AP26-$E26)/($AP$24-$E$24) -> 137576.29 | G26: =$E26+(G$24-$E$24)*($AP26-$E26)/($AP$24-$E$24) -> 141281.6 | H26: =$E26+(H$24-$E$24)*($AP26-$E26)/($AP$24-$E$24) -> 144986.92 | I26: =$E26+(I$24-$E$24)*($AP26-$E26)/($AP$24-$E$24) -> 148692.24 | J26: =$E26+(J$24-$E$24)*($AP26-$E26)/($AP$24-$E$24) -> 152397.56 | K26: =$E26+(K$24-$E$24)*($AP26-$E26)/($AP$24-$E$24) -> 156102.88 | L26: =$E26+(L$24-$E$24)*($AP26-$E26)/($AP$24-$E$24) -> 159808.2 | M26: =$E26+(M$24-$E$24)*($AP26-$E26)/($AP$24-$E$24) -> 163513.51 | ... AO26: =$E26+(AO$24-$E$24)*($AP26-$E26)/($AP$24-$E$24) -> 267262.42 | AP26: =P12-P13 -> 270967.74
A27: diesel | B27: =L13-L14 -> 219354.84 | C27: =M13-M14 -> 232258.06 | D27: =N13-N14 -> 229032.26 | E27: 250000 | F27: =$E27+(F$24-$E$24)*($AP27-$E27)/($AP$24-$E$24) -> 252136.01 | G27: =$E27+(G$24-$E$24)*($AP27-$E27)/($AP$24-$E$24) -> 254272.01 | H27: =$E27+(H$24-$E$24)*($AP27-$E27)/($AP$24-$E$24) -> 256408.02 | I27: =$E27+(I$24-$E$24)*($AP27-$E27)/($AP$24-$E$24) -> 258544.03 | J27: =$E27+(J$24-$E$24)*($AP27-$E27)/($AP$24-$E$24) -> 260680.03 | K27: =$E27+(K$24-$E$24)*($AP27-$E27)/($AP$24-$E$24) -> 262816.04 | L27: =$E27+(L$24-$E$24)*($AP27-$E27)/($AP$24-$E$24) -> 264952.05 | M27: =$E27+(M$24-$E$24)*($AP27-$E27)/($AP$24-$E$24) -> 267088.06 | ... AO27: =$E27+(AO$24-$E$24)*($AP27-$E27)/($AP$24-$E$24) -> 326896.25 | AP27: =P13 -> 329032.26
A29: 1000 toe | B29: 2010 | C29: 2011 | D29: 2012 | E29: 2013 | F29: 2014 | G29: 2015 | H29: 2016 | I29: 2017 | J29: 2018 | K29: 2019 | L29: 2020 | M29: 2021 | N29: 2022 | O29: 2023 | P29: 2024 | Q29: 2025 | R29: 2026 | S29: 2027 | T29: 2028 | U29: 2029 | V29: 2030 | W29: 2031 | X29: 2032 | Y29: 2033 | Z29: 2034 | AA29: 2035 | AB29: 2036 | AC29: 2037 | AD29: 2038 | AE29: 2039 | AF29: 2040 | AG29: 2041 | AH29: 2042 | AI29: 2043 | AJ29: 2044 | AK29: 2045 | AL29: 2046 | AM29: 2047 | AN29: 2048 | AO29: 2049 | AP29: 2050
A30: electricity | B30: =B25*$B$34/1000 -> 1656.5403 | C30: =C25*$B$34/1000 -> 1810.6371 | D30: =D25*$B$34/1000 -> 1733.5887 | E30: =E25*$B$34/1000 -> 1695.0645 | F30: =F25*$B$34/1000 -> 1734.6299 | G30: =G25*$B$34/1000 -> 1774.1953 | H30: =H25*$B$34/1000 -> 1813.7607 | I30: =I25*$B$34/1000 -> 1853.3261 | ... AP30: =AP25*$B$34/1000 -> 3158.9839
A31: firewood | B31: =B26*$B$34/1000 -> 2696.6935 | C31: =C26*$B$34/1000 -> 2696.6935 | D31: =D26*$B$34/1000 -> 2773.7419 | E31: =E26*$B$34/1000 -> 3197.5081 | F31: =F26*$B$34/1000 -> 3286.0096 | G31: =G26*$B$34/1000 -> 3374.5111 | H31: =H26*$B$34/1000 -> 3463.0126 | I31: =I26*$B$34/1000 -> 3551.5142 | ... AP31: =AP26*$B$34/1000 -> 6472.0645
A32: diesel | B32: =B27*$B$34/1000 -> 5239.2903 | C32: =C27*$B$34/1000 -> 5547.4839 | D32: =D27*$B$34/1000 -> 5470.4355 | E32: =E27*$B$34/1000 -> 5971.25 | F32: =F27*$B$34/1000 -> 6022.2685 | G32: =G27*$B$34/1000 -> 6073.2871 | H32: =H27*$B$34/1000 -> 6124.3056 | I32: =I27*$B$34/1000 -> 6175.3241 | ... AP32: =AP27*$B$34/1000 -> 7858.9355
A34: TJ to toe= | B34: 23.885

Sheet Chemicals
B2: Chemicals
B3: SIRENE | D3: Mitigation Options of Greenhouse Gas Emissions in Key Sectors in Brazil (MOP) | N3: https://sirene.mctic.gov.br/portal/opencms/paineis/2018/08/24/Opcoes_de_Mitigacao_de_Emissoes_de_Gases_de_Efeito_Estufa.html
A5: ktoe | D5: 2015; | E5: 2020; | F5: 2025; | G5: 2030; | H5: 2035; | I5: 2040; | J5: 2045; | K5: 2050;
A6: Total | B6: ktoe | C6: BAU | D6: 9800 | E6: 10700 | F6: 12200 | G6: 14200 | H6: 16200 | I6: 17700 | J6: 19100 | K6: 19900
A7: Electricity | B7: ktoe | C7: BAU | D7: 1700 | E7: 1800 | F7: 1900 | G7: 2300 | H7: 2600 | I7: 2800 | J7: 3000 | K7: 3300
A8: Natural Gas | B8: ktoe | C8: BAU | D8: 3900 | E8: 4900 | F8: 5800 | G8: 6700 | H8: 7400 | I8: 8300 | J8: 8700 | K8: 8900
A9: LPG | B9: ktoe | C9: BAU | D9: 0 | E9: 0 | F9: 0 | G9: 0 | H9: 0 | I9: 0 | J9: 0 | K9: 0
A10: Fuel Oil | B10: ktoe | C10: BAU | D10: 800 | E10: 1100 | F10: 1200 | G10: 1300 | H10: 1400 | I10: 1400 | J10: 1400 | K10: 1300
A11: Diesel | B11: ktoe | C11: BAU | D11: 0 | E11: 0 | F11: 0 | G11: 0 | H11: 0 | I11: 0 | J11: 0 | K11: 0
A12: Coke | B12: ktoe | C12: BAU | D12: 3100 | E12: 2700 | F12: 3000 | G12: 3500 | H12: 4200 | I12: 4800 | J12: 5400 | K12: 5700
A13: Charcoal | B13: ktoe | C13: BAU | D13: 0 | E13: 0 | F13: 0 | G13: 0 | H13: 0 | I13: 0 | J13: 0 | K13: 0
A14: Coal | B14: ktoe | C14: BAU | D14: 0 | E14: 0 | F14: 0 | G14: 0 | H14: 0 | I14: 0 | J14: 0 | K14: 0
A15: Biomass | B15: ktoe | C15: BAU | D15: 300 | E15: 300 | F15: 400 | G15: 400 | H15: 500 | I15: 500 | J15: 500 | K15: 700
A17: INDUSTRIAL SECTOR - CHEMICAL | F17: 10³ tep(toe)
A18: SOURCES | B18: 2015 | C18: 2016 | D18: 2017 | E18: 2018 | F18: 2019
A19: NATURAL GAS | B19: 2222.3101 | C19: 2197.9106 | D19: 2162.6602 | E19: 2422.2817 | F19: 1941.0024
A20: STEAM COAL | B20: 171.92038 | C20: 125.76592 | D20: 149.10934 | E20: 190.32746 | F20: 137.5116
A21: FIREWOOD | B21: 47.85687 | C21: 42.966 | D21: 46.891728 | E21: 46.148436 | F21: 44.145416
A22: SUGAR CANE BAGASSE AND OTHER WASTES | B22: 84.55 | C22: 80.75 | D22: 80.933864 | E22: 79.650962 | F22: 76.193803
A23: DIESEL OIL | B23: 16.834623 | C23: 15.15679 | D23: 16.774557 | E23: 16.096842 | F23: 15.061172
A24: BIODIESEL | B24: 1.1834442 | C24: 1.0654956 | D24: 1.3204166 | E24: 1.6155606 | F24: 1.6219787
A25: FUEL OIL | B25: 206.60502 | C25: 325.97885 | D25: 132.99855 | E25: 90.851907 | F25: 87.105657
A26: LIQUEFIED PETROLEUM GAS | B26: 214.73128 | C26: 184.91954 | D26: 210.78633 | E26: 202.50523 | F26: 191.11229
A27: NAPHTHA | B27: 0 | C27: 0 | D27: 0 | E27: 0 | F27: 0
A28: KEROSENE | B28: 0 | C28: 0 | D28: 0 | E28: 0 | F28: 0
A29: GASWORKS GAS | B29: 0 | C29: 0 | D29: 0 | E29: 0 | F29: 0
... A33: TOTAL | B33: 6874.0795 | C33: 6742.6419 | D33: 7018.0585 | E33: 6909.3598 | F33: 6669.4033
A35: Electricity | B35: =B30 -> 1939.5773 | C35: =C30 -> 1900.0065 | D35: =D30 -> 1904.3328
A36: Coal | B36: =B20 -> 171.92038 | C36: =C20 -> 125.76592 | D36: =D20 -> 149.10934
A37: Natural Gas | B37: =B19 -> 2222.3101 | C37: =C19 -> 2197.9106 | D37: =D19 -> 2162.6602
A38: Biomass | B38: =B21+B24+B22+B31 -> 151.85919 | C38: =C21+C24+C22+C31 -> 141.60334 | D38: =D21+D24+D22+D31 -> 146.00615
A39: Petroleum Diesel | B39: =B32+B23 -> 1967.0762 | C39: =C32+C23 -> 1866.4571 | D39: =D32+D23 -> 2312.1652
A40: Heat | B40: 0 | C40: 0 | D40: 0
A41: Crude Oil | B41: 0 | C41: 0 | D41: 0
A42: Heavy or residual oil | B42: =B25 -> 206.60502 | C42: =C25 -> 325.97885 | D42: =D25 -> 132.99855
A43: LPG propane or butane | B43: =B26 -> 214.73128 | C43: =C26 -> 184.91954 | D43: =D26 -> 210.78633
A44: hydrogen | B44: 0 | C44: 0 | D44: 0
B45: =SUM(B35:B44) -> 6874.0795 | C45: =SUM(C35:C44) -> 6742.6419 | D45: =SUM(D35:D44) -> 7018.0585

Sheet O&G systems
B2: O&G systems
B3: Sectoral modeling of low carbon options for the oil and natural gas sector
A4: E&P
B6: Emission factor natural gas(tCO2/TJ)= | E6: 56.1
B7: TJ to toe= | E7: 23.8846
A9: post salt | B9: emissions (MtCO2) | C9: 2010 | D9: 2015 | E9: 2020 | F9: 2025 | G9: 2030 | H9: 2035 | I9: 2040 | J9: 2045 | K9: 2050
B10: self-consumption | C10: 9.4213569 | D10: 9.6136294 | E10: 13.343718 | F10: 15.227989 | G10: 15.074171 | H10: 12.959172 | I10: 9.8828111 | J10: 6.8449042 | K10: 4.4222695 | M10: Table 14
B11: exploration | C11: 7.3716155 | D11: 7.5220566 | E11: 10.440615 | F11: 11.914938 | G11: 11.794585 | H11: 10.139732 | I11: 7.7326742 | J11: 5.3557043 | K11: 3.460146 | M11: Model assumptions on %CO2 for each stage
B13: natural gas (1000toe) | C13: =SUM(C10:C11)*10^3*$E$7/$E$6 -> 7149.6154 | D13: =SUM(D10:D11)*10^3*$E$7/$E$6 -> 7295.526 | E13: =SUM(E10:E11)*10^3*$E$7/$E$6 -> 10126.19 | F13: =SUM(F10:F11)*10^3*$E$7/$E$6 -> 11556.113 | G13: =SUM(G10:G11)*10^3*$E$7/$E$6 -> 11439.385 | H13: =SUM(H10:H11)*10^3*$E$7/$E$6 -> 9834.369 | I13: =SUM(I10:I11)*10^3*$E$7/$E$6 -> 7499.8007 | J13: =SUM(J10:J11)*10^3*$E$7/$E$6 -> 5194.4145 | K13: =SUM(K10:K11)*10^3*$E$7/$E$6 -> 3355.9419
A17: pre salt | B17: emissions (MtCO2) | C17: 2010 | D17: 2015 | E17: 2020 | F17: 2025 | G17: 2030 | H17: 2035 | I17: 2040 | J17: 2045 | K17: 2050 | M17: Table 14
A18: 10% mol CO2 | B18: self-consumption | C18: 0.19333129 | D18: 2.3586418 | E18: 4.0212909 | F18: 6.3412664 | G18: 9.5118997 | H18: 13.146528 | I18: 16.239829 | J18: 17.554481 | K18: 16.43316 | M18: Model assumptions on %CO2 for each stage
B19: exploration | C19: 0.1512695 | D19: 1.8454879 | E19: 3.1464056 | F19: 4.9616396 | G19: 7.4424595 | H19: 10.286326 | I19: 12.706638 | J19: 13.735271 | K19: 12.857908
B21: natural gas (1000toe) | C21: =SUM(C18:C19)*10^3*$E$7/$E$6 -> 146.71394 | D21: =SUM(D18:D19)*10^3*$E$7/$E$6 -> 1789.9101 | E21: =SUM(E18:E19)*10^3*$E$7/$E$6 -> 3051.65 | F21: =SUM(F18:F19)*10^3*$E$7/$E$6 -> 4812.2173 | G21: =SUM(G18:G19)*10^3*$E$7/$E$6 -> 7218.326 | H21: =SUM(H18:H19)*10^3*$E$7/$E$6 -> 9976.5481 | I21: =SUM(I18:I19)*10^3*$E$7/$E$6 -> 12323.971 | J21: =SUM(J18:J19)*10^3*$E$7/$E$6 -> 13321.626 | K21: =SUM(K18:K19)*10^3*$E$7/$E$6 -> 12470.685
A23: 45% mol CO2 | B23: self-consumption | C23: 0.19713038 | D23: 2.4049906 | E23: 4.1003119 | F23: 6.4658765 | G23: 9.6988147 | H23: 13.404866 | I23: 16.558952 | J23: 17.899439 | K23: 16.756082
B24: exploration | C24: 0.15424205 | D24: 1.881753 | E24: 3.2082346 | F24: 5.0591391 | G24: 7.5887087 | H24: 10.488459 | I24: 12.956332 | J24: 14.005178 | K24: 13.110574
B26: natural gas (1000toe) | C26: =SUM(C23:C24)*10^3*$E$7/$E$6 -> 149.59697 | D26: =SUM(D23:D24)*10^3*$E$7/$E$6 -> 1825.083 | E26: =SUM(E23:E24)*10^3*$E$7/$E$6 -> 3111.6169 | F26: =SUM(F23:F24)*10^3*$E$7/$E$6 -> 4906.7805 | G26: =SUM(G23:G24)*10^3*$E$7/$E$6 -> 7360.1708 | H26: =SUM(H23:H24)*10^3*$E$7/$E$6 -> 10172.594 | I26: =SUM(I23:I24)*10^3*$E$7/$E$6 -> 12566.145 | J26: =SUM(J23:J24)*10^3*$E$7/$E$6 -> 13583.405 | K26: =SUM(K23:K24)*10^3*$E$7/$E$6 -> 12715.742 | P26: =9000000*23.88/56.1/1000 -> 3831.016
A28: Average | B28: natural gas (1000toe) | C28: =(C21+C26)/2 -> 148.15545 | D28: =(D21+D26)/2 -> 1807.4965 | E28: =(E21+E26)/2 -> 3081.6335 | F28: =(F21+F26)/2 -> 4859.4989 | G28: =(G21+G26)/2 -> 7289.2484 | H28: =(H21+H26)/2 -> 10074.571 | I28: =(I21+I26)/2 -> 12445.058 | J28: =(J21+J26)/2 -> 13452.515 | K28: =(K21+K26)/2 -> 12593.214
A32: shale and natural gas
B33: emissions (MtCO2) | C33: 2010 | D33: 2015 | E33: 2020 | F33: 2025 | G33: 2030 | H33: 2035 | I33: 2040 | J33: 2045 | K33: 2050 | M33: Table 14
B34: self-consumption | C34: 0 | D34: 0 | E34: 0 | F34: 0.13892617 | G34: 0.64832215 | H34: 0.64832215 | I34: 0.64832215 | J34: 0.64832215 | K34: 0.64832215 | M34: Model assumptions on %CO2 for each stage
B36: natural gas (1000toe) | C36: =C34*10^3*$E$7/$E$6 -> 0 | D36: =D34*10^3*$E$7/$E$6 -> 0 | E36: =E34*10^3*$E$7/$E$6 -> 0 | F36: =F34*10^3*$E$7/$E$6 -> 59.147881 | G36: =G34*10^3*$E$7/$E$6 -> 276.02344 | H36: =H34*10^3*$E$7/$E$6 -> 276.02344 | I36: =I34*10^3*$E$7/$E$6 -> 276.02344 | J36: =J34*10^3*$E$7/$E$6 -> 276.02344 | K36: =K34*10^3*$E$7/$E$6 -> 276.02344
B38: total E&P
B39: natural gas (1000toe) | C39: =SUM(C13,C28,C36) -> 7297.7709 | D39: =SUM(D13,D28,D36) -> 9103.0225 | E39: =SUM(E13,E28,E36) -> 13207.823 | F39: =SUM(F13,F28,F36) -> 16474.76 | G39: =SUM(G13,G28,G36) -> 19004.657 | H39: =SUM(H13,H28,H36) -> 20184.963 | I39: =SUM(I13,I28,I36) -> 20220.882 | J39: =SUM(J13,J28,J36) -> 18922.953 | K39: =SUM(K13,K28,K36) -> 16225.179
A41: Refineries
G44: 2010 | H44: 2015 | I44: 2020 | J44: 2025 | K44: 2030 | L44: 2035 | M44: 2040 | N44: 2045 | O44: 2050
B45: natural gas
B46: total consumption | E46: Mm3 | G46: 2944 | H46: 7123.5 | I46: 11303 | J46: 12825.65 | K46: 14348.3 | L46: 15615.25 | M46: 16882.2 | N46: 16868.85 | O46: 16855.5 | P46: (Table 78)
B47: h2 production consumption | E47: Mm3 | G47: 502.3 | H47: 818 | I47: 1133.7 | J47: 1224.7 | K47: 1315.7 | L47: 1663 | M47: 2010.3 | N47: 2010.3 | O47: 2010.3 | P47: (Table 76)
B48: consumption for energy purpose | E48: Mm3 | G48: =G46-G47 -> 2441.7 | H48: =H46-H47 -> 6305.5 | I48: =I46-I47 -> 10169.3 | J48: =J46-J47 -> 11600.95 | K48: =K46-K47 -> 13032.6 | L48: =L46-L47 -> 13952.25 | M48: =M46-M47 -> 14871.9 | N48: =N46-N47 -> 14858.55 | O48: =O46-O47 -> 14845.2
B50: Heavy or residual oil | E50: PJ | G50: 47.7 | H50: 23.85 | I50: 0 | J50: 0 | K50: 0 | L50: 0 | M50: 0 | N50: 0 | O50: 0
B51: LPG propane or butane | E51: PJ | G51: 89.3 | H51: 101.65 | I51: 114 | J51: 128.35 | K51: 142.7 | L51: 146.85 | M51: 151 | N51: 150.7 | O51: 150.4
B53: electricity* | E53: GWh | G53: 0 | H53: 153.5 | I53: 307 | J53: 1218.25 | K53: 2129.5 | L53: 2344.15 | M53: 2558.8 | N53: 2555.45 | O53: 2552.1
B54: *grid consumption | D54: 1000 | E54: toe | G54: =G53*$D$60/1000 -> 0 | H54: =H53*$D$60/1000 -> 13.198621 | I54: =I53*$D$60/1000 -> 26.397241 | J54: =J53*$D$60/1000 -> 104.75062 | K54: =K53*$D$60/1000 -> 183.10399 | L54: =L53*$D$60/1000 -> 201.56057 | M54: =M53*$D$60/1000 -> 220.01714 | N54: =N53*$D$60/1000 -> 219.72909 | O54: =O53*$D$60/1000 -> 219.44104
B59: Conversion factors
B60: GWh to toe= | D60: 85.9845
B61: Mm3 (NG) to toe= | D61: =10^6/1110 -> 900.9009
B62: PJ to toe= | D62: 23884.6
A65: Total O&G
B66: 1000 toe | C66: 2010 | D66: 2015 | E66: 2020 | F66: 2025 | G66: 2030 | H66: 2035 | I66: 2040 | J66: 2045 | K66: 2050
B67: natural gas | C67: =C39+G46*$D$61/1000 -> 9950.0232 | D67: =D39+H46*$D$61/1000 -> 15520.59 | E67: =E39+I46*$D$61/1000 -> 23390.706 | F67: =F39+J46*$D$61/1000 -> 28029.4 | G67: =G39+K46*$D$61/1000 -> 31931.053 | H67: =H39+L46*$D$61/1000 -> 34252.756 | I67: =I39+M46*$D$61/1000 -> 35430.072 | J67: =J39+N46*$D$61/1000 -> 34120.115 | K67: =K39+O46*$D$61/1000 -> 31410.314
...

Sheet Non-ferrous metallurgy
B2: Non-ferrous metallurgy
B3: Sectoral modeling of low carbon options for the non-ferrous metallurgy sector
B4: Table 28
B5: 2010 | C5: 2015 | D5: 2020 | E5: 2025 | F5: 2030 | G5: 2035 | H5: 2040 | I5: 2045 | J5: 2050
A6: 1000 toe | B6: 6381 | C6: 5536 | D6: 5756 | E6: 6221 | F6: 6696 | G6: 7163 | H6: 7620 | I6: 8062 | J6: 8486
B8: Fuel shares (collected directly from the model)
B9: 2010 | C9: 2015 | D9: 2020 | E9: 2025 | F9: 2030 | G9: 2035 | H9: 2040 | I9: 2045 | J9: 2050
A10: Elect | B10: 0.50921584 | C10: 0.49133343 | D10: 0.56718822 | E10: 0.80192507 | F10: 0.80100488 | G10: 0.79928544 | H10: 0.79676311 | I10: 0.79188982 | J10: 0.71700042
A11: Gas | B11: 0.15495363 | C11: 0.16061014 | D11: 0.097730797 | E11: 0 | F11: 0 | G11: 0 | H11: 0 | I11: 0 | J11: 0.052037945
A12: LPG | B12: 0.0058786388 | C12: 0.0060817889 | D12: 0.00734866 | E12: 0.010697646 | F12: 0.010794722 | G12: 0.010859517 | H12: 0.011000316 | I12: 0.011274851 | J12: 0.010764037
A13: FuelOil | B13: 0.24036933 | C13: 0.2491219 | D13: 0.27123169 | E13: 0.18737729 | F13: 0.1882004 | G13: 0.18985504 | H13: 0.19223657 | I13: 0.19683533 | J13: 0.19011316
A14: Diesel | B14: 0 | C14: 0 | D14: 0 | E14: 0 | F14: 0 | G14: 0 | H14: 0 | I14: 0 | J14: 0
A15: Coke | B15: 0 | C15: 0 | D15: 0 | E15: 0 | F15: 0 | G15: 0 | H15: 0 | I15: 0 | J15: 0
A16: Charcoal | B16: 0.0096846017 | C16: 0.010038133 | D16: 0.0061081753 | E16: 0 | F16: 0 | G16: 0 | H16: 0 | I16: 0 | J16: 0.0032523716
A17: NCoal | B17: 0.079897959 | C17: 0.082814597 | D17: 0.05039245 | E17: 0 | F17: 0 | G17: 0 | H17: 0 | I17: 0 | J17: 0.026832063
A18: ICoal | B18: 0 | C18: 0 | D18: 0 | E18: 0 | F18: 0 | G18: 0 | H18: 0 | I18: 0 | J18: 0
A19: Biomass | B19: 0 | C19: 0 | D19: 0 | E19: 0 | F19: 0 | G19: 0 | H19: 0 | I19: 0 | J19: 0
A24: 1000 toe | B24: 2010 | C24: 2015 | D24: 2020 | E24: 2025 | F24: 2030 | G24: 2035 | H24: 2040 | I24: 2045 | J24: 2050
A25: Elect | B25: =B$6*B10 -> 3249.3063 | C25: =C$6*C10 -> 2720.0219 | D25: =D$6*D10 -> 3264.7354 | E25: =E$6*E10 -> 4988.7758 | F25: =F$6*F10 -> 5363.5287 | G25: =G$6*G10 -> 5725.2816 | H25: =H$6*H10 -> 6071.3349 | I25: =I$6*I10 -> 6384.2157 | J25: =J$6*J10 -> 6084.4656
A26: Gas | B26: =B$6*B11 -> 988.75909 | C26: =C$6*C11 -> 889.13774 | D26: =D$6*D11 -> 562.53847 | E26: =E$6*E11 -> 0 | F26: =F$6*F11 -> 0 | G26: =G$6*G11 -> 0 | H26: =H$6*H11 -> 0 | I26: =I$6*I11 -> 0 | J26: =J$6*J11 -> 441.594
A27: LPG | B27: =B$6*B12 -> 37.511594 | C27: =C$6*C12 -> 33.668783 | D27: =D$6*D12 -> 42.298887 | E27: =E$6*E12 -> 66.550059 | F27: =F$6*F12 -> 72.281459 | G27: =G$6*G12 -> 77.786721 | H27: =H$6*H12 -> 83.822411 | I27: =I$6*I12 -> 90.897848 | J27: =J$6*J12 -> 91.343617
A28: FuelOil | B28: =B$6*B13 -> 1533.7967 | C28: =C$6*C13 -> 1379.1389 | D28: =D$6*D13 -> 1561.2096 | E28: =E$6*E13 -> 1165.6741 | F28: =F$6*F13 -> 1260.1899 | G28: =G$6*G13 -> 1359.9317 | H28: =H$6*H13 -> 1464.8427 | I28: =I$6*I13 -> 1586.8865 | J28: =J$6*J13 -> 1613.3003
A29: Diesel | B29: =B$6*B14 -> 0 | C29: =C$6*C14 -> 0 | D29: =D$6*D14 -> 0 | E29: =E$6*E14 -> 0 | F29: =F$6*F14 -> 0 | G29: =G$6*G14 -> 0 | H29: =H$6*H14 -> 0 | I29: =I$6*I14 -> 0 | J29: =J$6*J14 -> 0
A30: Coke | B30: =B$6*B15 -> 0 | C30: =C$6*C15 -> 0 | D30: =D$6*D15 -> 0 | E30: =E$6*E15 -> 0 | F30: =F$6*F15 -> 0 | G30: =G$6*G15 -> 0 | H30: =H$6*H15 -> 0 | I30: =I$6*I15 -> 0 | J30: =J$6*J15 -> 0
A31: Charcoal | B31: =B$6*B16 -> 61.797443 | C31: =C$6*C16 -> 55.571105 | D31: =D$6*D16 -> 35.158657 | E31: =E$6*E16 -> 0 | F31: =F$6*F16 -> 0 | G31: =G$6*G16 -> 0 | H31: =H$6*H16 -> 0 | I31: =I$6*I16 -> 0 | J31: =J$6*J16 -> 27.599625
A32: NCoal | B32: =B$6*B17 -> 509.82888 | C32: =C$6*C17 -> 458.46161 | D32: =D$6*D17 -> 290.05894 | E32: =E$6*E17 -> 0 | F32: =F$6*F17 -> 0 | G32: =G$6*G17 -> 0 | H32: =H$6*H17 -> 0 | I32: =I$6*I17 -> 0 | J32: =J$6*J17 -> 227.69689
A33: ICoal | B33: =B$6*B18 -> 0 | C33: =C$6*C18 -> 0 | D33: =D$6*D18 -> 0 | E33: =E$6*E18 -> 0 | F33: =F$6*F18 -> 0 | G33: =G$6*G18 -> 0 | H33: =H$6*H18 -> 0 | I33: =I$6*I18 -> 0 | J33: =J$6*J18 -> 0
A34: Biomass | B34: =B$6*B19 -> 0 | C34: =C$6*C19 -> 0 | D34: =D$6*D19 -> 0 | E34: =E$6*E19 -> 0 | F34: =F$6*F19 -> 0 | G34: =G$6*G19 -> 0 | H34: =H$6*H19 -> 0 | I34: =I$6*I19 -> 0 | J34: =J$6*J19 -> 0

Sheet mop
A1: ktoe/yr | B1: 2010 | C1: 2011 | D1: 2012 | E1: 2013 | F1: 2014 | G1: 2015 | H1: 2016 | I1: 2017 | J1: 2018 | K1: 2019 | L1: 2020 | M1: 2021 | N1: 2022 | O1: 2023 | P1: 2024 | Q1: 2025 | R1: 2026 | S1: 2027 | T1: 2028 | U1: 2029 | V1: 2030 | W1: 2031 | X1: 2032 | Y1: 2033 | Z1: 2034 | AA1: 2035 | AB1: 2036 | AC1: 2037 | AD1: 2038 | AE1: 2039 | AF1: 2040 | AG1: 2041 | AH1: 2042 | AI1: 2043 | AJ1: 2044 | AK1: 2045 | AL1: 2046 | AM1: 2047 | AN1: 2048 | AO1: 2049 | AP1: 2050
A2: Cement and other carbonate use
A3: Cement | J3: =(J4-I4)/I4 -> 0.013970626 | K3: =(K4-J4)/J4 -> 0.013778137 | L3: =(L4-K4)/K4 -> 0.01359088 | M3: =(M4-L4)/L4 -> 0.016159136 | N3: =(N4-M4)/M4 -> 0.01590217 | O3: =(O4-N4)/N4 -> 0.01565325 | P3: =(P4-O4)/O4 -> 0.015412002 | Q3: =(Q4-P4)/P4 -> 0.015178077 | ... AP3: =(AP4-AO4)/AO4 -> 0.0064969645
A4: Electricity | B4: 553 | C4: =$B4+((C$1-$B$1)*($G4-$B4)/($G$1-$B$1)) -> 518.38 | D4: =$B4+((D$1-$B$1)*($G4-$B4)/($G$1-$B$1)) -> 483.76 | E4: =$B4+((E$1-$B$1)*($G4-$B4)/($G$1-$B$1)) -> 449.14 | F4: =$B4+((F$1-$B$1)*($G4-$B4)/($G$1-$B$1)) -> 414.52 | G4: 379.9 | H4: =$G4+((H$1-$G$1)*($L4-$G4)/($L$1-$G$1)) -> 385.36 | I4: =$G4+((I$1-$G$1)*($L4-$G4)/($L$1-$G$1)) -> 390.82 | J4: =$G4+((J$1-$G$1)*($L4-$G4)/($L$1-$G$1)) -> 396.28 | K4: =$G4+((K$1-$G$1)*($L4-$G4)/($L$1-$G$1)) -> 401.74 | L4: 407.2 | M4: =$L4+((M$1-$L$1)*($Q4-$L4)/($Q$1-$L$1)) -> 413.78 | N4: =$L4+((N$1-$L$1)*($Q4-$L4)/($Q$1-$L$1)) -> 420.36 | O4: =$L4+((O$1-$L$1)*($Q4-$L4)/($Q$1-$L$1)) -> 426.94 | P4: =$L4+((P$1-$L$1)*($Q4-$L4)/($Q$1-$L$1)) -> 433.52 | Q4: 440.1 | R4: =$Q4+((R$1-$Q$1)*($V4-$Q4)/($V$1-$Q$1)) -> 446.3 | S4: =$Q4+((S$1-$Q$1)*($V4-$Q4)/($V$1-$Q$1)) -> 452.5 | T4: =$Q4+((T$1-$Q$1)*($V4-$Q4)/($V$1-$Q$1)) -> 458.7 | U4: =$Q4+((U$1-$Q$1)*($V4-$Q4)/($V$1-$Q$1)) -> 464.9 | V4: 471.1 | W4: =$V4+((W$1-$V$1)*($AA4-$V4)/($AA$1-$V$1)) -> 476.92 | X4: =$V4+((X$1-$V$1)*($AA4-$V4)/($AA$1-$V$1)) -> 482.74 | Y4: =$V4+((Y$1-$V$1)*($AA4-$V4)/($AA$1-$V$1)) -> 488.56 | Z4: =$V4+((Z$1-$V$1)*($AA4-$V4)/($AA$1-$V$1)) -> 494.38 | AA4: 500.2 | AB4: =$AA4+((AB$1-$AA$1)*($AF4-$AA4)/($AF$1-$AA$1)) -> 505.42 | AC4: =$AA4+((AC$1-$AA$1)*($AF4-$AA4)/($AF$1-$AA$1)) -> 510.64 | AD4: =$AA4+((AD$1-$AA$1)*($AF4-$AA4)/($AF$1-$AA$1)) -> 515.86 | AE4: =$AA4+((AE$1-$AA$1)*($AF4-$AA4)/($AF$1-$AA$1)) -> 521.08 | AF4: 526.3 | AG4: =$AF4+((AG$1-$AF$1)*($AK4-$AF4)/($AK$1-$AF$1)) -> 530.78 | AH4: =$AF4+((AH$1-$AF$1)*($AK4-$AF4)/($AK$1-$AF$1)) -> 535.26 | AI4: =$AF4+((AI$1-$AF$1)*($AK4-$AF4)/($AK$1-$AF$1)) -> 539.74 | AJ4: =$AF4+((AJ$1-$AF$1)*($AK4-$AF4)/($AK$1-$AF$1)) -> 544.22 | AK4: 548.7 | AL4: =$AK4+((AL$1-$AK$1)*($AP4-$AK4)/($AP$1-$AK$1)) -> 552.36 | AM4: =$AK4+((AM$1-$AK$1)*($AP4-$AK4)/($AP$1-$AK$1)) -> 556.02 | AN4: =$AK4+((AN$1-$AK$1)*($AP4-$AK4)/($AP$1-$AK$1)) -> 559.68 | AO4: =$AK4+((AO$1-$AK$1)*($AP4-$AK4)/($AP$1-$AK$1)) -> 563.34 | AP4: 567
A5: Coal | B5: 52 | C5: =$B5+((C$1-$B$1)*($G5-$B5)/($G$1-$B$1)) -> 55.8 | D5: =$B5+((D$1-$B$1)*($G5-$B5)/($G$1-$B$1)) -> 59.6 | E5: =$B5+((E$1-$B$1)*($G5-$B5)/($G$1-$B$1)) -> 63.4 | F5: =$B5+((F$1-$B$1)*($G5-$B5)/($G$1-$B$1)) -> 67.2 | G5: 71 | H5: =$G5+((H$1-$G$1)*($L5-$G5)/($L$1-$G$1)) -> 68.22 | I5: =$G5+((I$1-$G$1)*($L5-$G5)/($L$1-$G$1)) -> 65.44 | J5: =$G5+((J$1-$G$1)*($L5-$G5)/($L$1-$G$1)) -> 62.66 | K5: =$G5+((K$1-$G$1)*($L5-$G5)/($L$1-$G$1)) -> 59.88 | L5: 57.1 | M5: =$L5+((M$1-$L$1)*($Q5-$L5)/($Q$1-$L$1)) -> 50.62 | N5: =$L5+((N$1-$L$1)*($Q5-$L5)/($Q$1-$L$1)) -> 44.14 | O5: =$L5+((O$1-$L$1)*($Q5-$L5)/($Q$1-$L$1)) -> 37.66 | P5: =$L5+((P$1-$L$1)*($Q5-$L5)/($Q$1-$L$1)) -> 31.18 | Q5: 24.7 | R5: =$Q5+((R$1-$Q$1)*($V5-$Q5)/($V$1-$Q$1)) -> 28.56 | S5: =$Q5+((S$1-$Q$1)*($V5-$Q5)/($V$1-$Q$1)) -> 32.42 | T5: =$Q5+((T$1-$Q$1)*($V5-$Q5)/($V$1-$Q$1)) -> 36.28 | U5: =$Q5+((U$1-$Q$1)*($V5-$Q5)/($V$1-$Q$1)) -> 40.14 | V5: 44 | W5: =$V5+((W$1-$V$1)*($AA5-$V5)/($AA$1-$V$1)) -> 46.42 | X5: =$V5+((X$1-$V$1)*($AA5-$V5)/($AA$1-$V$1)) -> 48.84 | Y5: =$V5+((Y$1-$V$1)*($AA5-$V5)/($AA$1-$V$1)) -> 51.26 | Z5: =$V5+((Z$1-$V$1)*($AA5-$V5)/($AA$1-$V$1)) -> 53.68 | AA5: 56.1 | AB5: =$AA5+((AB$1-$AA$1)*($AF5-$AA5)/($AF$1-$AA$1)) -> 64.56 | AC5: =$AA5+((AC$1-$AA$1)*($AF5-$AA5)/($AF$1-$AA$1)) -> 73.02 | AD5: =$AA5+((AD$1-$AA$1)*($AF5-$AA5)/($AF$1-$AA$1)) -> 81.48 | AE5: =$AA5+((AE$1-$AA$1)*($AF5-$AA5)/($AF$1-$AA$1)) -> 89.94 | AF5: 98.4 | AG5: =$AF5+((AG$1-$AF$1)*($AK5-$AF5)/($AK$1-$AF$1)) -> 104.36 | AH5: =$AF5+((AH$1-$AF$1)*($AK5-$AF5)/($AK$1-$AF$1)) -> 110.32 | AI5: =$AF5+((AI$1-$AF$1)*($AK5-$AF5)/($AK$1-$AF$1)) -> 116.28 | AJ5: =$AF5+((AJ$1-$AF$1)*($AK5-$AF5)/($AK$1-$AF$1)) -> 122.24 | AK5: 128.2 | AL5: =$AK5+((AL$1-$AK$1)*($AP5-$AK5)/($AP$1-$AK$1)) -> 132.24 | AM5: =$AK5+((AM$1-$AK$1)*($AP5-$AK5)/($AP$1-$AK$1)) -> 136.28 | AN5: =$AK5+((AN$1-$AK$1)*($AP5-$AK5)/($AP$1-$AK$1)) -> 140.32 | AO5: =$AK5+((AO$1-$AK$1)*($AP5-$AK5)/($AP$1-$AK$1)) -> 144.36 | AP5: 148.4
A6: Natural Gas | B6: 23 | C6: =$B6+((C$1-$B$1)*($G6-$B6)/($G$1-$B$1)) -> 23.38 | D6: =$B6+((D$1-$B$1)*($G6-$B6)/($G$1-$B$1)) -> 23.76 | E6: =$B6+((E$1-$B$1)*($G6-$B6)/($G$1-$B$1)) -> 24.14 | F6: =$B6+((F$1-$B$1)*($G6-$B6)/($G$1-$B$1)) -> 24.52 | G6: 24.9 | H6: =$G6+((H$1-$G$1)*($L6-$G6)/($L$1-$G$1)) -> 24.86 | I6: =$G6+((I$1-$G$1)*($L6-$G6)/($L$1-$G$1)) -> 24.82 | J6: =$G6+((J$1-$G$1)*($L6-$G6)/($L$1-$G$1)) -> 24.78 | K6: =$G6+((K$1-$G$1)*($L6-$G6)/($L$1-$G$1)) -> 24.74 | L6: 24.7 | M6: =$L6+((M$1-$L$1)*($Q6-$L6)/($Q$1-$L$1)) -> 27.98 | N6: =$L6+((N$1-$L$1)*($Q6-$L6)/($Q$1-$L$1)) -> 31.26 | O6: =$L6+((O$1-$L$1)*($Q6-$L6)/($Q$1-$L$1)) -> 34.54 | P6: =$L6+((P$1-$L$1)*($Q6-$L6)/($Q$1-$L$1)) -> 37.82 | Q6: 41.1 | R6: =$Q6+((R$1-$Q$1)*($V6-$Q6)/($V$1-$Q$1)) -> 50.5 | S6: =$Q6+((S$1-$Q$1)*($V6-$Q6)/($V$1-$Q$1)) -> 59.9 | T6: =$Q6+((T$1-$Q$1)*($V6-$Q6)/($V$1-$Q$1)) -> 69.3 | U6: =$Q6+((U$1-$Q$1)*($V6-$Q6)/($V$1-$Q$1)) -> 78.7 | V6: 88.1 | W6: =$V6+((W$1-$V$1)*($AA6-$V6)/($AA$1-$V$1)) -> 98.54 | X6: =$V6+((X$1-$V$1)*($AA6-$V6)/($AA$1-$V$1)) -> 108.98 | Y6: =$V6+((Y$1-$V$1)*($AA6-$V6)/($AA$1-$V$1)) -> 119.42 | Z6: =$V6+((Z$1-$V$1)*($AA6-$V6)/($AA$1-$V$1)) -> 129.86 | AA6: 140.3 | AB6: =$AA6+((AB$1-$AA$1)*($AF6-$AA6)/($AF$1-$AA$1)) -> 146.68 | AC6: =$AA6+((AC$1-$AA$1)*($AF6-$AA6)/($AF$1-$AA$1)) -> 153.06 | AD6: =$AA6+((AD$1-$AA$1)*($AF6-$AA6)/($AF$1-$AA$1)) -> 159.44 | AE6: =$AA6+((AE$1-$AA$1)*($AF6-$AA6)/($AF$1-$AA$1)) -> 165.82 | AF6: 172.2 | AG6: =$AF6+((AG$1-$AF$1)*($AK6-$AF6)/($AK$1-$AF$1)) -> 183.92 | AH6: =$AF6+((AH$1-$AF$1)*($AK6-$AF6)/($AK$1-$AF$1)) -> 195.64 | AI6: =$AF6+((AI$1-$AF$1)*($AK6-$AF6)/($AK$1-$AF$1)) -> 207.36 | AJ6: =$AF6+((AJ$1-$AF$1)*($AK6-$AF6)/($AK$1-$AF$1)) -> 219.08 | AK6: 230.8 | AL6: =$AK6+((AL$1-$AK$1)*($AP6-$AK6)/($AP$1-$AK$1)) -> 242.94 | AM6: =$AK6+((AM$1-$AK$1)*($AP6-$AK6)/($AP$1-$AK$1)) -> 255.08 | AN6: =$AK6+((AN$1-$AK$1)*($AP6-$AK6)/($AP$1-$AK$1)) -> 267.22 | AO6: =$AK6+((AO$1-$AK$1)*($AP6-$AK6)/($AP$1-$AK$1)) -> 279.36 | AP6: 291.5
A7: (biofuel heat and coproducts) Biomass | B7: =B8+B9 -> 413 | C7: =$B7+((C$1-$B$1)*($G7-$B7)/($G$1-$B$1)) -> 428.38 | D7: =$B7+((D$1-$B$1)*($G7-$B7)/($G$1-$B$1)) -> 443.76 | E7: =$B7+((E$1-$B$1)*($G7-$B7)/($G$1-$B$1)) -> 459.14 | F7: =$B7+((F$1-$B$1)*($G7-$B7)/($G$1-$B$1)) -> 474.52 | G7: =G8+G9 -> 489.9 | H7: =$G7+((H$1-$G$1)*($L7-$G7)/($L$1-$G$1)) -> 496.98 | I7: =$G7+((I$1-$G$1)*($L7-$G7)/($L$1-$G$1)) -> 504.06 | J7: =$G7+((J$1-$G$1)*($L7-$G7)/($L$1-$G$1)) -> 511.14 | K7: =$G7+((K$1-$G$1)*($L7-$G7)/($L$1-$G$1)) -> 518.22 | L7: =L8+L9 -> 525.3 | M7: =$L7+((M$1-$L$1)*($Q7-$L7)/($Q$1-$L$1)) -> 543.64 | N7: =$L7+((N$1-$L$1)*($Q7-$L7)/($Q$1-$L$1)) -> 561.98 | O7: =$L7+((O$1-$L$1)*($Q7-$L7)/($Q$1-$L$1)) -> 580.32 | P7: =$L7+((P$1-$L$1)*($Q7-$L7)/($Q$1-$L$1)) -> 598.66 | Q7: =Q8+Q9 -> 617 | R7: =$Q7+((R$1-$Q$1)*($V7-$Q7)/($V$1-$Q$1)) -> 646.69033 | S7: =$Q7+((S$1-$Q$1)*($V7-$Q7)/($V$1-$Q$1)) -> 676.38066 | T7: =$Q7+((T$1-$Q$1)*($V7-$Q7)/($V$1-$Q$1)) -> 706.07098 | U7: =$Q7+((U$1-$Q$1)*($V7-$Q7)/($V$1-$Q$1)) -> 735.76131 | V7: =V8+V9 -> 765.45164 | W7: =$V7+((W$1-$V$1)*($AA7-$V7)/($AA$1-$V$1)) -> 783.9377 | X7: =$V7+((X$1-$V$1)*($AA7-$V7)/($AA$1-$V$1)) -> 802.42377 | Y7: =$V7+((Y$1-$V$1)*($AA7-$V7)/($AA$1-$V$1)) -> 820.90984 | Z7: =$V7+((Z$1-$V$1)*($AA7-$V7)/($AA$1-$V$1)) -> 839.3959 | AA7: =AA8+AA9 -> 857.88197 | AB7: =$AA7+((AB$1-$AA$1)*($AF7-$AA7)/($AF$1-$AA$1)) -> 861.57918 | AC7: =$AA7+((AC$1-$AA$1)*($AF7-$AA7)/($AF$1-$AA$1)) -> 865.27639 | AD7: =$AA7+((AD$1-$AA$1)*($AF7-$AA7)/($AF$1-$AA$1)) -> 868.97361 | AE7: =$AA7+((AE$1-$AA$1)*($AF7-$AA7)/($AF$1-$AA$1)) -> 872.67082 | AF7: =AF8+AF9 -> 876.36803 | AG7: =$AF7+((AG$1-$AF$1)*($AK7-$AF7)/($AK$1-$AF$1)) -> 894.8541 | AH7: =$AF7+((AH$1-$AF$1)*($AK7-$AF7)/($AK$1-$AF$1)) -> 913.34016 | AI7: =$AF7+((AI$1-$AF$1)*($AK7-$AF7)/($AK$1-$AF$1)) -> 931.82623 | AJ7: =$AF7+((AJ$1-$AF$1)*($AK7-$AF7)/($AK$1-$AF$1)) -> 950.3123 | AK7: =AK8+AK9 -> 968.79836 | AL7: =$AK7+((AL$1-$AK$1)*($AP7-$AK7)/($AP$1-$AK$1)) -> 991.81869 | AM7: =$AK7+((AM$1-$AK$1)*($AP7-$AK7)/($AP$1-$AK$1)) -> 1014.839 | AN7: =$AK7+((AN$1-$AK$1)*($AP7-$AK7)/($AP$1-$AK$1)) -> 1037.8593 | AO7: =$AK7+((AO$1-$AK$1)*($AP7-$AK7)/($AP$1-$AK$1)) -> 1060.8797 | AP7: =AP8+AP9 -> 1083.9
A8: carvão vegetal | B8: 63 | C8: =$B8+((C$1-$B$1)*($G8-$B8)/($G$1-$B$1)) -> 63.18 | D8: =$B8+((D$1-$B$1)*($G8-$B8)/($G$1-$B$1)) -> 63.36 | E8: =$B8+((E$1-$B$1)*($G8-$B8)/($G$1-$B$1)) -> 63.54 | F8: =$B8+((F$1-$B$1)*($G8-$B8)/($G$1-$B$1)) -> 63.72 | G8: 63.9 | H8: =$G8+((H$1-$G$1)*($L8-$G8)/($L$1-$G$1)) -> 63.3 | I8: =$G8+((I$1-$G$1)*($L8-$G8)/($L$1-$G$1)) -> 62.7 | J8: =$G8+((J$1-$G$1)*($L8-$G8)/($L$1-$G$1)) -> 62.1 | K8: =$G8+((K$1-$G$1)*($L8-$G8)/($L$1-$G$1)) -> 61.5 | L8: 60.9 | M8: =$L8+((M$1-$L$1)*($Q8-$L8)/($Q$1-$L$1)) -> 65.18 | N8: =$L8+((N$1-$L$1)*($Q8-$L8)/($Q$1-$L$1)) -> 69.46 | O8: =$L8+((O$1-$L$1)*($Q8-$L8)/($Q$1-$L$1)) -> 73.74 | P8: =$L8+((P$1-$L$1)*($Q8-$L8)/($Q$1-$L$1)) -> 78.02 | Q8: 82.3 | R8: =$Q8+((R$1-$Q$1)*($V8-$Q8)/($V$1-$Q$1)) -> 108.0377 | S8: =$Q8+((S$1-$Q$1)*($V8-$Q8)/($V$1-$Q$1)) -> 133.77541 | T8: =$Q8+((T$1-$Q$1)*($V8-$Q8)/($V$1-$Q$1)) -> 159.51311 | U8: =$Q8+((U$1-$Q$1)*($V8-$Q8)/($V$1-$Q$1)) -> 185.25082 | V8: 210.98852 | W8: =$V8+((W$1-$V$1)*($AA8-$V8)/($AA$1-$V$1)) -> 217.13607 | X8: =$V8+((X$1-$V$1)*($AA8-$V8)/($AA$1-$V$1)) -> 223.28361 | Y8: =$V8+((Y$1-$V$1)*($AA8-$V8)/($AA$1-$V$1)) -> 229.43115 | Z8: =$V8+((Z$1-$V$1)*($AA8-$V8)/($AA$1-$V$1)) -> 235.57869 | AA8: 241.72623 | AB8: =$AA8+((AB$1-$AA$1)*($AF8-$AA8)/($AF$1-$AA$1)) -> 242.95574 | AC8: =$AA8+((AC$1-$AA$1)*($AF8-$AA8)/($AF$1-$AA$1)) -> 244.18525 | AD8: =$AA8+((AD$1-$AA$1)*($AF8-$AA8)/($AF$1-$AA$1)) -> 245.41475 | AE8: =$AA8+((AE$1-$AA$1)*($AF8-$AA8)/($AF$1-$AA$1)) -> 246.64426 | AF8: 247.87377 | AG8: =$AF8+((AG$1-$AF$1)*($AK8-$AF8)/($AK$1-$AF$1)) -> 254.02131 | AH8: =$AF8+((AH$1-$AF$1)*($AK8-$AF8)/($AK$1-$AF$1)) -> 260.16885 | AI8: =$AF8+((AI$1-$AF$1)*($AK8-$AF8)/($AK$1-$AF$1)) -> 266.31639 | AJ8: =$AF8+((AJ$1-$AF$1)*($AK8-$AF8)/($AK$1-$AF$1)) -> 272.46393 | AK8: 278.61148 | AL8: =$AK8+((AL$1-$AK$1)*($AP8-$AK8)/($AP$1-$AK$1)) -> 280.68918 | AM8: =$AK8+((AM$1-$AK$1)*($AP8-$AK8)/($AP$1-$AK$1)) -> 282.76689 | AN8: =$AK8+((AN$1-$AK$1)*($AP8-$AK8)/($AP$1-$AK$1)) -> 284.84459 | AO8: =$AK8+((AO$1-$AK$1)*($AP8-$AK8)/($AP$1-$AK$1)) -> 286.9223 | AP8: 289
A9: outras | B9: 350 | C9: =$B9+((C$1-$B$1)*($G9-$B9)/($G$1-$B$1)) -> 365.2 | D9: =$B9+((D$1-$B$1)*($G9-$B9)/($G$1-$B$1)) -> 380.4 | E9: =$B9+((E$1-$B$1)*($G9-$B9)/($G$1-$B$1)) -> 395.6 | F9: =$B9+((F$1-$B$1)*($G9-$B9)/($G$1-$B$1)) -> 410.8 | G9: 426 | H9: =$G9+((H$1-$G$1)*($L9-$G9)/($L$1-$G$1)) -> 433.68 | I9: =$G9+((I$1-$G$1)*($L9-$G9)/($L$1-$G$1)) -> 441.36 | J9: =$G9+((J$1-$G$1)*($L9-$G9)/($L$1-$G$1)) -> 449.04 | K9: =$G9+((K$1-$G$1)*($L9-$G9)/($L$1-$G$1)) -> 456.72 | L9: 464.4 | M9: =$L9+((M$1-$L$1)*($Q9-$L9)/($Q$1-$L$1)) -> 478.46 | N9: =$L9+((N$1-$L$1)*($Q9-$L9)/($Q$1-$L$1)) -> 492.52 | O9: =$L9+((O$1-$L$1)*($Q9-$L9)/($Q$1-$L$1)) -> 506.58 | P9: =$L9+((P$1-$L$1)*($Q9-$L9)/($Q$1-$L$1)) -> 520.64 | Q9: 534.7 | R9: =$Q9+((R$1-$Q$1)*($V9-$Q9)/($V$1-$Q$1)) -> 538.65262 | S9: =$Q9+((S$1-$Q$1)*($V9-$Q9)/($V$1-$Q$1)) -> 542.60525 | T9: =$Q9+((T$1-$Q$1)*($V9-$Q9)/($V$1-$Q$1)) -> 546.55787 | U9: =$Q9+((U$1-$Q$1)*($V9-$Q9)/($V$1-$Q$1)) -> 550.51049 | V9: 554.46311 | W9: =$V9+((W$1-$V$1)*($AA9-$V9)/($AA$1-$V$1)) -> 566.80164 | X9: =$V9+((X$1-$V$1)*($AA9-$V9)/($AA$1-$V$1)) -> 579.14016 | Y9: =$V9+((Y$1-$V$1)*($AA9-$V9)/($AA$1-$V$1)) -> 591.47869 | Z9: =$V9+((Z$1-$V$1)*($AA9-$V9)/($AA$1-$V$1)) -> 603.81721 | AA9: 616.15574 | AB9: =$AA9+((AB$1-$AA$1)*($AF9-$AA9)/($AF$1-$AA$1)) -> 618.62344 | AC9: =$AA9+((AC$1-$AA$1)*($AF9-$AA9)/($AF$1-$AA$1)) -> 621.09115 | AD9: =$AA9+((AD$1-$AA$1)*($AF9-$AA9)/($AF$1-$AA$1)) -> 623.55885 | AE9: =$AA9+((AE$1-$AA$1)*($AF9-$AA9)/($AF$1-$AA$1)) -> 626.02656 | AF9: 628.49426 | AG9: =$AF9+((AG$1-$AF$1)*($AK9-$AF9)/($AK$1-$AF$1)) -> 640.83279 | AH9: =$AF9+((AH$1-$AF$1)*($AK9-$AF9)/($AK$1-$AF$1)) -> 653.17131 | AI9: =$AF9+((AI$1-$AF$1)*($AK9-$AF9)/($AK$1-$AF$1)) -> 665.50984 | AJ9: =$AF9+((AJ$1-$AF$1)*($AK9-$AF9)/($AK$1-$AF$1)) -> 677.84836 | AK9: 690.18689 | AL9: =$AK9+((AL$1-$AK$1)*($AP9-$AK9)/($AP$1-$AK$1)) -> 711.12951 | AM9: =$AK9+((AM$1-$AK$1)*($AP9-$AK9)/($AP$1-$AK$1)) -> 732.07213 | AN9: =$AK9+((AN$1-$AK$1)*($AP9-$AK9)/($AP$1-$AK$1)) -> 753.01475 | AO9: =$AK9+((AO$1-$AK$1)*($AP9-$AK9)/($AP$1-$AK$1)) -> 773.95738 | AP9: 794.9
