Workbook

Sheet About
A1: BCDTRtSY BAU Cargo Dist Transported Relative to Start Year
A3: Source: | B3: passenger PKM
B4: Brazilian Ministry of Science, Technology, Innovation and Communication (MCTIC)
B5: 2017
B6: Report: "Greenhouse gas mitigation options in key sectors in Brazil"
B7: Version: "Sector modeling of low carbon options for the transport sector"
B8: https://www.mctic.gov.br/mctic/export/sites/institucional/ciencia/SEPED/clima/arquivos/projeto_opcoes_mitigacao/publicacoes/Setor-Transportes.pdf
B9: Page 247
B10: Table 94 - Passenger-Kilometers Transported by Modal (Millions of PKM)
B12: freight TKM
B13: Brazilian Ministry of Science, Technology, Innovation and Communication (MCTIC)
B14: 2017
B15: Report: "Greenhouse gas mitigation options in key sectors in Brazil"
B16: Version: "Sector modeling of low carbon options for the transport sector"
B17: https://www.mctic.gov.br/mctic/export/sites/institucional/ciencia/SEPED/clima/arquivos/projeto_opcoes_mitigacao/publicacoes/Setor-Transportes.pdf
B18: page 248
B19: Table 95 - Tons-Kilometers Transported by Modal (Million)
A23: Notes
A24: This variable contains ratios of cargo distance transported in each year of the
A25: model run relative to the start year. The start year is the year is 2019
A26: The start year column does not have to be included in the outputs but is retained here for visual clarity.
A28: We scale by passenger-miles and freight ton-miles.

Sheet table 95
A1: page 248
A2: Table 95 - Tons-Kilometers Transported by Modal (Million)
M5: translation
M7: road
M8: railroad
M9: ships
M10: aircraft

Sheet table 94
A1: Page 247
A2: Table 94 - Passenger-Kilometers Transported by Modal (Millions of PKM)
K5: translation
K7: road
K8: railroad
K9: ships
K10: aircraft

Sheet psgr-Road
A1: Notes
A2: We group the vehicle type according to LDV, HDV and motorbike category and then computed the cargo distance transported relative to start year (2015)
A4: table 94 from MOP report summarizes the data
A5: The table below is from the excel file that generated the results for transportation sector, this file has more detalied informations about the modelling than the report.
A7: PKM (10³ pkm)
A9: Vehicle type | B9: 2015 | C9: 2016 | D9: 2017 | E9: 2018 | F9: 2019 | G9: 2020 | H9: 2021 | I9: 2022 | J9: 2023 | K9: 2024 | L9: 2025 | M9: 2026 | N9: 2027 | O9: 2028 | P9: 2029 | Q9: 2030 | R9: 2031 | S9: 2032 | T9: 2033 | U9: 2034 | V9: 2035 | W9: 2036 | X9: 2037 | Y9: 2038 | Z9: 2039 | AA9: 2040 | AB9: 2041 | AC9: 2042 | AD9: 2043 | AE9: 2044 | AF9: 2045 | AG9: 2046 | AH9: 2047 | AI9: 2048 | AJ9: 2049 | AK9: 2050
A10: Auto Gasoline C | B10: 1.5594967e+08 | C10: 1.4191539e+08 | D10: 1.2934102e+08 | E10: 1.1822313e+08 | F10: 1.0853287e+08 | G10: 99937994 | H10: 92429654 | I10: 85918693 | J10: 80294256 | K10: 75465955 | L10: 71293200 | M10: 67649223 | N10: 64441495 | O10: 61596561 | P10: 59008926 | Q10: 56718973 | R10: 54801461 | S10: 53215846 | T10: 51909775 | U10: 50834817 | V10: 49938014 | W10: 49154290 | X10: 48444078 | Y10: 47793661 | Z10: 47196501 | AA10: 46645585 | AB10: 46138142 | AC10: 45674345 | AD10: 45244424 | AE10: 44842302 | AF10: 44463341 | AG10: 44103800 | AH10: 43762907 | AI10: 43438375 | AJ10: 43125196 | AK10: 43142734
A11: Auto Ethanol | B11: 6130059.6 | C11: 5087778 | D11: 4230501.3 | E11: 3515907.9 | F11: 2933752.8 | G11: 2454735.3 | H11: 2044452.3 | I11: 1699957.8 | J11: 1415754.3 | K11: 1188215.7 | L11: 1000861.2 | M11: 841634.1 | N11: 705092.4 | O11: 588173.1 | P11: 488486.1 | Q11: 404499.9 | R11: 334050.9 | S11: 275634.6 | T11: 229869.9 | U11: 193548.3 | V11: 166298.4 | W11: 143178.3 | X11: 123942.3 | Y11: 106416.6 | Z11: 88369.5 | AA11: 72892.5 | AB11: 58755 | AC11: 46065 | AD11: 36939 | AE11: 28098 | AF11: 21606 | AG11: 18267 | AH11: 14853 | AI11: 11574 | AJ11: 8172 | AK11: 6132
A12: Auto flex | B12: 574565097 | C12: 6.3156541e+08 | D12: 6.8749025e+08 | E12: 7.4226513e+08 | F12: 7.9586792e+08 | G12: 8.4444235e+08 | H12: 8.9089858e+08 | I12: 9.3559565e+08 | J12: 9.7865703e+08 | K12: 1.0202197e+09 | L12: 1.0590654e+09 | M12: 1.0941281e+09 | N12: 1.1256885e+09 | O12: 1.1539684e+09 | P12: 1.1791858e+09 | Q12: 1.2017639e+09 | R12: 1.2195439e+09 | S12: 1.2303237e+09 | T12: 1.2344402e+09 | U12: 1.2322428e+09 | V12: 1.2236699e+09 | W12: 1.2087753e+09 | X12: 1.18811e+09 | Y12: 1.1622095e+09 | Z12: 1.1315839e+09 | AA12: 1.0964125e+09 | AB12: 1.0568801e+09 | AC12: 1.0134682e+09 | AD12: 9.6666659e+08 | AE12: 9.1689247e+08 | AF12: 8.6457289e+08 | AG12: 8.1010642e+08 | AH12: 7.5386435e+08 | AI12: 6.961862e+08 | AJ12: 6.3737981e+08 | AK12: 5.8484451e+08
A13: Auto Hybrid | B13: 0 | C13: 0 | D13: 0 | E13: 0 | F13: 0 | G13: 276856.47 | H13: 1104915.9 | I13: 2498225.5 | J13: 4467913.7 | K13: 7022038.9 | L13: 10121337 | M13: 13713208 | N13: 17771850 | O13: 22267610 | P13: 27169042 | Q13: 32117032 | R13: 39371283 | S13: 51342259 | T13: 67862132 | U13: 88749079 | V13: 1.1365616e+08 | W13: 1.4218843e+08 | X13: 1.7404557e+08 | Y13: 2.0891817e+08 | Z13: 2.4649225e+08 | AA13: 2.8645343e+08 | AB13: 3.2849193e+08 | AC13: 3.7230703e+08 | AD13: 4.176104e+08 | AE13: 4.6413016e+08 | AF13: 5.116137e+08 | AG13: 5.5982921e+08 | AH13: 6.0856665e+08 | AI13: 6.5763747e+08 | AJ13: 7.0687431e+08 | AK13: 7.5941013e+08
A14: Auto Plug-in Flex | B14: 0 | C14: 0 | D14: 0 | E14: 0 | F14: 0 | G14: 0 | H14: 0 | I14: 0 | J14: 0 | K14: 0 | L14: 0 | M14: 0 | N14: 0 | O14: 0 | P14: 0 | Q14: 0 | R14: 0 | S14: 0 | T14: 0 | U14: 0 | V14: 0 | W14: 0 | X14: 0 | Y14: 0 | Z14: 0 | AA14: 0 | AB14: 0 | AC14: 0 | AD14: 0 | AE14: 0 | AF14: 0 | AG14: 0 | AH14: 0 | AI14: 0 | AJ14: 0 | AK14: 0
A15: Auto Battery | B15: 0 | C15: 0 | D15: 0 | E15: 0 | F15: 0 | G15: 0 | H15: 0 | I15: 0 | J15: 0 | K15: 0 | L15: 0 | M15: 0 | N15: 0 | O15: 0 | P15: 0 | Q15: 0 | R15: 0 | S15: 0 | T15: 0 | U15: 0 | V15: 0 | W15: 0 | X15: 0 | Y15: 0 | Z15: 0 | AA15: 324596.05 | AB15: 1269504.4 | AC15: 2801792.8 | AD15: 4887374.2 | AE15: 7490490.7 | AF15: 10573869 | AG15: 14098549 | AH15: 18024200 | AI15: 22309766 | AJ15: 26913871 | AK15: 31726404
A16: Com. Light Gasoline C | B16: 32151215 | C16: 32823251 | D16: 33556900 | E16: 34344129 | F16: 35178064 | G16: 36053603 | H16: 36974021 | I16: 37940623 | J16: 38947878 | K16: 39992505 | L16: 41071686 | M16: 42188505 | N16: 43344379 | O16: 44534798 | P16: 45753201 | Q16: 46993902 | R16: 48258322 | S16: 49546289 | T16: 50854176 | U16: 52180122 | V16: 53522406 | W16: 54879974 | X16: 56251542 | Y16: 57635941 | Z16: 59033534 | AA16: 60443509 | AB16: 61867048 | AC16: 63304038 | AD16: 64750876 | AE16: 66206249 | AF16: 67668919 | AG16: 69138062 | AH16: 70612981 | AI16: 72093146 | AJ16: 73577605 | AK16: 75065822
A17: Com. Light Ethanol | B17: 519455.1 | C17: 420980.4 | D17: 341046.6 | E17: 276529.2 | F17: 225327.9 | G17: 184343.7 | H17: 150088.5 | I17: 122226.9 | J17: 100064.4 | K17: 83006.1 | L17: 69516.6 | M17: 58359.3 | N17: 48921.6 | O17: 40874.7 | P17: 34074.6 | Q17: 28363.5 | R17: 23547.6 | S17: 19667.7 | T17: 16769.1 | U17: 14407.2 | V17: 12438.6 | W17: 10741.5 | X17: 9300 | Y17: 7983.6 | Z17: 6754.8 | AA17: 5595 | AB17: 4548 | AC17: 3600 | AD17: 2811 | AE17: 2100 | AF17: 1581 | AG17: 1329 | AH17: 1059 | AI17: 777 | AJ17: 516 | AK17: 339
A18: Com. Light Flex | B18: 66482746 | C18: 73760488 | D18: 80745824 | E18: 87429622 | F18: 93810674 | G18: 99895027 | H18: 1.0571798e+08 | I18: 1.1131813e+08 | J18: 1.1671296e+08 | K18: 1.2192199e+08 | L18: 126965361 | M18: 1.3187675e+08 | N18: 1.3668821e+08 | O18: 1.414163e+08 | P18: 1.4607601e+08 | Q18: 1.506805e+08 | R18: 1.5525043e+08 | S18: 1.5980396e+08 | T18: 1.6434848e+08 | U18: 1.6889022e+08 | V18: 1.734353e+08 | W18: 177993186 | X18: 1.8257274e+08 | Y18: 1.8717736e+08 | Z18: 1.9180771e+08 | AA18: 1.9646287e+08 | AB18: 2.0114611e+08 | AC18: 2.0585819e+08 | AD18: 2.1059783e+08 | AE18: 215361417 | AF18: 2.2014603e+08 | AG18: 2.2494923e+08 | AH18: 2.2976872e+08 | AI18: 2.346025e+08 | AJ18: 2.394488e+08 | AK18: 2.4430592e+08
A19: Com. Light Diesel | B19: 47489179 | C19: 50793212 | D19: 54069865 | E19: 57312356 | F19: 60516527 | G19: 63677721 | H19: 66803360 | I19: 69900581 | J19: 72968258 | K19: 76003784 | L19: 79004188 | M19: 81978818 | N19: 84934541 | O19: 87871313 | P19: 90790097 | Q19: 93694522 | R19: 96593386 | S19: 99494077 | T19: 1.023992e+08 | U19: 105313020 | V19: 1.0823669e+08 | W19: 1.1117628e+08 | X19: 114136176 | Y19: 1.1711444e+08 | Z19: 120110160 | AA19: 1.2312188e+08 | AB19: 126149958 | AC19: 1.2919457e+08 | AD19: 1.3225476e+08 | AE19: 1.35329e+08 | AF19: 1.3841663e+08 | AG19: 1.4151652e+08 | AH19: 1.4462781e+08 | AI19: 1.4774962e+08 | AJ19: 1.5088051e+08 | AK19: 1.5401982e+08
A20: Gasoline motorcycle C | B20: 1.1065979e+08 | C20: 110436900 | D20: 1.1084254e+08 | E20: 1.1190098e+08 | F20: 1.1355695e+08 | G20: 1.1587722e+08 | H20: 1.189037e+08 | I20: 1.2268737e+08 | J20: 1.2721078e+08 | K20: 1.3242731e+08 | L20: 1.3781521e+08 | M20: 142940140 | N20: 147817738 | O20: 1.5245448e+08 | P20: 156857168 | Q20: 161033238 | R20: 1.6500453e+08 | S20: 1.6879136e+08 | T20: 1.7241143e+08 | U20: 1.7588803e+08 | V20: 1.7908883e+08 | W20: 1.8194763e+08 | X20: 1.844876e+08 | Y20: 1.8673194e+08 | Z20: 1.8871458e+08 | AA20: 190465668 | AB20: 1.9201333e+08 | AC20: 1.9338337e+08 | AD20: 1.945985e+08 | AE20: 195680242 | AF20: 1.9664711e+08 | AG20: 197517108 | AH20: 1.9830629e+08 | AI20: 1.9902823e+08 | AJ20: 1.9969471e+08 | AK20: 2.0031549e+08
... A24: Bus Rodo Diesel | B24: 1.5321327e+08 | C24: 1.593848e+08 | D24: 1.6564334e+08 | E24: 1.7200597e+08 | F24: 1.7841939e+08 | G24: 1.8491249e+08 | H24: 1.9147852e+08 | I24: 1.9815405e+08 | J24: 2.0491313e+08 | K24: 2.1173569e+08 | L24: 2.1865172e+08 | M24: 2.2562922e+08 | N24: 2.3270306e+08 | O24: 2.3984006e+08 | P24: 2.4705901e+08 | Q24: 2.5434019e+08 | R24: 2.6169786e+08 | S24: 2.6912515e+08 | T24: 2.766351e+08 | U24: 2.8420113e+08 | V24: 2.9186632e+08 | W24: 2.9957976e+08 | X24: 3.0738408e+08 | Y24: 3.1523863e+08 | Z24: 3.2318152e+08 | AA24: 3.3117419e+08 | AB24: 3.3924814e+08 | AC24: 3.473697e+08 | AD24: 3.5555686e+08 | AE24: 3.6380431e+08 | AF24: 3.7208952e+08 | AG24: 3.8041039e+08 | AH24: 3.8879094e+08 | AI24: 3.9720587e+08 | AJ24: 4.0566266e+08 | AK24: 4.1415116e+08
A26: LDV | D26: =SUM(D10:D19) -> 9.8977541e+08 | E26: =SUM(E10:E19) -> 1.0433668e+09 | F26: =SUM(F10:F19) -> 1.0970651e+09 | G26: =SUM(G10:G19) -> 1.1469226e+09 | H26: =SUM(H10:H19) -> 1.1961231e+09 | I26: =SUM(I10:I19) -> 1.2449941e+09 | J26: =SUM(J10:J19) -> 1.2935641e+09 | K26: =SUM(K10:K19) -> 1.3418972e+09 | ... AK26: =SUM(AK10:AK19) -> 1.8925218e+09
A27: Cargo Dist Transported Relative to Start Year | F27: 1 | G27: =G26/$F$26 -> 1.0454463 | H27: =H26/$F$26 -> 1.0902936 | I27: =I26/$F$26 -> 1.1348406 | J27: =J26/$F$26 -> 1.1791133 | K27: =K26/$F$26 -> 1.2231701 | L27: =L26/$F$26 -> 1.265733 | M27: =M26/$F$26 -> 1.3056969 | N27: =N26/$F$26 -> 1.3432411 | ... AK27: =AK26/$F$26 -> 1.725077
A28: HDV | D28: =SUM(D22:D24) -> 9.0780739e+08 | E28: =SUM(E22:E24) -> 9.4343875e+08 | F28: =SUM(F22:F24) -> 9.7921905e+08 | G28: =SUM(G22:G24) -> 1.0119401e+09 | H28: =SUM(H22:H24) -> 1.0440938e+09 | I28: =SUM(I22:I24) -> 1.0759616e+09 | J28: =SUM(J22:J24) -> 1.10739e+09 | K28: =SUM(K22:K24) -> 1.138283e+09 | ... AK28: =SUM(AK22:AK24) -> 1.901094e+09
A29: Cargo Dist Transported Relative to Start Year | F29: 1 | G29: =G28/$F$28 -> 1.0334154 | H29: =H28/$F$28 -> 1.0662515 | I29: =I28/$F$28 -> 1.0987956 | J29: =J28/$F$28 -> 1.130891 | K29: =K28/$F$28 -> 1.1624396 | L29: =L28/$F$28 -> 1.1934822 | M29: =M28/$F$28 -> 1.2239426 | N29: =N28/$F$28 -> 1.2540753 | ... AK29: =AK28/$F$28 -> 1.941439
A30: Motorbike | D30: =SUM(D20:D21) -> 1.6487885e+08 | E30: =SUM(E20:E21) -> 1.7247661e+08 | F30: =SUM(F20:F21) -> 180682556 | G30: =SUM(G20:G21) -> 1.8954235e+08 | H30: =SUM(H20:H21) -> 1.9918183e+08 | I30: =SUM(I20:I21) -> 2.0968017e+08 | J30: =SUM(J20:J21) -> 2.2106601e+08 | K30: =SUM(K20:K21) -> 2.3331404e+08 | ... AK30: =SUM(AK20:AK21) -> 3.7206446e+08
A31: Cargo Dist Transported Relative to Start Year | F31: 1 | G31: =G30/$F$30 -> 1.0490352 | H31: =H30/$F$30 -> 1.1023855 | I31: =I30/$F$30 -> 1.1604893 | J31: =J30/$F$30 -> 1.223505 | K31: =K30/$F$30 -> 1.2912926 | L31: =L30/$F$30 -> 1.3587913 | M31: =M30/$F$30 -> 1.4217727 | N31: =N30/$F$30 -> 1.4806189 | ... AK31: =AK30/$F$30 -> 2.0592163

Sheet psgr-Air
A1: Notes
A2: Computed pkm relative to start year based on MOP's pkm estimation for reference scenario.
A4: table 94 from MOP report summarizes the data
A5: The table below is from the excel file that generated the results for transportation sector, this file has more detalied informations about the modelling than the report.
A9: Aircraft | B9: 2013 | C9: 2014 | D9: 2015 | E9: 2016 | F9: 2017 | G9: 2018 | H9: 2019 | I9: 2020 | J9: 2021 | K9: 2022 | L9: 2023 | M9: 2024 | N9: 2025 | O9: 2026 | P9: 2027 | Q9: 2028 | R9: 2029 | S9: 2030 | T9: 2031 | U9: 2032 | V9: 2033 | W9: 2034 | X9: 2035 | Y9: 2036 | Z9: 2037 | AA9: 2038 | AB9: 2039 | AC9: 2040 | AD9: 2041 | AE9: 2042 | AF9: 2043 | AG9: 2044 | AH9: 2045 | AI9: 2046 | AJ9: 2047 | AK9: 2048 | AL9: 2049 | AM9: 2050
A10: PKM (Millions) | B10: 210.86107 | C10: 221.61498 | D10: 239.34418 | E10: 259.46721 | F10: 279.17105 | G10: 301.50474 | H10: 325.62511 | I10: 343.59646 | J10: 362.4875 | K10: 382.41718 | L10: 403.44259 | M10: 425.62399 | N10: 449.02493 | O10: 472.21131 | P10: 496.59498 | Q10: 522.23774 | R10: 549.20463 | S10: 577.56402 | T10: 598.22148 | U10: 619.6178 | V10: 641.77939 | W10: 664.73362 | X10: 688.50884 | Y10: 711.02481 | Z10: 734.27712 | AA10: 758.28983 | AB10: 783.08781 | AC10: 808.69676 | AD10: 832.80175 | AE10: 857.62525 | AF10: 883.18867 | AG10: 909.51406 | AH10: 936.62414 | AI10: 962.03279 | AJ10: 988.13073 | AK10: 1014.9367 | AL10: 1042.4698 | AM10: 1070.7498
A11: PKM relative to start Yr | H11: 1 | I11: =I10/$H$10 -> 1.0551903 | J11: =J10/$H$10 -> 1.113205 | K11: =K10/$H$10 -> 1.1744093 | L11: =L10/$H$10 -> 1.2389787 | M11: =M10/$H$10 -> 1.3070982 | N11: =N10/$H$10 -> 1.3789628 | O11: =O10/$H$10 -> 1.4501686 | P11: =P10/$H$10 -> 1.5250512 | ... AM11: =AM10/$H$10 -> 3.28829

Sheet psgr-Rail
A1: Notes
A2: Computed pkm relative to start year based on table 94
A3: The time series was Linear interpolated
A5: table 94 from MOP report summarizes the data
A7: Rail | B7: 2013 | C7: 2014 | D7: 2015 | E7: 2016 | F7: 2017 | G7: 2018 | H7: 2019 | I7: 2020 | J7: 2021 | K7: 2022 | L7: 2023 | M7: 2024 | N7: 2025 | O7: 2026 | P7: 2027 | Q7: 2028 | R7: 2029 | S7: 2030 | T7: 2031 | U7: 2032 | V7: 2033 | W7: 2034 | X7: 2035 | Y7: 2036 | Z7: 2037 | AA7: 2038 | AB7: 2039 | AC7: 2040 | AD7: 2041 | AE7: 2042 | AF7: 2043 | AG7: 2044 | AH7: 2045 | AI7: 2046 | AJ7: 2047 | AK7: 2048 | AL7: 2049 | AM7: 2050
A8: PKM (Millions) | B8: 28000 | C8: 28285.714 | D8: 28571.429 | E8: 28857.143 | F8: 29142.857 | G8: 29428.571 | H8: 29714.286 | I8: 30000 | J8: 32000 | K8: 34000 | L8: 36000 | M8: 38000 | N8: 40000 | O8: 42000 | P8: 44000 | Q8: 46000 | R8: 48000 | S8: 50000 | T8: 52500 | U8: 55000 | V8: 57500 | W8: 60000 | X8: 62500 | Y8: 65000 | Z8: 67500 | AA8: 70000 | AB8: 72500 | AC8: 75000 | AD8: 76500 | AE8: 78000 | AF8: 79500 | AG8: 81000 | AH8: 82500 | AI8: 84000 | AJ8: 85500 | AK8: 87000 | AL8: 88500 | AM8: 90000
A9: Interpolated | B9: 28000 | C9: 28285.714 | D9: 28571.429 | E9: 28857.143 | F9: 29142.857 | G9: 29428.571 | H9: 29714.286 | I9: 30000 | J9: 32000 | K9: 34000 | L9: 36000 | M9: 38000 | N9: 40000 | O9: 42000 | P9: 44000 | Q9: 46000 | R9: 48000 | S9: 50000 | T9: 52500 | U9: 55000 | V9: 57500 | W9: 60000 | X9: 62500 | Y9: 65000 | Z9: 67500 | AA9: 70000 | AB9: 72500 | AC9: 75000 | AD9: 76500 | AE9: 78000 | AF9: 79500 | AG9: 81000 | AH9: 82500 | AI9: 84000 | AJ9: 85500 | AK9: 87000 | AL9: 88500 | AM9: 90000
A10: PKM relative to start Yr | H10: 1 | I10: =I9/$H$9 -> 1.0096154 | J10: =J9/$H$9 -> 1.0769231 | K10: =K9/$H$9 -> 1.1442308 | L10: =L9/$H$9 -> 1.2115385 | M10: =M9/$H$9 -> 1.2788462 | N10: =N9/$H$9 -> 1.3461538 | O10: =O9/$H$9 -> 1.4134615 | P10: =P9/$H$9 -> 1.4807692 | ... AM10: =AM9/$H$9 -> 3.0288462

Sheet psgr-Ship
A1: Notes
A2: Computed pkm relative to start year based on table 94
A3: The time series was Linear interpolated
A5: table 94 from MOP report summarizes the data
A7: Ship | B7: 2013 | C7: 2014 | D7: 2015 | E7: 2016 | F7: 2017 | G7: 2018 | H7: 2019 | I7: 2020 | J7: 2021 | K7: 2022 | L7: 2023 | M7: 2024 | N7: 2025 | O7: 2026 | P7: 2027 | Q7: 2028 | R7: 2029 | S7: 2030 | T7: 2031 | U7: 2032 | V7: 2033 | W7: 2034 | X7: 2035 | Y7: 2036 | Z7: 2037 | AA7: 2038 | AB7: 2039 | AC7: 2040 | AD7: 2041 | AE7: 2042 | AF7: 2043 | AG7: 2044 | AH7: 2045 | AI7: 2046 | AJ7: 2047 | AK7: 2048 | AL7: 2049 | AM7: 2050
A8: PKM (Millions) | B8: 1919 | C8: 1943.4286 | D8: 1967.8571 | E8: 1992.2857 | F8: 2016.7143 | G8: 2041.1429 | H8: 2065.5714 | I8: 2090 | J8: 2108.7 | K8: 2127.4 | L8: 2146.1 | M8: 2164.8 | N8: 2183.5 | O8: 2202.2 | P8: 2220.9 | Q8: 2239.6 | R8: 2258.3 | S8: 2277 | T8: 2282.1 | U8: 2287.2 | V8: 2292.3 | W8: 2297.4 | X8: 2302.5 | Y8: 2307.6 | Z8: 2312.7 | AA8: 2317.8 | AB8: 2322.9 | AC8: 2328 | AD8: 2326.2 | AE8: 2324.4 | AF8: 2322.6 | AG8: 2320.8 | AH8: 2319 | AI8: 2317.2 | AJ8: 2315.4 | AK8: 2313.6 | AL8: 2311.8 | AM8: 2310
A9: Interpolated | B9: 1919 | C9: 1943.4286 | D9: 1967.8571 | E9: 1992.2857 | F9: 2016.7143 | G9: 2041.1429 | H9: 2065.5714 | I9: 2090 | J9: 2108.7 | K9: 2127.4 | L9: 2146.1 | M9: 2164.8 | N9: 2183.5 | O9: 2202.2 | P9: 2220.9 | Q9: 2239.6 | R9: 2258.3 | S9: 2277 | T9: 2282.1 | U9: 2287.2 | V9: 2292.3 | W9: 2297.4 | X9: 2302.5 | Y9: 2307.6 | Z9: 2312.7 | AA9: 2317.8 | AB9: 2322.9 | AC9: 2328 | AD9: 2326.2 | AE9: 2324.4 | AF9: 2322.6 | AG9: 2320.8 | AH9: 2319 | AI9: 2317.2 | AJ9: 2315.4 | AK9: 2313.6 | AL9: 2311.8 | AM9: 2310
A10: PKM relative to start Yr | H10: 1 | I10: =I9/$H$9 -> 1.0118265 | J10: =J9/$H$9 -> 1.0208797 | K10: =K9/$H$9 -> 1.0299329 | L10: =L9/$H$9 -> 1.0389861 | M10: =M9/$H$9 -> 1.0480393 | N10: =N9/$H$9 -> 1.0570925 | O10: =O9/$H$9 -> 1.0661457 | P10: =P9/$H$9 -> 1.0751988 | ... AM10: =AM9/$H$9 -> 1.1183346

Sheet frgt-Road
A1: Notes
A2: LDV corresponds to light commercials vehicles
A3: HDV correspond to the average of all fleet, exclueded light commercials, relative to start year average
A5: table 95 from MOP report summarizes the data
A6: The table below is from the excel file that generated the results for transportation sector, this file has more detalied informations about the modelling than the report.
A8: TKU
A9: Year | B9: Light Commercials | C9: Semilight Trucks | D9: Light Trucks | E9: Medium Trucks | F9: Semi-heavy trucks | G9: Heavy Trucks | I9: LDV | J9: HDV
A10: 2012 | B10: 4.7075391e+09 | C10: 5.8644066e+09 | D10: 5.7319679e+10 | E10: 8.1071124e+10 | F10: 2.2085706e+11 | G10: 3.9277989e+11
A11: 2013 | B11: 5.1479745e+09 | C11: 6.0197796e+09 | D11: 5.953143e+10 | E11: 8.1278333e+10 | F11: 2.3541974e+11 | G11: 4.2843447e+11
A12: 2014 | B12: 5.5635887e+09 | C12: 6.010729e+09 | D12: 6.1476826e+10 | E12: 8.1183138e+10 | F12: 2.4789426e+11 | G12: 4.6231682e+11
A13: 2015 | B13: 5.9111258e+09 | C13: 5.9200485e+09 | D13: 6.2681756e+10 | E13: 8.0293549e+10 | F13: 2.5688804e+11 | G13: 4.8463645e+11
A14: 2016 | B14: 6.2108499e+09 | C14: 5.8137684e+09 | D14: 6.3620828e+10 | E14: 7.9327501e+10 | F14: 2.6476423e+11 | G14: 5.024249e+11
A15: 2017 | B15: 6.5120241e+09 | C15: 5.7215098e+09 | D15: 6.4143042e+10 | E15: 7.8549522e+10 | F15: 2.7313544e+11 | G15: 5.2136498e+11
A16: 2018 | B16: 6.8048415e+09 | C16: 5.643682e+09 | D16: 6.4683724e+10 | E16: 7.7913591e+10 | F16: 2.8160087e+11 | G16: 5.4063248e+11
A17: 2019 | B17: 7.089636e+09 | C17: 5.5847122e+09 | D17: 6.5422928e+10 | E17: 7.7385934e+10 | F17: 2.9019815e+11 | G17: 5.5874514e+11 | I17: 1 | J17: 1
A18: 2020 | B18: 7.3665913e+09 | C18: 5.5396429e+09 | D18: 6.6228648e+10 | E18: 7.7003673e+10 | F18: 2.9528233e+11 | G18: 5.701864e+11 | I18: =B18/$B$17 -> 1.0390648 | J18: =AVERAGE(C18:G18)/AVERAGE($C$17:$G$17) -> 1.016949
A19: 2021 | B19: 7.5469274e+09 | C19: 5.4640202e+09 | D19: 6.7205105e+10 | E19: 7.6284529e+10 | F19: 2.9762925e+11 | G19: 5.7470497e+11 | I19: =B19/$B$17 -> 1.0645014 | J19: =AVERAGE(C19:G19)/AVERAGE($C$17:$G$17) -> 1.024015
A20: 2022 | B20: 7.6359167e+09 | C20: 5.3550436e+09 | D20: 6.8156449e+10 | E20: 7.5201661e+10 | F20: 2.9875108e+11 | G20: 5.7591166e+11 | I20: =B20/$B$17 -> 1.0770534 | J20: =AVERAGE(C20:G20)/AVERAGE($C$17:$G$17) -> 1.0261086
A21: 2023 | B21: 7.7208566e+09 | C21: 5.2459344e+09 | D21: 6.8798746e+10 | E21: 7.4200664e+10 | F21: 2.9990049e+11 | G21: 5.7818316e+11 | I21: =B21/$B$17 -> 1.0890343 | J21: =AVERAGE(C21:G21)/AVERAGE($C$17:$G$17) -> 1.0290695
A22: 2024 | B22: 7.802168e+09 | C22: 5.1456265e+09 | D22: 6.9051338e+10 | E22: 7.3305533e+10 | F22: 3.0126726e+11 | G22: 5.8042453e+11 | I22: =B22/$B$17 -> 1.1005033 | J22: =AVERAGE(C22:G22)/AVERAGE($C$17:$G$17) -> 1.0319425
A23: 2025 | B23: 7.8801526e+09 | C23: 5.0552149e+09 | D23: 6.8996035e+10 | E23: 7.2477885e+10 | F23: 3.0364664e+11 | G23: 5.8573087e+11 | I23: =B23/$B$17 -> 1.1115031 | J23: =AVERAGE(C23:G23)/AVERAGE($C$17:$G$17) -> 1.0386728
A24: 2026 | B24: 7.9658525e+09 | C24: 4.9714351e+09 | D24: 6.8859511e+10 | E24: 7.1831839e+10 | F24: 3.0579671e+11 | G24: 5.918255e+11 | I24: =B24/$B$17 -> 1.1235912 | J24: =AVERAGE(C24:G24)/AVERAGE($C$17:$G$17) -> 1.0460708
A25: 2027 | B25: 8.0701219e+09 | C25: 4.908016e+09 | D25: 6.8880423e+10 | E25: 7.1439454e+10 | F25: 3.0865999e+11 | G25: 5.9939452e+11 | I25: =B25/$B$17 -> 1.1382985 | J25: =AVERAGE(C25:G25)/AVERAGE($C$17:$G$17) -> 1.0560949
A26: 2028 | B26: 8.1944009e+09 | C26: 4.8641038e+09 | D26: 6.8951055e+10 | E26: 7.1262968e+10 | F26: 3.1222375e+11 | G26: 6.087495e+11 | I26: =B26/$B$17 -> 1.1558282 | J26: =AVERAGE(C26:G26)/AVERAGE($C$17:$G$17) -> 1.068898
A27: 2029 | B27: 8.340316e+09 | C27: 4.8379665e+09 | D27: 6.9228733e+10 | E27: 7.1331516e+10 | F27: 3.1664522e+11 | G27: 6.1917902e+11 | I27: =B27/$B$17 -> 1.1764096 | J27: =AVERAGE(C27:G27)/AVERAGE($C$17:$G$17) -> 1.0841096
A28: 2030 | B28: 8.5097142e+09 | C28: 4.8333029e+09 | D28: 6.9702417e+10 | E28: 7.1577876e+10 | F28: 3.2047737e+11 | G28: 6.2856535e+11 | I28: =B28/$B$17 -> 1.2003034 | J28: =AVERAGE(C28:G28)/AVERAGE($C$17:$G$17) -> 1.0980806
A29: 2031 | B29: 8.7044434e+09 | C29: 4.8446498e+09 | D29: 7.0338113e+10 | E29: 7.2049475e+10 | F29: 3.2631136e+11 | G29: 6.4247566e+11 | I29: =B29/$B$17 -> 1.2277701 | J29: =AVERAGE(C29:G29)/AVERAGE($C$17:$G$17) -> 1.1189993
... A48: 2050 | B48: 1.2525953e+10 | C48: 5.6530833e+09 | D48: 9.0301627e+10 | E48: 9.2338488e+10 | F48: 4.3958953e+11 | G48: 8.8086551e+11 | I48: =B48/$B$17 -> 1.7667978 | J48: =AVERAGE(C48:G48)/AVERAGE($C$17:$G$17) -> 1.512777

Sheet frgt-Ship
A1: Notes
A2: Computed pkm relative to start year based on table 95
A3: The time series was Linear interpolated
A5: table 95 from MOP report summarizes the data
A7: Ship | B7: 2013 | C7: 2014 | D7: 2015 | E7: 2016 | F7: 2017 | G7: 2018 | H7: 2019 | I7: 2020 | J7: 2021 | K7: 2022 | L7: 2023 | M7: 2024 | N7: 2025 | O7: 2026 | P7: 2027 | Q7: 2028 | R7: 2029 | S7: 2030 | T7: 2031 | U7: 2032 | V7: 2033 | W7: 2034 | X7: 2035 | Y7: 2036 | Z7: 2037 | AA7: 2038 | AB7: 2039 | AC7: 2040 | AD7: 2041 | AE7: 2042 | AF7: 2043 | AG7: 2044 | AH7: 2045 | AI7: 2046 | AJ7: 2047 | AK7: 2048 | AL7: 2049 | AM7: 2050
A8: TKM (Millions) | B8: 203255 | C8: 213577.86 | D8: 223900.71 | E8: 234223.57 | F8: 244546.43 | G8: 254869.29 | H8: 265192.14 | I8: 275515 | J8: 287270.8 | K8: 299026.6 | L8: 310782.4 | M8: 322538.2 | N8: 334294 | O8: 346049.8 | P8: 357805.6 | Q8: 369561.4 | R8: 381317.2 | S8: 393073 | T8: 401508.1 | U8: 409943.2 | V8: 418378.3 | W8: 426813.4 | X8: 435248.5 | Y8: 443683.6 | Z8: 452118.7 | AA8: 460553.8 | AB8: 468988.9 | AC8: 477424 | AD8: 481038.4 | AE8: 484652.8 | AF8: 488267.2 | AG8: 491881.6 | AH8: 495496 | AI8: 499110.4 | AJ8: 502724.8 | AK8: 506339.2 | AL8: 509953.6 | AM8: 513568
A9: Interpolated | B9: 203255 | C9: 213577.86 | D9: 223900.71 | E9: 234223.57 | F9: 244546.43 | G9: 254869.29 | H9: 265192.14 | I9: 275515 | J9: 287270.8 | K9: 299026.6 | L9: 310782.4 | M9: 322538.2 | N9: 334294 | O9: 346049.8 | P9: 357805.6 | Q9: 369561.4 | R9: 381317.2 | S9: 393073 | T9: 401508.1 | U9: 409943.2 | V9: 418378.3 | W9: 426813.4 | X9: 435248.5 | Y9: 443683.6 | Z9: 452118.7 | AA9: 460553.8 | AB9: 468988.9 | AC9: 477424 | AD9: 481038.4 | AE9: 484652.8 | AF9: 488267.2 | AG9: 491881.6 | AH9: 495496 | AI9: 499110.4 | AJ9: 502724.8 | AK9: 506339.2 | AL9: 509953.6 | AM9: 513568
A10: PKM relative to start Yr | H10: 1 | I10: =I9/$H$9 -> 1.038926 | J10: =J9/$H$9 -> 1.0832553 | K10: =K9/$H$9 -> 1.1275847 | L10: =L9/$H$9 -> 1.1719141 | M10: =M9/$H$9 -> 1.2162434 | N10: =N9/$H$9 -> 1.2605728 | O10: =O9/$H$9 -> 1.3049022 | P10: =P9/$H$9 -> 1.3492315 | ... AM10: =AM9/$H$9 -> 1.9365883

Sheet frgt-Rail
A1: Notes
A2: Computed pkm relative to start year based on table 95
A3: The time series was Linear interpolated
A5: table 95 from MOP report summarizes the data
A7: Rail | B7: 2013 | C7: 2014 | D7: 2015 | E7: 2016 | F7: 2017 | G7: 2018 | H7: 2019 | I7: 2020 | J7: 2021 | K7: 2022 | L7: 2023 | M7: 2024 | N7: 2025 | O7: 2026 | P7: 2027 | Q7: 2028 | R7: 2029 | S7: 2030 | T7: 2031 | U7: 2032 | V7: 2033 | W7: 2034 | X7: 2035 | Y7: 2036 | Z7: 2037 | AA7: 2038 | AB7: 2039 | AC7: 2040 | AD7: 2041 | AE7: 2042 | AF7: 2043 | AG7: 2044 | AH7: 2045 | AI7: 2046 | AJ7: 2047 | AK7: 2048 | AL7: 2049 | AM7: 2050
A8: TKM (Millions) | B8: 316462 | C8: 333025.29 | D8: 349588.57 | E8: 366151.86 | F8: 382715.14 | G8: 399278.43 | H8: 415841.71 | I8: 432405 | J8: 451494.8 | K8: 470584.6 | L8: 489674.4 | M8: 508764.2 | N8: 527854 | O8: 546943.8 | P8: 566033.6 | Q8: 585123.4 | R8: 604213.2 | S8: 623303 | T8: 655393.7 | U8: 687484.4 | V8: 719575.1 | W8: 751665.8 | X8: 783756.5 | Y8: 815847.2 | Z8: 847937.9 | AA8: 880028.6 | AB8: 912119.3 | AC8: 944210 | AD8: 992182.4 | AE8: 1040154.8 | AF8: 1088127.2 | AG8: 1136099.6 | AH8: 1184072 | AI8: 1232044.4 | AJ8: 1280016.8 | AK8: 1327989.2 | AL8: 1375961.6 | AM8: 1423934
A9: Interpolated | B9: 316462 | C9: 333025.29 | D9: 349588.57 | E9: 366151.86 | F9: 382715.14 | G9: 399278.43 | H9: 415841.71 | I9: 432405 | J9: 451494.8 | K9: 470584.6 | L9: 489674.4 | M9: 508764.2 | N9: 527854 | O9: 546943.8 | P9: 566033.6 | Q9: 585123.4 | R9: 604213.2 | S9: 623303 | T9: 655393.7 | U9: 687484.4 | V9: 719575.1 | W9: 751665.8 | X9: 783756.5 | Y9: 815847.2 | Z9: 847937.9 | AA9: 880028.6 | AB9: 912119.3 | AC9: 944210 | AD9: 992182.4 | AE9: 1040154.8 | AF9: 1088127.2 | AG9: 1136099.6 | AH9: 1184072 | AI9: 1232044.4 | AJ9: 1280016.8 | AK9: 1327989.2 | AL9: 1375961.6 | AM9: 1423934
A10: PKM relative to start Yr | H10: 1 | I10: =I9/$H$9 -> 1.0398307 | J10: =J9/$H$9 -> 1.0857372 | K10: =K9/$H$9 -> 1.1316436 | L10: =L9/$H$9 -> 1.17755 | M10: =M9/$H$9 -> 1.2234564 | N10: =N9/$H$9 -> 1.2693628 | O10: =O9/$H$9 -> 1.3152692 | P10: =P9/$H$9 -> 1.3611756 | ... AM10: =AM9/$H$9 -> 3.4242212

Sheet frgt-Air
A1: Notes
A2: Computed pkm relative to start year based on table 95
A3: The time series was Linear interpolated
A5: table 95 from MOP report summarizes the data
A7: Air | B7: 2013 | C7: 2014 | D7: 2015 | E7: 2016 | F7: 2017 | G7: 2018 | H7: 2019 | I7: 2020 | J7: 2021 | K7: 2022 | L7: 2023 | M7: 2024 | N7: 2025 | O7: 2026 | P7: 2027 | Q7: 2028 | R7: 2029 | S7: 2030 | T7: 2031 | U7: 2032 | V7: 2033 | W7: 2034 | X7: 2035 | Y7: 2036 | Z7: 2037 | AA7: 2038 | AB7: 2039 | AC7: 2040 | AD7: 2041 | AE7: 2042 | AF7: 2043 | AG7: 2044 | AH7: 2045 | AI7: 2046 | AJ7: 2047 | AK7: 2048 | AL7: 2049 | AM7: 2050
A8: TKM (Millions) | B8: 8635 | C8: 8716.1429 | D8: 8797.2857 | E8: 8878.4286 | F8: 8959.5714 | G8: 9040.7143 | H8: 9121.8571 | I8: 9203 | J8: 9114.4 | K8: 9025.8 | L8: 8937.2 | M8: 8848.6 | N8: 8760 | O8: 8671.4 | P8: 8582.8 | Q8: 8494.2 | R8: 8405.6 | S8: 8317 | T8: 8442.6 | U8: 8568.2 | V8: 8693.8 | W8: 8819.4 | X8: 8945 | Y8: 9070.6 | Z8: 9196.2 | AA8: 9321.8 | AB8: 9447.4 | AC8: 9573 | AD8: 9814.3 | AE8: 10055.6 | AF8: 10296.9 | AG8: 10538.2 | AH8: 10779.5 | AI8: 11020.8 | AJ8: 11262.1 | AK8: 11503.4 | AL8: 11744.7 | AM8: 11986
A9: Interpolated | B9: 8635 | C9: 8716.1429 | D9: 8797.2857 | E9: 8878.4286 | F9: 8959.5714 | G9: 9040.7143 | H9: 9121.8571 | I9: 9203 | J9: 9114.4 | K9: 9025.8 | L9: 8937.2 | M9: 8848.6 | N9: 8760 | O9: 8671.4 | P9: 8582.8 | Q9: 8494.2 | R9: 8405.6 | S9: 8317 | T9: 8442.6 | U9: 8568.2 | V9: 8693.8 | W9: 8819.4 | X9: 8945 | Y9: 9070.6 | Z9: 9196.2 | AA9: 9321.8 | AB9: 9447.4 | AC9: 9573 | AD9: 9814.3 | AE9: 10055.6 | AF9: 10296.9 | AG9: 10538.2 | AH9: 10779.5 | AI9: 11020.8 | AJ9: 11262.1 | AK9: 11503.4 | AL9: 11744.7 | AM9: 11986
A10: PKM relative to start Yr | H10: 1 | I10: =I9/$H$9 -> 1.0088954 | J10: =J9/$H$9 -> 0.9991825 | K10: =K9/$H$9 -> 0.98946956 | L10: =L9/$H$9 -> 0.97975663 | M10: =M9/$H$9 -> 0.97004369 | N10: =N9/$H$9 -> 0.96033076 | O10: =O9/$H$9 -> 0.95061783 | P10: =P9/$H$9 -> 0.94090489 | ... AM10: =AM9/$H$9 -> 1.3139868

Sheet Evidence 2019-2025
A1: Observed Brazilian transport data used to adjust the MCTIC (2017) BAU projections
A2: Blue = value typed from the cited source. Black = formula. Edit any blue cell and every downstream result updates.
A4: Item | B4: Value | C4: Unit | D4: Year | E4: Source (publisher, document, URL) | F4: Note
A5: Diesel B sales | B5: 57.47 | C5: bn litres | D5: 2020 | E5: ANP, "Comercialização de combustíveis em 2020 teve queda de 5,97%", https://www.gov.br/anp/pt-br/canais_atendimento/imprensa/noticias-comunicados/comercializacao-de-combustiveis-em-2020-teve-queda-de-5-97-na-comparacao-com-2019-devido-a-pandemia
A6: Diesel B change 2020 vs 2019 | B6: 0.003 | C6: fraction | D6: 2020 | E6: ANP (same release) | F6: +0.30%
A7: Diesel B sales | B7: 67.25 | C7: bn litres | D7: 2024 | E7: ANP, "País teve comercialização de mais de 130 bilhões de litros de combustíveis em 2024", https://www.gov.br/anp/pt-br/canais_atendimento/imprensa/noticias-comunicados/pais-teve-comercializacao-de-mais-de-130-bilhoes-de-litros-de-combustiveis-em-2024
A8: Gasoline C sales | B8: 35.82 | C8: bn litres | D8: 2020 | E8: ANP 2020 release (above)
A9: Gasoline C change 2020 vs 2019 | B9: -0.0613 | C9: fraction | D9: 2020 | E9: ANP 2020 release (above) | F9: -6.13%
A10: Gasoline C sales | B10: 44.19 | C10: bn litres | D10: 2024 | E10: ANP 2024 release (above)
A11: Hydrous ethanol sales | B11: 19.26 | C11: bn litres | D11: 2020 | E11: ANP 2020 release (above)
A12: Hydrous ethanol change 2020 vs 2019 | B12: -0.1458 | C12: fraction | D12: 2020 | E12: ANP 2020 release (above) | F12: -14.58%
A13: Hydrous ethanol sales | B13: 21.66 | C13: bn litres | D13: 2024 | E13: ANP 2024 release (above)
A14: Hydrous ethanol : gasoline C distance equivalence | B14: 0.7 | C14: ratio | D14: - | E14: ASSUMPTION: the usual Brazilian 70% price-parity rule, i.e. 1 L ethanol drives ~0.7 of the distance of 1 L gasoline C | F14: Used to convert light-fuel litres into a vehicle-km proxy
A15: Domestic air RPK change 2020 vs 2019 | B15: -0.487 | C15: fraction | D15: 2020 | E15: ANAC, "Com pandemia indicadores do setor aéreo reduzem 50% em 2020", https://www.anac.gov.br/noticias/2021/com-pandemia-indicadores-do-setor-aereo-reduzem-50-em-2020-1 | F15: -48.7%
A16: Domestic air passengers change 2025 vs 2019 | B16: 0.053 | C16: fraction | D16: 2025 | E16: ANAC, "Com quase 130 milhões de viajantes...", https://www.gov.br/anac/pt-br/noticias/2026/com-quase-130-milhoes-de-viajantes-aviacao-alcanca-melhores-indices-de-movimentacao-de-passageiros-da-historia | F16: Passengers, used as RPK proxy (+5.3%)
A17: Domestic air cargo | B17: 324438 | C17: tonnes | D17: 2020 | E17: ANAC 2020 release (above)
A18: Domestic air cargo change 2020 vs 2019 | B18: -0.283 | C18: fraction | D18: 2020 | E18: ANAC 2020 release (above) | F18: -28.3%
A19: Domestic air cargo | B19: 488000 | C19: tonnes | D19: 2024 | E19: ANAC, "Com 118 milhões de passageiros transportados em 2024...", https://www.gov.br/anac/pt-br/noticias/2025/com-118-milhoes-de-passageiros-transportados-em-2024-setor-aereo-tem-segundo-melhor-desempenhos-da-his | F19: Tonnes, used as tonne-km proxy
A20: Rail freight production | B20: 366 | C20: bn TKU | D20: 2019 | E20: ANTF (2019) as cited in Revista Conecta v.3 (2020), https://fatecrl.edu.br/revistaconecta/index.php/rc/article/download/18/14/25 | F20: Secondary citation of ANTF
A21: Rail freight production | B21: 365.1 | C21: bn TKU | D21: 2020 | E21: ANTF, cited by FTC, https://www.ftc.com.br/detalhe/786
A22: Rail freight production | B22: 371.1 | C22: bn TKU | D22: 2022 | E22: ANTF, "Carga geral: expansão anual média chega a 4,1%", https://www.antf.org.br/carga-geral-expansao-anual-media-chega-a-41/
A23: Port cargo handled | B23: 1.151 | C23: bn tonnes | D23: 2020 | E23: ANTAQ, "Movimentação portuária cresce 4,2% em 2020", https://www.gov.br/antaq/pt-br/noticias/2021/movimentacao-portuaria-cresce-4-2-em-2020 | F23: Tonnes, used as ship tonne-km proxy
A24: Port cargo change 2020 vs 2019 | B24: 0.042 | C24: fraction | D24: 2020 | E24: ANTAQ 2020 release (above) | F24: +4.2%
A25: Port cargo handled | B25: 1.32 | C25: bn tonnes | D25: 2024 | E25: ANTAQ, "Recorde nos portos...2024", https://www.gov.br/antaq/pt-br/noticias/2025/recorde-nos-portos-setor-aquaviario-movimenta-mais-de-1-32-bi-de-toneladas-em-2024
A26: Metro/urban rail passengers | B26: 3.3 | C26: bn trips | D26: 2019 | E26: ANPTrilhos Balanço 2020-2021, via Diário do Transporte, https://diariodotransporte.com.br/2021/04/23/setor-de-trilhos-transportou-16-bilhao-de-passageiros-a-menos-em-2020-sete-vezes-a-populacao-do-brasil/
A27: Metro/urban rail passengers change 2020 vs 2019 | B27: -0.467 | C27: fraction | D27: 2020 | E27: ANPTrilhos (same source) | F27: -46.7%
A28: Metro/urban rail passengers | B28: 2.57 | C28: bn trips | D28: 2024 | E28: ANPTrilhos, "Balanço Metroferroviário 2024", https://anptrilhos.org.br/balanco-metroferroviario-2024-transporte-sobre-trilhos-cresce-e-transporta-257-bilhoes-de-passageiros/ | F28: Trips, used as pkm proxy
A29: Urban bus paying passengers change 2020 vs 2019 | B29: -0.511 | C29: fraction | D29: 2020 | E29: NTU Anuário 2020-2021, via Exame, https://exame.com/bussola/com-pandemia-numero-de-passageiros-de-onibus-urbanos-cai-51/ | F29: Nine state capitals
A30: Urban bus passengers change 2024 vs 2019 | B30: -0.195 | C30: fraction | D30: 2024 | E30: NTU Anuário 2024-2025, https://ntu.org.br/ntu-urbano/7/ainda-em-recuperacao | F30: -19.5%
A31: Interstate bus passengers | B31: 90 | C31: million | D31: 2019 | E31: ANTT, TRIIP presentation, https://portal.antt.gov.br/en/resultado/-/asset_publisher/m2By5inRuGGs/content/id/2469286 | F31: "more than 90 million"
A32: Interstate bus passengers | B32: 46 | C32: million | D32: 2020 | E32: ANTT (same source) | F32: "more than 46 million"
A34: Derived 2019 base values (formulas)
A35: Diesel B sales 2019 (back-calculated) | B35: =B5/(1+B6) -> 57.298106 | C35: bn litres
A36: Gasoline C sales 2019 (back-calculated) | B36: =B8/(1+B9) -> 38.159156 | C36: bn litres
A37: Hydrous ethanol sales 2019 (back-calculated) | B37: =B11/(1+B12) -> 22.547413 | C37: bn litres
A38: Domestic air cargo 2019 (back-calculated) | B38: =B17/(1+B18) -> 452493.72 | C38: tonnes
A39: Port cargo 2019 (back-calculated) | B39: =B23/(1+B24) -> 1.1046065 | C39: bn tonnes
A40: Light-fuel distance proxy 2019 = gasoline + k x ethanol | B40: =B36+B14*B37 -> 53.942345 | C40: bn L gasoline-eq.
A41: Light-fuel distance proxy 2020 | B41: =B8+B14*B11 -> 49.302 | C41: bn L gasoline-eq.
A42: Light-fuel distance proxy 2024 | B42: =B10+B14*B13 -> 59.352 | C42: bn L gasoline-eq.
...

Sheet BAU Adjustment
A1: BAU adjustment: MCTIC (2017) projections calibrated to observed 2020 shock and latest observed year
A2: Method. O(t) = original MCTIC ratio to 2019. S = 2020 value used (user input 1.15, Evidence G61). C = observed index in calibration year Tc (sheet "Evidence 2019-2025").
A3: Multiplier m(2020) = S / O(2020); m(Tc) = C / O(Tc); m(t) moves linearly from m(2020) to m(Tc) between 2020 and Tc, and stays at m(Tc) after Tc.
A4: Adjusted(t) = O(t) x m(t). So 2019 = 1, 2020 = observed value, Tc = observed value, and after Tc the MCTIC growth rates apply from the observed level.
A6: Passenger: original MCTIC ratios O(t) | AI6: S = 2020 value used (Evidence col G)
A7: Mode | B7: 2019 | C7: 2020 | D7: 2021 | E7: 2022 | F7: 2023 | G7: 2024 | H7: 2025 | I7: 2026 | J7: 2027 | K7: 2028 | L7: 2029 | M7: 2030 | N7: 2031 | O7: 2032 | P7: 2033 | Q7: 2034 | R7: 2035 | S7: 2036 | T7: 2037 | U7: 2038 | V7: 2039 | W7: 2040 | X7: 2041 | Y7: 2042 | Z7: 2043 | AA7: 2044 | AB7: 2045 | AC7: 2046 | AD7: 2047 | AE7: 2048 | AF7: 2049 | AG7: 2050 | AI7: S (2020 obs.) | AJ7: Tc | AK7: C (Tc obs.) | AL7: m(2020) | AM7: m(Tc)
A8: LDVs | B8: ='psgr-Road'!F27 -> 1 | C8: ='psgr-Road'!G27 -> 1.0454463 | D8: ='psgr-Road'!H27 -> 1.0902936 | E8: ='psgr-Road'!I27 -> 1.1348406 | F8: ='psgr-Road'!J27 -> 1.1791133 | G8: ='psgr-Road'!K27 -> 1.2231701 | H8: ='psgr-Road'!L27 -> 1.265733 | I8: ='psgr-Road'!M27 -> 1.3056969 | ... AG8: ='psgr-Road'!AK27 -> 1.725077 | AI8: ='Evidence 2019-2025'!G47 -> 1.15 | AJ8: ='Evidence 2019-2025'!D47 -> 2024 | AK8: ='Evidence 2019-2025'!E47 -> 1.1002859 | AL8: =IF($C8=0,1,AI8/$C8) -> 1.1000087 | AM8: =IF(INDEX($B8:$AG8,1,AJ8-2018)=0,1,AK8/INDEX($B8:$AG8,1,AJ8-2018)) -> 0.89953629
A9: HDVs | B9: ='psgr-Road'!F29 -> 1 | C9: ='psgr-Road'!G29 -> 1.0334154 | D9: ='psgr-Road'!H29 -> 1.0662515 | E9: ='psgr-Road'!I29 -> 1.0987956 | F9: ='psgr-Road'!J29 -> 1.130891 | G9: ='psgr-Road'!K29 -> 1.1624396 | H9: ='psgr-Road'!L29 -> 1.1934822 | I9: ='psgr-Road'!M29 -> 1.2239426 | ... AG9: ='psgr-Road'!AK29 -> 1.941439 | AI9: ='Evidence 2019-2025'!G48 -> 1.15 | AJ9: ='Evidence 2019-2025'!D48 -> 2024 | AK9: ='Evidence 2019-2025'!E48 -> 0.805 | AL9: =IF($C9=0,1,AI9/$C9) -> 1.1128148 | AM9: =IF(INDEX($B9:$AG9,1,AJ9-2018)=0,1,AK9/INDEX($B9:$AG9,1,AJ9-2018)) -> 0.69250908
A10: aircraft | B10: ='psgr-Air'!H11 -> 1 | C10: ='psgr-Air'!I11 -> 1.0551903 | D10: ='psgr-Air'!J11 -> 1.113205 | E10: ='psgr-Air'!K11 -> 1.1744093 | F10: ='psgr-Air'!L11 -> 1.2389787 | G10: ='psgr-Air'!M11 -> 1.3070982 | H10: ='psgr-Air'!N11 -> 1.3789628 | I10: ='psgr-Air'!O11 -> 1.4501686 | ... AG10: ='psgr-Air'!AM11 -> 3.28829 | AI10: ='Evidence 2019-2025'!G49 -> 1.15 | AJ10: ='Evidence 2019-2025'!D49 -> 2025 | AK10: ='Evidence 2019-2025'!E49 -> 1.053 | AL10: =IF($C10=0,1,AI10/$C10) -> 1.0898508 | AM10: =IF(INDEX($B10:$AG10,1,AJ10-2018)=0,1,AK10/INDEX($B10:$AG10,1,AJ10-2018)) -> 0.7636174
A11: rail | B11: ='psgr-Rail'!H10 -> 1 | C11: ='psgr-Rail'!I10 -> 1.0096154 | D11: ='psgr-Rail'!J10 -> 1.0769231 | E11: ='psgr-Rail'!K10 -> 1.1442308 | F11: ='psgr-Rail'!L10 -> 1.2115385 | G11: ='psgr-Rail'!M10 -> 1.2788462 | H11: ='psgr-Rail'!N10 -> 1.3461538 | I11: ='psgr-Rail'!O10 -> 1.4134615 | ... AG11: ='psgr-Rail'!AM10 -> 3.0288462 | AI11: ='Evidence 2019-2025'!G50 -> 1.15 | AJ11: ='Evidence 2019-2025'!D50 -> 2024 | AK11: ='Evidence 2019-2025'!E50 -> 0.77878788 | AL11: =IF($C11=0,1,AI11/$C11) -> 1.1390476 | AM11: =IF(INDEX($B11:$AG11,1,AJ11-2018)=0,1,AK11/INDEX($B11:$AG11,1,AJ11-2018)) -> 0.60897699
A12: ships | B12: ='psgr-Ship'!H10 -> 1 | C12: ='psgr-Ship'!I10 -> 1.0118265 | D12: ='psgr-Ship'!J10 -> 1.0208797 | E12: ='psgr-Ship'!K10 -> 1.0299329 | F12: ='psgr-Ship'!L10 -> 1.0389861 | G12: ='psgr-Ship'!M10 -> 1.0480393 | H12: ='psgr-Ship'!N10 -> 1.0570925 | I12: ='psgr-Ship'!O10 -> 1.0661457 | ... AG12: ='psgr-Ship'!AM10 -> 1.1183346 | AI12: ='Evidence 2019-2025'!G51 -> 1.15 | AJ12: ='Evidence 2019-2025'!D51 -> 2024 | AK12: ='Evidence 2019-2025'!E51 -> 0.77878788 | AL12: =IF($C12=0,1,AI12/$C12) -> 1.1365584 | AM12: =IF(INDEX($B12:$AG12,1,AJ12-2018)=0,1,AK12/INDEX($B12:$AG12,1,AJ12-2018)) -> 0.74309035
A13: motorbikes | B13: ='psgr-Road'!F31 -> 1 | C13: ='psgr-Road'!G31 -> 1.0490352 | D13: ='psgr-Road'!H31 -> 1.1023855 | E13: ='psgr-Road'!I31 -> 1.1604893 | F13: ='psgr-Road'!J31 -> 1.223505 | G13: ='psgr-Road'!K31 -> 1.2912926 | H13: ='psgr-Road'!L31 -> 1.3587913 | I13: ='psgr-Road'!M31 -> 1.4217727 | ... AG13: ='psgr-Road'!AK31 -> 2.0592163 | AI13: ='Evidence 2019-2025'!G52 -> 1.15 | AJ13: ='Evidence 2019-2025'!D52 -> 2024 | AK13: ='Evidence 2019-2025'!E52 -> 1.1002859 | AL13: =IF($C13=0,1,AI13/$C13) -> 1.0962454 | AM13: =IF(INDEX($B13:$AG13,1,AJ13-2018)=0,1,AK13/INDEX($B13:$AG13,1,AJ13-2018)) -> 0.85208101
A15: Passenger: multiplier m(t)
B16: 2019 | C16: 2020 | D16: 2021 | E16: 2022 | F16: 2023 | G16: 2024 | H16: 2025 | I16: 2026 | J16: 2027 | K16: 2028 | L16: 2029 | M16: 2030 | N16: 2031 | O16: 2032 | P16: 2033 | Q16: 2034 | R16: 2035 | S16: 2036 | T16: 2037 | U16: 2038 | V16: 2039 | W16: 2040 | X16: 2041 | Y16: 2042 | Z16: 2043 | AA16: 2044 | AB16: 2045 | AC16: 2046 | AD16: 2047 | AE16: 2048 | AF16: 2049 | AG16: 2050
A17: LDVs | B17: 1 | C17: =IF(C$16>=$AJ$8,$AM$8,$AL$8+($AM$8-$AL$8)*(C$16-2020)/($AJ$8-2020)) -> 1.1000087 | D17: =IF(D$16>=$AJ$8,$AM$8,$AL$8+($AM$8-$AL$8)*(D$16-2020)/($AJ$8-2020)) -> 1.0498906 | E17: =IF(E$16>=$AJ$8,$AM$8,$AL$8+($AM$8-$AL$8)*(E$16-2020)/($AJ$8-2020)) -> 0.99977251 | F17: =IF(F$16>=$AJ$8,$AM$8,$AL$8+($AM$8-$AL$8)*(F$16-2020)/($AJ$8-2020)) -> 0.9496544 | G17: =IF(G$16>=$AJ$8,$AM$8,$AL$8+($AM$8-$AL$8)*(G$16-2020)/($AJ$8-2020)) -> 0.89953629 | H17: =IF(H$16>=$AJ$8,$AM$8,$AL$8+($AM$8-$AL$8)*(H$16-2020)/($AJ$8-2020)) -> 0.89953629 | I17: =IF(I$16>=$AJ$8,$AM$8,$AL$8+($AM$8-$AL$8)*(I$16-2020)/($AJ$8-2020)) -> 0.89953629 | J17: =IF(J$16>=$AJ$8,$AM$8,$AL$8+($AM$8-$AL$8)*(J$16-2020)/($AJ$8-2020)) -> 0.89953629 | ... AG17: =IF(AG$16>=$AJ$8,$AM$8,$AL$8+($AM$8-$AL$8)*(AG$16-2020)/($AJ$8-2020)) -> 0.89953629
A18: HDVs | B18: 1 | C18: =IF(C$16>=$AJ$9,$AM$9,$AL$9+($AM$9-$AL$9)*(C$16-2020)/($AJ$9-2020)) -> 1.1128148 | D18: =IF(D$16>=$AJ$9,$AM$9,$AL$9+($AM$9-$AL$9)*(D$16-2020)/($AJ$9-2020)) -> 1.0077384 | E18: =IF(E$16>=$AJ$9,$AM$9,$AL$9+($AM$9-$AL$9)*(E$16-2020)/($AJ$9-2020)) -> 0.90266194 | F18: =IF(F$16>=$AJ$9,$AM$9,$AL$9+($AM$9-$AL$9)*(F$16-2020)/($AJ$9-2020)) -> 0.79758551 | G18: =IF(G$16>=$AJ$9,$AM$9,$AL$9+($AM$9-$AL$9)*(G$16-2020)/($AJ$9-2020)) -> 0.69250908 | H18: =IF(H$16>=$AJ$9,$AM$9,$AL$9+($AM$9-$AL$9)*(H$16-2020)/($AJ$9-2020)) -> 0.69250908 | I18: =IF(I$16>=$AJ$9,$AM$9,$AL$9+($AM$9-$AL$9)*(I$16-2020)/($AJ$9-2020)) -> 0.69250908 | J18: =IF(J$16>=$AJ$9,$AM$9,$AL$9+($AM$9-$AL$9)*(J$16-2020)/($AJ$9-2020)) -> 0.69250908 | ... AG18: =IF(AG$16>=$AJ$9,$AM$9,$AL$9+($AM$9-$AL$9)*(AG$16-2020)/($AJ$9-2020)) -> 0.69250908
A19: aircraft | B19: 1 | C19: =IF(C$16>=$AJ$10,$AM$10,$AL$10+($AM$10-$AL$10)*(C$16-2020)/($AJ$10-2020)) -> 1.0898508 | D19: =IF(D$16>=$AJ$10,$AM$10,$AL$10+($AM$10-$AL$10)*(D$16-2020)/($AJ$10-2020)) -> 1.0246041 | E19: =IF(E$16>=$AJ$10,$AM$10,$AL$10+($AM$10-$AL$10)*(E$16-2020)/($AJ$10-2020)) -> 0.95935744 | F19: =IF(F$16>=$AJ$10,$AM$10,$AL$10+($AM$10-$AL$10)*(F$16-2020)/($AJ$10-2020)) -> 0.89411076 | G19: =IF(G$16>=$AJ$10,$AM$10,$AL$10+($AM$10-$AL$10)*(G$16-2020)/($AJ$10-2020)) -> 0.82886408 | H19: =IF(H$16>=$AJ$10,$AM$10,$AL$10+($AM$10-$AL$10)*(H$16-2020)/($AJ$10-2020)) -> 0.7636174 | I19: =IF(I$16>=$AJ$10,$AM$10,$AL$10+($AM$10-$AL$10)*(I$16-2020)/($AJ$10-2020)) -> 0.7636174 | J19: =IF(J$16>=$AJ$10,$AM$10,$AL$10+($AM$10-$AL$10)*(J$16-2020)/($AJ$10-2020)) -> 0.7636174 | ... AG19: =IF(AG$16>=$AJ$10,$AM$10,$AL$10+($AM$10-$AL$10)*(AG$16-2020)/($AJ$10-2020)) -> 0.7636174
A20: rail | B20: 1 | C20: =IF(C$16>=$AJ$11,$AM$11,$AL$11+($AM$11-$AL$11)*(C$16-2020)/($AJ$11-2020)) -> 1.1390476 | D20: =IF(D$16>=$AJ$11,$AM$11,$AL$11+($AM$11-$AL$11)*(D$16-2020)/($AJ$11-2020)) -> 1.00653 | E20: =IF(E$16>=$AJ$11,$AM$11,$AL$11+($AM$11-$AL$11)*(E$16-2020)/($AJ$11-2020)) -> 0.8740123 | F20: =IF(F$16>=$AJ$11,$AM$11,$AL$11+($AM$11-$AL$11)*(F$16-2020)/($AJ$11-2020)) -> 0.74149465 | G20: =IF(G$16>=$AJ$11,$AM$11,$AL$11+($AM$11-$AL$11)*(G$16-2020)/($AJ$11-2020)) -> 0.60897699 | H20: =IF(H$16>=$AJ$11,$AM$11,$AL$11+($AM$11-$AL$11)*(H$16-2020)/($AJ$11-2020)) -> 0.60897699 | I20: =IF(I$16>=$AJ$11,$AM$11,$AL$11+($AM$11-$AL$11)*(I$16-2020)/($AJ$11-2020)) -> 0.60897699 | J20: =IF(J$16>=$AJ$11,$AM$11,$AL$11+($AM$11-$AL$11)*(J$16-2020)/($AJ$11-2020)) -> 0.60897699 | ... AG20: =IF(AG$16>=$AJ$11,$AM$11,$AL$11+($AM$11-$AL$11)*(AG$16-2020)/($AJ$11-2020)) -> 0.60897699
A21: ships | B21: 1 | C21: =IF(C$16>=$AJ$12,$AM$12,$AL$12+($AM$12-$AL$12)*(C$16-2020)/($AJ$12-2020)) -> 1.1365584 | D21: =IF(D$16>=$AJ$12,$AM$12,$AL$12+($AM$12-$AL$12)*(D$16-2020)/($AJ$12-2020)) -> 1.0381914 | E21: =IF(E$16>=$AJ$12,$AM$12,$AL$12+($AM$12-$AL$12)*(E$16-2020)/($AJ$12-2020)) -> 0.9398244 | F21: =IF(F$16>=$AJ$12,$AM$12,$AL$12+($AM$12-$AL$12)*(F$16-2020)/($AJ$12-2020)) -> 0.84145737 | G21: =IF(G$16>=$AJ$12,$AM$12,$AL$12+($AM$12-$AL$12)*(G$16-2020)/($AJ$12-2020)) -> 0.74309035 | H21: =IF(H$16>=$AJ$12,$AM$12,$AL$12+($AM$12-$AL$12)*(H$16-2020)/($AJ$12-2020)) -> 0.74309035 | I21: =IF(I$16>=$AJ$12,$AM$12,$AL$12+($AM$12-$AL$12)*(I$16-2020)/($AJ$12-2020)) -> 0.74309035 | J21: =IF(J$16>=$AJ$12,$AM$12,$AL$12+($AM$12-$AL$12)*(J$16-2020)/($AJ$12-2020)) -> 0.74309035 | ... AG21: =IF(AG$16>=$AJ$12,$AM$12,$AL$12+($AM$12-$AL$12)*(AG$16-2020)/($AJ$12-2020)) -> 0.74309035
A22: motorbikes | B22: 1 | C22: =IF(C$16>=$AJ$13,$AM$13,$AL$13+($AM$13-$AL$13)*(C$16-2020)/($AJ$13-2020)) -> 1.0962454 | D22: =IF(D$16>=$AJ$13,$AM$13,$AL$13+($AM$13-$AL$13)*(D$16-2020)/($AJ$13-2020)) -> 1.0352043 | E22: =IF(E$16>=$AJ$13,$AM$13,$AL$13+($AM$13-$AL$13)*(E$16-2020)/($AJ$13-2020)) -> 0.97416322 | F22: =IF(F$16>=$AJ$13,$AM$13,$AL$13+($AM$13-$AL$13)*(F$16-2020)/($AJ$13-2020)) -> 0.91312211 | G22: =IF(G$16>=$AJ$13,$AM$13,$AL$13+($AM$13-$AL$13)*(G$16-2020)/($AJ$13-2020)) -> 0.85208101 | H22: =IF(H$16>=$AJ$13,$AM$13,$AL$13+($AM$13-$AL$13)*(H$16-2020)/($AJ$13-2020)) -> 0.85208101 | I22: =IF(I$16>=$AJ$13,$AM$13,$AL$13+($AM$13-$AL$13)*(I$16-2020)/($AJ$13-2020)) -> 0.85208101 | J22: =IF(J$16>=$AJ$13,$AM$13,$AL$13+($AM$13-$AL$13)*(J$16-2020)/($AJ$13-2020)) -> 0.85208101 | ... AG22: =IF(AG$16>=$AJ$13,$AM$13,$AL$13+($AM$13-$AL$13)*(AG$16-2020)/($AJ$13-2020)) -> 0.85208101
A24: Passenger: ADJUSTED ratio = O(t) x m(t) (linked to blue sheet)
B25: 2019 | C25: 2020 | D25: 2021 | E25: 2022 | F25: 2023 | G25: 2024 | H25: 2025 | I25: 2026 | J25: 2027 | K25: 2028 | L25: 2029 | M25: 2030 | N25: 2031 | O25: 2032 | P25: 2033 | Q25: 2034 | R25: 2035 | S25: 2036 | T25: 2037 | U25: 2038 | V25: 2039 | W25: 2040 | X25: 2041 | Y25: 2042 | Z25: 2043 | AA25: 2044 | AB25: 2045 | AC25: 2046 | AD25: 2047 | AE25: 2048 | AF25: 2049 | AG25: 2050
A26: LDVs | B26: =B8*B17 -> 1 | C26: =C8*C17 -> 1.15 | D26: =D8*D17 -> 1.144689 | E26: =E8*E17 -> 1.1345825 | F26: =F8*F17 -> 1.1197502 | G26: =G8*G17 -> 1.1002859 | H26: =H8*H17 -> 1.1385728 | I26: =I8*I17 -> 1.1745218 | ... AG26: =AG8*AG17 -> 1.5517693
A27: HDVs | B27: =B9*B18 -> 1 | C27: =C9*C18 -> 1.15 | D27: =D9*D18 -> 1.0745026 | E27: =E9*E18 -> 0.99184096 | F27: =F9*F18 -> 0.90198224 | G27: =G9*G18 -> 0.805 | H27: =H9*H18 -> 0.82649723 | I27: =I9*I18 -> 0.84759135 | ... AG27: =AG9*AG18 -> 1.3444641
A28: aircraft | B28: =B10*B19 -> 1 | C28: =C10*C19 -> 1.15 | D28: =D10*D19 -> 1.1405944 | E28: =E10*E19 -> 1.1266783 | F28: =F10*F19 -> 1.1077842 | G28: =G10*G19 -> 1.0834067 | H28: =H10*H19 -> 1.053 | I28: =I10*I19 -> 1.107374 | ... AG28: =AG10*AG19 -> 2.5109954
A29: rail | B29: =B11*B20 -> 1 | C29: =C11*C20 -> 1.15 | D29: =D11*D20 -> 1.0839553 | E29: =E11*E20 -> 1.0000718 | F29: =F11*F20 -> 0.89834928 | G29: =G11*G20 -> 0.77878788 | H29: =H11*H20 -> 0.81977671 | I29: =I11*I20 -> 0.86076555 | ... AG29: =AG11*AG20 -> 1.8444976
A30: ships | B30: =B12*B21 -> 1 | C30: =C12*C21 -> 1.15 | D30: =D12*D21 -> 1.0598686 | E30: =E12*E21 -> 0.96795608 | F30: =F12*F21 -> 0.87426251 | G30: =G12*G21 -> 0.77878788 | H30: =H12*H21 -> 0.78551521 | I30: =I12*I21 -> 0.79224255 | ... AG30: =AG12*AG21 -> 0.83102365
A31: motorbikes | B31: =B13*B22 -> 1 | C31: =C13*C22 -> 1.15 | D31: =D13*D22 -> 1.1411942 | E31: =E13*E22 -> 1.130506 | F31: =F13*F22 -> 1.1172095 | G31: =G13*G22 -> 1.1002859 | H31: =H13*H22 -> 1.1578002 | I31: =I13*I22 -> 1.2114655 | ... AG31: =AG13*AG22 -> 1.7546191
A33: Freight: original MCTIC ratios O(t)
A34: Mode | B34: 2019 | C34: 2020 | D34: 2021 | E34: 2022 | F34: 2023 | G34: 2024 | H34: 2025 | I34: 2026 | J34: 2027 | K34: 2028 | L34: 2029 | M34: 2030 | N34: 2031 | O34: 2032 | P34: 2033 | Q34: 2034 | R34: 2035 | S34: 2036 | T34: 2037 | U34: 2038 | V34: 2039 | W34: 2040 | X34: 2041 | Y34: 2042 | Z34: 2043 | AA34: 2044 | AB34: 2045 | AC34: 2046 | AD34: 2047 | AE34: 2048 | AF34: 2049 | AG34: 2050 | AI34: S (2020 obs.) | AJ34: Tc | AK34: C (Tc obs.) | AL34: m(2020) | AM34: m(Tc)
A35: LDVs | B35: ='frgt-Road'!I17 -> 1 | C35: ='frgt-Road'!I18 -> 1.0390648 | D35: ='frgt-Road'!I19 -> 1.0645014 | E35: ='frgt-Road'!I20 -> 1.0770534 | F35: ='frgt-Road'!I21 -> 1.0890343 | G35: ='frgt-Road'!I22 -> 1.1005033 | H35: ='frgt-Road'!I23 -> 1.1115031 | I35: ='frgt-Road'!I24 -> 1.1235912 | J35: ='frgt-Road'!I25 -> 1.1382985 | K35: ='frgt-Road'!I26 -> 1.1558282 | L35: ='frgt-Road'!I27 -> 1.1764096 | M35: ='frgt-Road'!I28 -> 1.2003034 | N35: ='frgt-Road'!I29 -> 1.2277701 | O35: ='frgt-Road'!I30 -> 1.2576048 | P35: ='frgt-Road'!I31 -> 1.2878888 | Q35: ='frgt-Road'!I32 -> 1.3180439 | R35: ='frgt-Road'!I33 -> 1.3480599 | S35: ='frgt-Road'!I34 -> 1.377502 | T35: ='frgt-Road'!I35 -> 1.4063865 | U35: ='frgt-Road'!I36 -> 1.435101 | V35: ='frgt-Road'!I37 -> 1.4635761 | W35: ='frgt-Road'!I38 -> 1.4917624 | X35: ='frgt-Road'!I39 -> 1.5221694 | Y35: ='frgt-Road'!I40 -> 1.5573085 | Z35: ='frgt-Road'!I41 -> 1.5957099 | AA35: ='frgt-Road'!I42 -> 1.6346693 | AB35: ='frgt-Road'!I43 -> 1.6730168 | AC35: ='frgt-Road'!I44 -> 1.7004016 | AD35: ='frgt-Road'!I45 -> 1.7173719 | AE35: ='frgt-Road'!I46 -> 1.7340562 | AF35: ='frgt-Road'!I47 -> 1.7505123 | AG35: ='frgt-Road'!I48 -> 1.7667978 | AI35: ='Evidence 2019-2025'!G53 -> 1.15 | AJ35: ='Evidence 2019-2025'!D53 -> 2024 | AK35: ='Evidence 2019-2025'!E53 -> 1.1736863 | AL35: =IF($C35=0,1,AI35/$C35) -> 1.1067645 | AM35: =IF(INDEX($B35:$AG35,1,AJ35-2018)=0,1,AK35/INDEX($B35:$AG35,1,AJ35-2018)) -> 1.0664995
A36: HDVs | B36: ='frgt-Road'!J17 -> 1 | C36: ='frgt-Road'!J18 -> 1.016949 | D36: ='frgt-Road'!J19 -> 1.024015 | E36: ='frgt-Road'!J20 -> 1.0261086 | F36: ='frgt-Road'!J21 -> 1.0290695 | G36: ='frgt-Road'!J22 -> 1.0319425 | H36: ='frgt-Road'!J23 -> 1.0386728 | I36: ='frgt-Road'!J24 -> 1.0460708 | J36: ='frgt-Road'!J25 -> 1.0560949 | K36: ='frgt-Road'!J26 -> 1.068898 | L36: ='frgt-Road'!J27 -> 1.0841096 | M36: ='frgt-Road'!J28 -> 1.0980806 | N36: ='frgt-Road'!J29 -> 1.1189993 | O36: ='frgt-Road'!J30 -> 1.1415111 | P36: ='frgt-Road'!J31 -> 1.1643353 | Q36: ='frgt-Road'!J32 -> 1.1869056 | R36: ='frgt-Road'!J33 -> 1.2045401 | S36: ='frgt-Road'!J34 -> 1.226085 | T36: ='frgt-Road'!J35 -> 1.2472521 | U36: ='frgt-Road'!J36 -> 1.268299 | V36: ='frgt-Road'!J37 -> 1.2892133 | W36: ='frgt-Road'!J38 -> 1.3049547 | X36: ='frgt-Road'!J39 -> 1.3293879 | Y36: ='frgt-Road'!J40 -> 1.3575016 | Z36: ='frgt-Road'!J41 -> 1.3882643 | AA36: ='frgt-Road'!J42 -> 1.4194877 | AB36: ='frgt-Road'!J43 -> 1.4390183 | AC36: ='frgt-Road'!J44 -> 1.4618532 | AD36: ='frgt-Road'!J45 -> 1.4774159 | AE36: ='frgt-Road'!J46 -> 1.4928984 | AF36: ='frgt-Road'!J47 -> 1.5087759 | AG36: ='frgt-Road'!J48 -> 1.512777 | AI36: ='Evidence 2019-2025'!G54 -> 1.15 | AJ36: ='Evidence 2019-2025'!D54 -> 2024 | AK36: ='Evidence 2019-2025'!E54 -> 1.1736863 | AL36: =IF($C36=0,1,AI36/$C36) -> 1.1308335 | AM36: =IF(INDEX($B36:$AG36,1,AJ36-2018)=0,1,AK36/INDEX($B36:$AG36,1,AJ36-2018)) -> 1.1373563
A37: aircraft | B37: ='frgt-Air'!H10 -> 1 | C37: ='frgt-Air'!I10 -> 1.0088954 | D37: ='frgt-Air'!J10 -> 0.9991825 | E37: ='frgt-Air'!K10 -> 0.98946956 | F37: ='frgt-Air'!L10 -> 0.97975663 | G37: ='frgt-Air'!M10 -> 0.97004369 | H37: ='frgt-Air'!N10 -> 0.96033076 | I37: ='frgt-Air'!O10 -> 0.95061783 | ... AG37: ='frgt-Air'!AM10 -> 1.3139868 | AI37: ='Evidence 2019-2025'!G55 -> 1.15 | AJ37: ='Evidence 2019-2025'!D55 -> 2024 | AK37: ='Evidence 2019-2025'!E55 -> 1.078468 | AL37: =IF($C37=0,1,AI37/$C37) -> 1.1398604 | AM37: =IF(INDEX($B37:$AG37,1,AJ37-2018)=0,1,AK37/INDEX($B37:$AG37,1,AJ37-2018)) -> 1.1117726
A38: rail | B38: ='frgt-Rail'!H10 -> 1 | C38: ='frgt-Rail'!I10 -> 1.0398307 | D38: ='frgt-Rail'!J10 -> 1.0857372 | E38: ='frgt-Rail'!K10 -> 1.1316436 | F38: ='frgt-Rail'!L10 -> 1.17755 | G38: ='frgt-Rail'!M10 -> 1.2234564 | H38: ='frgt-Rail'!N10 -> 1.2693628 | I38: ='frgt-Rail'!O10 -> 1.3152692 | ... AG38: ='frgt-Rail'!AM10 -> 3.4242212 | AI38: ='Evidence 2019-2025'!G56 -> 1.15 | AJ38: ='Evidence 2019-2025'!D56 -> 2022 | AK38: ='Evidence 2019-2025'!E56 -> 1.0139344 | AL38: =IF($C38=0,1,AI38/$C38) -> 1.1059492 | AM38: =IF(INDEX($B38:$AG38,1,AJ38-2018)=0,1,AK38/INDEX($B38:$AG38,1,AJ38-2018)) -> 0.89598391
A39: ships | B39: ='frgt-Ship'!H10 -> 1 | C39: ='frgt-Ship'!I10 -> 1.038926 | D39: ='frgt-Ship'!J10 -> 1.0832553 | E39: ='frgt-Ship'!K10 -> 1.1275847 | F39: ='frgt-Ship'!L10 -> 1.1719141 | G39: ='frgt-Ship'!M10 -> 1.2162434 | H39: ='frgt-Ship'!N10 -> 1.2605728 | I39: ='frgt-Ship'!O10 -> 1.3049022 | ... AG39: ='frgt-Ship'!AM10 -> 1.9365883 | AI39: ='Evidence 2019-2025'!G57 -> 1.15 | AJ39: ='Evidence 2019-2025'!D57 -> 2024 | AK39: ='Evidence 2019-2025'!E57 -> 1.1949957 | AL39: =IF($C39=0,1,AI39/$C39) -> 1.1069124 | AM39: =IF(INDEX($B39:$AG39,1,AJ39-2018)=0,1,AK39/INDEX($B39:$AG39,1,AJ39-2018)) -> 0.98253
A40: motorbikes | B40: 0 | C40: 0 | D40: 0 | E40: 0 | F40: 0 | G40: 0 | H40: 0 | I40: 0 | J40: 0 | K40: 0 | L40: 0 | M40: 0 | N40: 0 | O40: 0 | P40: 0 | Q40: 0 | R40: 0 | S40: 0 | T40: 0 | U40: 0 | V40: 0 | W40: 0 | X40: 0 | Y40: 0 | Z40: 0 | AA40: 0 | AB40: 0 | AC40: 0 | AD40: 0 | AE40: 0 | AF40: 0 | AG40: 0 | AI40: ='Evidence 2019-2025'!G58 -> 0 | AJ40: ='Evidence 2019-2025'!D58 -> 2024 | AK40: ='Evidence 2019-2025'!E58 -> 0 | AL40: =IF($C40=0,1,AI40/$C40) -> 1 | AM40: =IF(INDEX($B40:$AG40,1,AJ40-2018)=0,1,AK40/INDEX($B40:$AG40,1,AJ40-2018)) -> 1
A42: Freight: multiplier m(t)
B43: 2019 | C43: 2020 | D43: 2021 | E43: 2022 | F43: 2023 | G43: 2024 | H43: 2025 | I43: 2026 | J43: 2027 | K43: 2028 | L43: 2029 | M43: 2030 | N43: 2031 | O43: 2032 | P43: 2033 | Q43: 2034 | R43: 2035 | S43: 2036 | T43: 2037 | U43: 2038 | V43: 2039 | W43: 2040 | X43: 2041 | Y43: 2042 | Z43: 2043 | AA43: 2044 | AB43: 2045 | AC43: 2046 | AD43: 2047 | AE43: 2048 | AF43: 2049 | AG43: 2050
A44: LDVs | B44: 1 | C44: =IF(C$43>=$AJ$35,$AM$35,$AL$35+($AM$35-$AL$35)*(C$43-2020)/($AJ$35-2020)) -> 1.1067645 | D44: =IF(D$43>=$AJ$35,$AM$35,$AL$35+($AM$35-$AL$35)*(D$43-2020)/($AJ$35-2020)) -> 1.0966982 | E44: =IF(E$43>=$AJ$35,$AM$35,$AL$35+($AM$35-$AL$35)*(E$43-2020)/($AJ$35-2020)) -> 1.086632 | F44: =IF(F$43>=$AJ$35,$AM$35,$AL$35+($AM$35-$AL$35)*(F$43-2020)/($AJ$35-2020)) -> 1.0765658 | G44: =IF(G$43>=$AJ$35,$AM$35,$AL$35+($AM$35-$AL$35)*(G$43-2020)/($AJ$35-2020)) -> 1.0664995 | H44: =IF(H$43>=$AJ$35,$AM$35,$AL$35+($AM$35-$AL$35)*(H$43-2020)/($AJ$35-2020)) -> 1.0664995 | I44: =IF(I$43>=$AJ$35,$AM$35,$AL$35+($AM$35-$AL$35)*(I$43-2020)/($AJ$35-2020)) -> 1.0664995 | J44: =IF(J$43>=$AJ$35,$AM$35,$AL$35+($AM$35-$AL$35)*(J$43-2020)/($AJ$35-2020)) -> 1.0664995 | ... AG44: =IF(AG$43>=$AJ$35,$AM$35,$AL$35+($AM$35-$AL$35)*(AG$43-2020)/($AJ$35-2020)) -> 1.0664995
A45: HDVs | B45: 1 | C45: =IF(C$43>=$AJ$36,$AM$36,$AL$36+($AM$36-$AL$36)*(C$43-2020)/($AJ$36-2020)) -> 1.1308335 | D45: =IF(D$43>=$AJ$36,$AM$36,$AL$36+($AM$36-$AL$36)*(D$43-2020)/($AJ$36-2020)) -> 1.1324642 | E45: =IF(E$43>=$AJ$36,$AM$36,$AL$36+($AM$36-$AL$36)*(E$43-2020)/($AJ$36-2020)) -> 1.1340949 | F45: =IF(F$43>=$AJ$36,$AM$36,$AL$36+($AM$36-$AL$36)*(F$43-2020)/($AJ$36-2020)) -> 1.1357256 | G45: =IF(G$43>=$AJ$36,$AM$36,$AL$36+($AM$36-$AL$36)*(G$43-2020)/($AJ$36-2020)) -> 1.1373563 | H45: =IF(H$43>=$AJ$36,$AM$36,$AL$36+($AM$36-$AL$36)*(H$43-2020)/($AJ$36-2020)) -> 1.1373563 | I45: =IF(I$43>=$AJ$36,$AM$36,$AL$36+($AM$36-$AL$36)*(I$43-2020)/($AJ$36-2020)) -> 1.1373563 | J45: =IF(J$43>=$AJ$36,$AM$36,$AL$36+($AM$36-$AL$36)*(J$43-2020)/($AJ$36-2020)) -> 1.1373563 | ... AG45: =IF(AG$43>=$AJ$36,$AM$36,$AL$36+($AM$36-$AL$36)*(AG$43-2020)/($AJ$36-2020)) -> 1.1373563
...

Sheet BCDTRtSY-psgr
A1: Cargo Dist Transported Relative to Start Year (dimensionless) | B1: 2019 | C1: 2020 | D1: 2021 | E1: 2022 | F1: 2023 | G1: 2024 | H1: 2025 | I1: 2026 | J1: 2027 | K1: 2028 | L1: 2029 | M1: 2030 | N1: 2031 | O1: 2032 | P1: 2033 | Q1: 2034 | R1: 2035 | S1: 2036 | T1: 2037 | U1: 2038 | V1: 2039 | W1: 2040 | X1: 2041 | Y1: 2042 | Z1: 2043 | AA1: 2044 | AB1: 2045 | AC1: 2046 | AD1: 2047 | AE1: 2048 | AF1: 2049 | AG1: 2050
A2: LDVs | B2: ='BAU Adjustment'!B26 -> 1 | C2: ='BAU Adjustment'!C26 -> 1.15 | D2: ='BAU Adjustment'!D26 -> 1.144689 | E2: ='BAU Adjustment'!E26 -> 1.1345825 | F2: ='BAU Adjustment'!F26 -> 1.1197502 | G2: ='BAU Adjustment'!G26 -> 1.1002859 | H2: ='BAU Adjustment'!H26 -> 1.1385728 | I2: ='BAU Adjustment'!I26 -> 1.1745218 | ... AG2: ='BAU Adjustment'!AG26 -> 1.5517693
A3: HDVs | B3: ='BAU Adjustment'!B27 -> 1 | C3: ='BAU Adjustment'!C27 -> 1.15 | D3: ='BAU Adjustment'!D27 -> 1.0745026 | E3: ='BAU Adjustment'!E27 -> 0.99184096 | F3: ='BAU Adjustment'!F27 -> 0.90198224 | G3: ='BAU Adjustment'!G27 -> 0.805 | H3: ='BAU Adjustment'!H27 -> 0.82649723 | I3: ='BAU Adjustment'!I27 -> 0.84759135 | ... AG3: ='BAU Adjustment'!AG27 -> 1.3444641
A4: aircraft | B4: ='BAU Adjustment'!B28 -> 1 | C4: ='BAU Adjustment'!C28 -> 1.15 | D4: ='BAU Adjustment'!D28 -> 1.1405944 | E4: ='BAU Adjustment'!E28 -> 1.1266783 | F4: ='BAU Adjustment'!F28 -> 1.1077842 | G4: ='BAU Adjustment'!G28 -> 1.0834067 | H4: ='BAU Adjustment'!H28 -> 1.053 | I4: ='BAU Adjustment'!I28 -> 1.107374 | ... AG4: ='BAU Adjustment'!AG28 -> 2.5109954
A5: rail | B5: ='BAU Adjustment'!B29 -> 1 | C5: ='BAU Adjustment'!C29 -> 1.15 | D5: ='BAU Adjustment'!D29 -> 1.0839553 | E5: ='BAU Adjustment'!E29 -> 1.0000718 | F5: ='BAU Adjustment'!F29 -> 0.89834928 | G5: ='BAU Adjustment'!G29 -> 0.77878788 | H5: ='BAU Adjustment'!H29 -> 0.81977671 | I5: ='BAU Adjustment'!I29 -> 0.86076555 | ... AG5: ='BAU Adjustment'!AG29 -> 1.8444976
A6: ships | B6: ='BAU Adjustment'!B30 -> 1 | C6: ='BAU Adjustment'!C30 -> 1.15 | D6: ='BAU Adjustment'!D30 -> 1.0598686 | E6: ='BAU Adjustment'!E30 -> 0.96795608 | F6: ='BAU Adjustment'!F30 -> 0.87426251 | G6: ='BAU Adjustment'!G30 -> 0.77878788 | H6: ='BAU Adjustment'!H30 -> 0.78551521 | I6: ='BAU Adjustment'!I30 -> 0.79224255 | ... AG6: ='BAU Adjustment'!AG30 -> 0.83102365
A7: motorbikes | B7: ='BAU Adjustment'!B31 -> 1 | C7: ='BAU Adjustment'!C31 -> 1.15 | D7: ='BAU Adjustment'!D31 -> 1.1411942 | E7: ='BAU Adjustment'!E31 -> 1.130506 | F7: ='BAU Adjustment'!F31 -> 1.1172095 | G7: ='BAU Adjustment'!G31 -> 1.1002859 | H7: ='BAU Adjustment'!H31 -> 1.1578002 | I7: ='BAU Adjustment'!I31 -> 1.2114655 | ... AG7: ='BAU Adjustment'!AG31 -> 1.7546191

Sheet BCDTRtSY-frgt
A1: Cargo Dist Transported Relative to Start Year (dimensionless) | B1: 2019 | C1: 2020 | D1: 2021 | E1: 2022 | F1: 2023 | G1: 2024 | H1: 2025 | I1: 2026 | J1: 2027 | K1: 2028 | L1: 2029 | M1: 2030 | N1: 2031 | O1: 2032 | P1: 2033 | Q1: 2034 | R1: 2035 | S1: 2036 | T1: 2037 | U1: 2038 | V1: 2039 | W1: 2040 | X1: 2041 | Y1: 2042 | Z1: 2043 | AA1: 2044 | AB1: 2045 | AC1: 2046 | AD1: 2047 | AE1: 2048 | AF1: 2049 | AG1: 2050
A2: LDVs | B2: ='BAU Adjustment'!B53 -> 1 | C2: ='BAU Adjustment'!C53 -> 1.15 | D2: ='BAU Adjustment'!D53 -> 1.1674368 | E2: ='BAU Adjustment'!E53 -> 1.1703607 | F2: ='BAU Adjustment'!F53 -> 1.172417 | G2: ='BAU Adjustment'!G53 -> 1.1736863 | H2: ='BAU Adjustment'!H53 -> 1.1854176 | I2: ='BAU Adjustment'!I53 -> 1.1983095 | ... AG2: ='BAU Adjustment'!AG53 -> 1.884289
A3: HDVs | B3: ='BAU Adjustment'!B54 -> 1 | C3: ='BAU Adjustment'!C54 -> 1.15 | D3: ='BAU Adjustment'!D54 -> 1.1596603 | E3: ='BAU Adjustment'!E54 -> 1.1637045 | F3: ='BAU Adjustment'!F54 -> 1.1687406 | G3: ='BAU Adjustment'!G54 -> 1.1736863 | H3: ='BAU Adjustment'!H54 -> 1.181341 | I3: ='BAU Adjustment'!I54 -> 1.1897552 | ... AG3: ='BAU Adjustment'!AG54 -> 1.7205664
