Workbook
Name Fraction_coal: About!$C$59
Name gal_per_barrel: [1]About!$A$63
Name Percent_rural: About!$A$109
Name Percent_urban: About!$A$108
Name quadrillion: About!$B$111
Name Table4: #REF!
Name Table4_1: #REF!
Name Table4_1_22: #REF!
Name Table4_22: #REF!
Name Table4_A: #REF!
Name Table4_A_22: #REF!
Name Table5: #REF!
Name Table5_1: #REF!
Name Table5_1_22: #REF!
Name Table5_22: #REF!
Name Table5_A: #REF!
Name Table5_A_22: #REF!

Sheet About
A1: BCEU BAU Components Energy Use
A3: Notes: | B3: Urban vs. Rural Residential Households
B4: Brazilian Ministry of Science, Technology, Innovation and Communication (MCTIC)
B5: 2017
B6: Report: "Greenhouse gas mitigation options in key sectors in Brazil"
B7: Version: "Sector modeling of low carbon options for the building sector"
B8: http://www.mctic.gov.br/mctic/export/sites/institucional/ciencia/SEPED/clima/arquivos/projeto_opcoes_mitigacao/publicacoes/Edificacoes.pdf
B10: urban-residential-cooling
B11: Brazilian Ministry of Science, Technology, Innovation and Communication (MCTIC)
B12: 2017
B13: Report: "Greenhouse gas mitigation options in key sectors in Brazil"
B14: Version: "Sector modeling of low carbon options for the building sector"
B15: http://www.mctic.gov.br/mctic/export/sites/institucional/ciencia/SEPED/clima/arquivos/projeto_opcoes_mitigacao/publicacoes/Edificacoes.pdf
B16: page 151
B17: Figure 85 - Energy Consumption from Climate Use in the REF Scenario by Equipment (2010-2050)
B19: urban-residential-lighting
B20: Brazilian Ministry of Science, Technology, Innovation and Communication (MCTIC)
B21: 2017
B22: Report: "Greenhouse gas mitigation options in key sectors in Brazil"
B23: Version: "Sector modeling of low carbon options for the building sector"
B24: http://www.mctic.gov.br/mctic/export/sites/institucional/ciencia/SEPED/clima/arquivos/projeto_opcoes_mitigacao/publicacoes/Edificacoes.pdf
B25: page 146
B26: Figure 78 - Energy Consumption of Lighting Use in the REF Scenario by Type of Technology (2010-2050)
B28: urban-residential-appl
B29: Brazilian Ministry of Science, Technology, Innovation and Communication (MCTIC)
B30: 2017
B31: Report: "Greenhouse gas mitigation options in key sectors in Brazil"
B32: Version: "Sector modeling of low carbon options for the building sector"
B33: http://www.mctic.gov.br/mctic/export/sites/institucional/ciencia/SEPED/clima/arquivos/projeto_opcoes_mitigacao/publicacoes/Edificacoes.pdf
B34: page 161
B35: Figure 100 - Energy Consumption of Water Heating in the REF Scenario by Energy (2010-2050)
B37: page 164
B38: Figure 101 - Energy Consumption of Other Uses in the REF Scenario by Type of Equipment (2010-2050)
B40: urban-residential-other
B41: Brazilian Ministry of Science, Technology, Innovation and Communication (MCTIC)
B42: 2017
B43: Report: "Greenhouse gas mitigation options in key sectors in Brazil"
B44: Version: "Sector modeling of low carbon options for the building sector"
B45: http://www.mctic.gov.br/mctic/export/sites/institucional/ciencia/SEPED/clima/arquivos/projeto_opcoes_mitigacao/publicacoes/Edificacoes.pdf
B46: page 158
...

Sheet urban-residential-cooling
A1: Notes:
A2: 1. In MOP's study cooling components represents the appliances to space cooling (AC and ventilator) and the appliances to cool food (fridge and freezer);
A3: 2. MOP computes the energy demand in ktep, to convert to BTU we assume the factor: 1 tep = 3,968e+7 BTU or 1 ktep = 3,968e+10 BTU;
A4: 3.9683051e+10
A6: Figure 85 - Energy Consumption from Climate Use in the REF Scenario by Equipment (2010-2050)
A29: The table below is from the excel file that generated the results for buildings sector.
A30: * Data in ktep
A31: Sector | B31: Demand | C31: Energetic / End Use | D31: 2010 | E31: 2011 | F31: 2012 | G31: 2013 | H31: 2014 | I31: 2015 | J31: 2016 | K31: 2017 | L31: 2018 | M31: 2019 | N31: 2020 | O31: 2021 | P31: 2022 | Q31: 2023 | R31: 2024 | S31: 2025 | T31: 2026 | U31: 2027 | V31: 2028 | W31: 2029 | X31: 2030 | Y31: 2031 | Z31: 2032 | AA31: 2033 | AB31: 2034 | AC31: 2035 | AD31: 2036 | AE31: 2037 | AF31: 2038 | AG31: 2039 | AH31: 2040 | AI31: 2041 | AJ31: 2042 | AK31: 2043 | AL31: 2044 | AM31: 2045 | AN31: 2046 | AO31: 2047 | AP31: 2048 | AQ31: 2049 | AR31: 2050
A32: Residential | B32: Water heating | C32: Natural gas | D32: 143
A33: Residential | B33: Water heating | C33: LPG | D33: 94.47
A34: Residential | B34: Water heating | C34: Electricity | D34: 1649
A35: Residential | B35: Water heating | C35: Solar | D35: 0
A36: Residential | B36: Cooking | C36: Natural gas | D36: 112
A37: Residential | B37: Cooking | C37: LPG | D37: 6203.53
A38: Residential | B38: Cooking | C38: Firewood | D38: 7276
A39: Residential | B39: Cooking | C39: Charcoal | D39: 509
A40: Residential | B40: Cooking | C40: Electricity | D40: 0 | E40: 0 | F40: 0 | G40: 0 | H40: 0 | I40: 0 | J40: 0 | K40: 0 | L40: 0 | M40: 0 | N40: 0 | O40: 0 | P40: 0 | Q40: 0 | R40: 0 | S40: 0 | T40: 0 | U40: 0 | V40: 0 | W40: 0 | X40: 0 | Y40: 0 | Z40: 0 | AA40: 0 | AB40: 0 | AC40: 0 | AD40: 0 | AE40: 0 | AF40: 0 | AG40: 0 | AH40: 0 | AI40: 0 | AJ40: 0 | AK40: 0 | AL40: 0 | AM40: 0 | AN40: 0 | AO40: 0 | AP40: 0 | AQ40: 0 | AR40: 0
A41: Residential | B41: Cooking | C41: Solar | D41: 0 | E41: 0 | F41: 0 | G41: 0 | H41: 0 | I41: 0 | J41: 0 | K41: 0 | L41: 0 | M41: 0 | N41: 0 | O41: 0 | P41: 0 | Q41: 0 | R41: 0 | S41: 0 | T41: 0 | U41: 0 | V41: 0 | W41: 0 | X41: 0 | Y41: 0 | Z41: 0 | AA41: 0 | AB41: 0 | AC41: 0 | AD41: 0 | AE41: 0 | AF41: 0 | AG41: 0 | AH41: 0 | AI41: 0 | AJ41: 0 | AK41: 0 | AL41: 0 | AM41: 0 | AN41: 0 | AO41: 0 | AP41: 0 | AQ41: 0 | AR41: 0
A42: Residential | B42: Lighting | C42: Electricity | D42: 1469.5035 | E42: 1510.4945 | F42: 1554.129 | G42: 1561.5737 | H42: 1597.2765 | I42: 1633.2376 | J42: 840.54232 | K42: 860.87933 | L42: 881.41056 | M42: 902.1359 | N42: 923.05523 | O42: 943.27573 | P42: 963.67751 | Q42: 984.26111 | R42: 1005.0261 | S42: 1025.9722 | T42: 1047.0981 | U42: 1068.4031 | V42: 1089.8876 | W42: 1111.5506 | X42: 1133.3915 | Y42: 1153.3292 | Z42: 1173.4237 | AA42: 1193.6749 | AB42: 1214.0829 | AC42: 1234.6476 | AD42: 1255.3691 | AE42: 1276.2474 | AF42: 1297.2824 | AG42: 1318.4741 | AH42: 1339.8227 | AI42: 1357.4019 | AJ42: 1375.0937 | AK42: 1392.8981 | AL42: 1410.8149 | AM42: 1428.8443 | AN42: 1446.9863 | AO42: 1465.2408 | AP42: 1483.6078 | AQ42: 1502.0873 | AR42: 1520.6794
A43: Residential | B43: Climatization | C43: Electricity | D43: 503 | E43: 533.32042 | F43: 572.10388 | G43: 610.31558 | H43: 660.48007 | I43: 711.10575 | J43: 758.78876 | K43: 811.23331 | L43: 871.4355 | M43: 932.29996 | N43: 986.67045 | O43: 1033.7892 | P43: 1073.513 | Q43: 1105.7979 | R43: 1135.5336 | S43: 1165.1267 | T43: 1194.5644 | U43: 1223.822 | V43: 1252.8592 | W43: 1281.6492 | X43: 1310.1654 | Y43: 1337.1299 | Z43: 1364.3634 | AA43: 1391.1548 | AB43: 1417.4795 | AC43: 1443.3122 | AD43: 1468.6267 | AE43: 1493.3959 | AF43: 1517.5919 | AG43: 1541.1861 | AH43: 1564.1487 | AI43: 1584.8023 | AJ43: 1604.6151 | AK43: 1623.5704 | AL43: 1641.6511 | AM43: 1658.8399 | AN43: 1675.1192 | AO43: 1690.471 | AP43: 1704.8769 | AQ43: 1718.3186 | AR43: 1730.7769
A44: Residential | B44: Cooling | C44: Electricity | D44: 2113 | E44: 2179.4516 | F44: 2251.1509 | G44: 2269.8381 | H44: 2330.3514 | I44: 2391.3793 | J44: 2452.9241 | K44: 2514.9756 | L44: 2577.5072 | M44: 2640.5049 | N44: 2703.9554 | O44: 2765.204 | P44: 2826.8313 | Q44: 2888.838 | R44: 2951.2124 | S44: 3013.9425 | T44: 3077.0059 | U44: 3140.3904 | V44: 3204.0957 | W44: 3268.1098 | X44: 3332.4199 | Y44: 3390.5292 | Z44: 3448.8307 | AA44: 3507.3146 | AB44: 3565.9711 | AC44: 3624.7903 | AD44: 3683.7625 | AE44: 3742.8775 | AF44: 3802.1255 | AG44: 3861.4964 | AH44: 3920.9801 | AI44: 3969.0867 | AJ44: 4017.1773 | AK44: 4065.2443 | AL44: 4113.28 | AM44: 4161.2767 | AN44: 4209.2265 | AO44: 4257.1217 | AP44: 4304.9544 | AQ44: 4352.7167 | AR44: 4400.4008
A45: Residential | B45: Others | C45: Electricity | D45: 3485 | E45: 3716.0276 | F45: 3864.0408 | G45: 3971.2619 | H45: 4140.8104 | I45: 4324.4473 | J45: 4516.6381 | K45: 4727.5973 | L45: 4960.2854 | M45: 5218.2018 | N45: 5505.4717 | O45: 5605.1595 | P45: 5806.5187 | Q45: 5933.718 | R45: 6085.7212 | S45: 6244.9617 | T45: 6412.285 | U45: 6588.1474 | V45: 6773.3026 | W45: 6813.1499 | X45: 6910.4825 | Y45: 6997.4141 | Z45: 7094.1214 | AA45: 7191.3229 | AB45: 7288.9952 | AC45: 7387.1176 | AD45: 7485.3369 | AE45: 7583.9646 | AF45: 7682.9819 | AG45: 7782.3747 | AH45: 7882.1347 | AI45: 7962.7447 | AJ45: 8049.6705 | AK45: 8136.75 | AL45: 8223.9861 | AM45: 8311.381 | AN45: 8398.9255 | AO45: 8486.6393 | AP45: 8574.5283 | AQ45: 8662.6028 | AR45: 8750.873
A46: Residential | B46: Lighting | C46: Kerosene | D46: 4
A47: Commercial | B47: Water heating | C47: Natural gas
A48: Commercial | B48: Water heating | C48: LPG
A49: Commercial | B49: Water heating | C49: Electricity
A50: Commercial | B50: Water heating | C50: Solar
A51: Commercial | B51: Cooking | C51: Natural gas
A52: Commercial | B52: Cooking | C52: LPG
A53: Commercial | B53: Cooking | C53: Firewood
A54: Commercial | B54: Cooking | C54: Charcoal
A55: Commercial | B55: Cooking | C55: Electricity
A56: Commercial | B56: Cooking | C56: Solar
A57: Commercial | B57: Climatization | C57: Natural gas
A58: Commercial | B58: Climatization | C58: Electricity | D58: 1262.0912 | E58: 1320.2971 | F58: 1378.503 | G58: 1436.709 | H58: 1494.9149 | I58: 1553.1208 | J58: 1663.8998 | K58: 1774.6787 | L58: 1885.4576 | M58: 1996.2365 | N58: 2107.0155 | O58: 2328.7621 | P58: 2550.5086 | Q58: 2772.2552 | R58: 2994.0018 | S58: 3215.7484 | T58: 3585.4385 | U58: 3955.1286 | V58: 4324.8187 | W58: 4694.5088 | X58: 5064.1989 | Y58: 5509.4927 | Z58: 5954.7866 | AA58: 6400.0804 | AB58: 6845.3742 | AC58: 7290.668 | AD58: 7688.0293 | AE58: 8085.3907 | AF58: 8482.7521 | AG58: 8880.1134 | AH58: 9277.4748 | AI58: 9592.5843 | AJ58: 9907.6938 | AK58: 10222.803 | AL58: 10537.913 | AM58: 10853.022 | AN58: 11144.848 | AO58: 11436.673 | AP58: 11728.498 | AQ58: 12020.323 | AR58: 12312.149
A59: Commercial | B59: Climatization | C59: Solar
A60: Commercial | B60: Lighting | C60: Electricity
A61: Commercial | B61: Street lighting | C61: Electricity
A62: Commercial | B62: Cooling | C62: Electricity
A63: Commercial | B63: Others | C63: Electricity
...

Sheet urban-residential-lighting
A1: Notes:
A2: 1. MOP computes the energy demand in ktep, to convert to BTU we assume the factor: 1 tep = 3,968e+7 BTU or 1 ktep = 3,968e+10 BTU;
A3: 3.9683051e+10
A5: Figure 78 - Energy Consumption of Lighting Use in the REF Scenario by Type of Technology (2010-2050)
A25: The table below is from the excel file that generated the results for buildings sector.
A26: * Data in ktep
A27: Sector | B27: Demand | C27: Energetic / End Use | D27: 2010 | E27: 2011 | F27: 2012 | G27: 2013 | H27: 2014 | I27: 2015 | J27: 2016 | K27: 2017 | L27: 2018 | M27: 2019 | N27: 2020 | O27: 2021 | P27: 2022 | Q27: 2023 | R27: 2024 | S27: 2025 | T27: 2026 | U27: 2027 | V27: 2028 | W27: 2029 | X27: 2030 | Y27: 2031 | Z27: 2032 | AA27: 2033 | AB27: 2034 | AC27: 2035 | AD27: 2036 | AE27: 2037 | AF27: 2038 | AG27: 2039 | AH27: 2040 | AI27: 2041 | AJ27: 2042 | AK27: 2043 | AL27: 2044 | AM27: 2045 | AN27: 2046 | AO27: 2047 | AP27: 2048 | AQ27: 2049 | AR27: 2050
A28: Residential | B28: Water heating | C28: Natural gas | D28: 143
A29: Residential | B29: Water heating | C29: LPG | D29: 94.47
A30: Residential | B30: Water heating | C30: Electricity | D30: 1649
A31: Residential | B31: Water heating | C31: Solar | D31: 0
A32: Residential | B32: Cooking | C32: Natural gas | D32: 112
A33: Residential | B33: Cooking | C33: LPG | D33: 6203.53
A34: Residential | B34: Cooking | C34: Firewood | D34: 7276
A35: Residential | B35: Cooking | C35: Charcoal | D35: 509
A36: Residential | B36: Cooking | C36: Electricity | D36: 0 | E36: 0 | F36: 0 | G36: 0 | H36: 0 | I36: 0 | J36: 0 | K36: 0 | L36: 0 | M36: 0 | N36: 0 | O36: 0 | P36: 0 | Q36: 0 | R36: 0 | S36: 0 | T36: 0 | U36: 0 | V36: 0 | W36: 0 | X36: 0 | Y36: 0 | Z36: 0 | AA36: 0 | AB36: 0 | AC36: 0 | AD36: 0 | AE36: 0 | AF36: 0 | AG36: 0 | AH36: 0 | AI36: 0 | AJ36: 0 | AK36: 0 | AL36: 0 | AM36: 0 | AN36: 0 | AO36: 0 | AP36: 0 | AQ36: 0 | AR36: 0
A37: Residential | B37: Cooking | C37: Solar | D37: 0 | E37: 0 | F37: 0 | G37: 0 | H37: 0 | I37: 0 | J37: 0 | K37: 0 | L37: 0 | M37: 0 | N37: 0 | O37: 0 | P37: 0 | Q37: 0 | R37: 0 | S37: 0 | T37: 0 | U37: 0 | V37: 0 | W37: 0 | X37: 0 | Y37: 0 | Z37: 0 | AA37: 0 | AB37: 0 | AC37: 0 | AD37: 0 | AE37: 0 | AF37: 0 | AG37: 0 | AH37: 0 | AI37: 0 | AJ37: 0 | AK37: 0 | AL37: 0 | AM37: 0 | AN37: 0 | AO37: 0 | AP37: 0 | AQ37: 0 | AR37: 0
A38: Residential | B38: Lighting | C38: Electricity | D38: 1469.5035 | E38: 1510.4945 | F38: 1554.129 | G38: 1561.5737 | H38: 1597.2765 | I38: 1633.2376 | J38: 840.54232 | K38: 860.87933 | L38: 881.41056 | M38: 902.1359 | N38: 923.05523 | O38: 943.27573 | P38: 963.67751 | Q38: 984.26111 | R38: 1005.0261 | S38: 1025.9722 | T38: 1047.0981 | U38: 1068.4031 | V38: 1089.8876 | W38: 1111.5506 | X38: 1133.3915 | Y38: 1153.3292 | Z38: 1173.4237 | AA38: 1193.6749 | AB38: 1214.0829 | AC38: 1234.6476 | AD38: 1255.3691 | AE38: 1276.2474 | AF38: 1297.2824 | AG38: 1318.4741 | AH38: 1339.8227 | AI38: 1357.4019 | AJ38: 1375.0937 | AK38: 1392.8981 | AL38: 1410.8149 | AM38: 1428.8443 | AN38: 1446.9863 | AO38: 1465.2408 | AP38: 1483.6078 | AQ38: 1502.0873 | AR38: 1520.6794
A39: Residential | B39: Climatization | C39: Electricity | D39: 503 | E39: 533.32042 | F39: 572.10388 | G39: 610.31558 | H39: 660.48007 | I39: 711.10575 | J39: 758.78876 | K39: 811.23331 | L39: 871.4355 | M39: 932.29996 | N39: 986.67045 | O39: 1033.7892 | P39: 1073.513 | Q39: 1105.7979 | R39: 1135.5336 | S39: 1165.1267 | T39: 1194.5644 | U39: 1223.822 | V39: 1252.8592 | W39: 1281.6492 | X39: 1310.1654 | Y39: 1337.1299 | Z39: 1364.3634 | AA39: 1391.1548 | AB39: 1417.4795 | AC39: 1443.3122 | AD39: 1468.6267 | AE39: 1493.3959 | AF39: 1517.5919 | AG39: 1541.1861 | AH39: 1564.1487 | AI39: 1584.8023 | AJ39: 1604.6151 | AK39: 1623.5704 | AL39: 1641.6511 | AM39: 1658.8399 | AN39: 1675.1192 | AO39: 1690.471 | AP39: 1704.8769 | AQ39: 1718.3186 | AR39: 1730.7769
A40: Residential | B40: Cooling | C40: Electricity | D40: 2113 | E40: 2179.4516 | F40: 2251.1509 | G40: 2269.8381 | H40: 2330.3514 | I40: 2391.3793 | J40: 2452.9241 | K40: 2514.9756 | L40: 2577.5072 | M40: 2640.5049 | N40: 2703.9554 | O40: 2765.204 | P40: 2826.8313 | Q40: 2888.838 | R40: 2951.2124 | S40: 3013.9425 | T40: 3077.0059 | U40: 3140.3904 | V40: 3204.0957 | W40: 3268.1098 | X40: 3332.4199 | Y40: 3390.5292 | Z40: 3448.8307 | AA40: 3507.3146 | AB40: 3565.9711 | AC40: 3624.7903 | AD40: 3683.7625 | AE40: 3742.8775 | AF40: 3802.1255 | AG40: 3861.4964 | AH40: 3920.9801 | AI40: 3969.0867 | AJ40: 4017.1773 | AK40: 4065.2443 | AL40: 4113.28 | AM40: 4161.2767 | AN40: 4209.2265 | AO40: 4257.1217 | AP40: 4304.9544 | AQ40: 4352.7167 | AR40: 4400.4008
A41: Residential | B41: Others | C41: Electricity | D41: 3485 | E41: 3716.0276 | F41: 3864.0408 | G41: 3971.2619 | H41: 4140.8104 | I41: 4324.4473 | J41: 4516.6381 | K41: 4727.5973 | L41: 4960.2854 | M41: 5218.2018 | N41: 5505.4717 | O41: 5605.1595 | P41: 5806.5187 | Q41: 5933.718 | R41: 6085.7212 | S41: 6244.9617 | T41: 6412.285 | U41: 6588.1474 | V41: 6773.3026 | W41: 6813.1499 | X41: 6910.4825 | Y41: 6997.4141 | Z41: 7094.1214 | AA41: 7191.3229 | AB41: 7288.9952 | AC41: 7387.1176 | AD41: 7485.3369 | AE41: 7583.9646 | AF41: 7682.9819 | AG41: 7782.3747 | AH41: 7882.1347 | AI41: 7962.7447 | AJ41: 8049.6705 | AK41: 8136.75 | AL41: 8223.9861 | AM41: 8311.381 | AN41: 8398.9255 | AO41: 8486.6393 | AP41: 8574.5283 | AQ41: 8662.6028 | AR41: 8750.873
A42: Residential | B42: Lighting | C42: Kerosene | D42: 4
A43: Commercial | B43: Water heating | C43: Natural gas
A44: Commercial | B44: Water heating | C44: LPG
A45: Commercial | B45: Water heating | C45: Electricity
A46: Commercial | B46: Water heating | C46: Solar
A47: Commercial | B47: Cooking | C47: Natural gas
A48: Commercial | B48: Cooking | C48: LPG
A49: Commercial | B49: Cooking | C49: Firewood
A50: Commercial | B50: Cooking | C50: Charcoal
A51: Commercial | B51: Cooking | C51: Electricity
A52: Commercial | B52: Cooking | C52: Solar
A53: Commercial | B53: Climatization | C53: Natural gas
A54: Commercial | B54: Climatization | C54: Electricity | D54: 1262.0912 | E54: 1320.2971 | F54: 1378.503 | G54: 1436.709 | H54: 1494.9149 | I54: 1553.1208 | J54: 1663.8998 | K54: 1774.6787 | L54: 1885.4576 | M54: 1996.2365 | N54: 2107.0155 | O54: 2328.7621 | P54: 2550.5086 | Q54: 2772.2552 | R54: 2994.0018 | S54: 3215.7484 | T54: 3585.4385 | U54: 3955.1286 | V54: 4324.8187 | W54: 4694.5088 | X54: 5064.1989 | Y54: 5509.4927 | Z54: 5954.7866 | AA54: 6400.0804 | AB54: 6845.3742 | AC54: 7290.668 | AD54: 7688.0293 | AE54: 8085.3907 | AF54: 8482.7521 | AG54: 8880.1134 | AH54: 9277.4748 | AI54: 9592.5843 | AJ54: 9907.6938 | AK54: 10222.803 | AL54: 10537.913 | AM54: 10853.022 | AN54: 11144.848 | AO54: 11436.673 | AP54: 11728.498 | AQ54: 12020.323 | AR54: 12312.149
A55: Commercial | B55: Climatization | C55: Solar
A56: Commercial | B56: Lighting | C56: Electricity
A57: Commercial | B57: Street lighting | C57: Electricity
A58: Commercial | B58: Cooling | C58: Electricity
A59: Commercial | B59: Others | C59: Electricity
A60: Commercial | B60: Power cogeneration | C60: Natural gas

Sheet urban-residential-appl
A1: Notes:
A2: 1. In MOP's study, appliances represents the follows gears: TV, electric iron, washing machine, computer, Water heaters (shower propose) and others.
A3: 2. MOP computes the energy demand in ktep, to convert to BTU we assume the factor: 1 tep = 3,968e+7 BTU or 1 ktep = 3,968e+10 BTU;
A4: 3.9683051e+10
A6: Figure 100 - Energy Consumption of Water Heating in the REF Scenario by Energy (2010-2050) | H6: Figure 101 - Energy Consumption of Other Uses in the REF Scenario by Type of Equipment (2010-2050)
A29: The table below is from the excel file that generated the results for buildings sector.
A31: Total power consumption (GWh and 10 ^ 3 TEP) | B31: 2010 | C31: 2011 | D31: 2012 | E31: 2013 | F31: 2014 | G31: 2015 | H31: 2016 | I31: 2017 | J31: 2018 | K31: 2019 | L31: 2020 | M31: 2021 | N31: 2022 | O31: 2023 | P31: 2024 | Q31: 2025 | R31: 2026 | S31: 2027 | T31: 2028 | U31: 2029 | V31: 2030 | W31: 2031 | X31: 2032 | Y31: 2033 | Z31: 2034 | AA31: 2035 | AB31: 2036 | AC31: 2037 | AD31: 2038 | AE31: 2039 | AF31: 2040 | AG31: 2041 | AH31: 2042 | AI31: 2043 | AJ31: 2044 | AK31: 2045 | AL31: 2046 | AM31: 2047 | AN31: 2048 | AO31: 2049 | AP31: 2050
A32: GWh | B32: 40528.454 | C32: 43217.401 | D32: 44938.794 | E32: 46185.775 | F32: 48157.625 | G32: 50293.322 | H32: 52528.501 | I32: 54981.956 | J32: 57688.12 | K32: 60687.687 | L32: 64028.636 | M32: 65188.005 | N32: 67529.812 | O32: 69009.141 | P32: 70776.938 | Q32: 72628.905 | R32: 74574.874 | S32: 76620.155 | T32: 78773.509 | U32: 79236.933 | V32: 80368.912 | W32: 81379.926 | X32: 82504.632 | Y32: 83635.085 | Z32: 84771.015 | AA32: 85912.178 | AB32: 87054.468 | AC32: 88201.508 | AD32: 89353.079 | AE32: 90509.017 | AF32: 91669.226 | AG32: 92606.721 | AH32: 93617.668 | AI32: 94630.403 | AJ32: 95644.958 | AK32: 96661.36 | AL32: 97679.503 | AM32: 98699.615 | AN32: 99721.764 | AO32: 100746.07 | AP32: 101772.65
A33: 10 ^ 3 TEP | B33: 3484.8197 | C33: 3716.0276 | D33: 3864.0408 | E33: 3971.2619 | F33: 4140.8104 | G33: 4324.4473 | H33: 4516.6381 | I33: 4727.5973 | J33: 4960.2854 | K33: 5218.2018 | L33: 5505.4717 | M33: 5605.1595 | N33: 5806.5187 | O33: 5933.718 | P33: 6085.7212 | Q33: 6244.9617 | R33: 6412.285 | S33: 6588.1474 | T33: 6773.3026 | U33: 6813.1499 | V33: 6910.4825 | W33: 6997.4141 | X33: 7094.1214 | Y33: 7191.3229 | Z33: 7288.9952 | AA33: 7387.1176 | AB33: 7485.3369 | AC33: 7583.9646 | AD33: 7682.9819 | AE33: 7782.3747 | AF33: 7882.1347 | AG33: 7962.7447 | AH33: 8049.6705 | AI33: 8136.75 | AJ33: 8223.9861 | AK33: 8311.381 | AL33: 8398.9255 | AM33: 8486.6393 | AN33: 8574.5283 | AO33: 8662.6028 | AP33: 8750.873
A36: Shareholding with elasticity | B36: 2010 | C36: 2011 | D36: 2012 | E36: 2013 | F36: 2014 | G36: 2015 | H36: 2016 | I36: 2017 | J36: 2018 | K36: 2019 | L36: 2020 | M36: 2021 | N36: 2022 | O36: 2023 | P36: 2024 | Q36: 2025 | R36: 2026 | S36: 2027 | T36: 2028 | U36: 2029 | V36: 2030 | W36: 2031 | X36: 2032 | Y36: 2033 | Z36: 2034 | AA36: 2035 | AB36: 2036 | AC36: 2037 | AD36: 2038 | AE36: 2039 | AF36: 2040 | AG36: 2041 | AH36: 2042 | AI36: 2043 | AJ36: 2044 | AK36: 2045 | AL36: 2046 | AM36: 2047 | AN36: 2048 | AO36: 2049 | AP36: 2050
A37: TV, iron, PC, machine of washing | B37: 0.76286412 | C37: 0.77341073 | D37: 0.77796129 | E37: 0.77985846 | F37: 0.78486547 | G37: 0.79009079 | H37: 0.79691154 | I37: 0.80388953 | J37: 0.81103829 | K37: 0.81836747 | L37: 0.82588144 | M37: 0.82671209 | N37: 0.83047907 | O37: 0.83186512 | P37: 0.83382053 | Q37: 0.83582007 | R37: 0.83784067 | S37: 0.83991786 | T37: 0.84205695 | U37: 0.84071011 | V37: 0.84066899 | W37: 0.84039118 | X37: 0.8402956 | Y37: 0.8401693 | Z37: 0.84001301 | AA37: 0.8398275 | AB37: 0.83965087 | AC37: 0.83944547 | AD37: 0.83921204 | AE37: 0.8389514 | AF37: 0.83866445 | AG37: 0.83798246 | AH37: 0.83740223 | AI37: 0.83679834 | AJ37: 0.83617163 | AK37: 0.8355229 | AL37: 0.8348544 | AM37: 0.83416548 | AN37: 0.83345692 | AO37: 0.83272956 | AP37: 0.8319842
A38: Other appliances | B38: 0.23713588 | C38: 0.22658927 | D38: 0.22203871 | E38: 0.22014154 | F38: 0.21513453 | G38: 0.20990921 | H38: 0.20308846 | I38: 0.19611047 | J38: 0.18896171 | K38: 0.18163253 | L38: 0.17411856 | M38: 0.17328791 | N38: 0.16952093 | O38: 0.16813488 | P38: 0.16617947 | Q38: 0.16417993 | R38: 0.16215933 | S38: 0.16008214 | T38: 0.15794305 | U38: 0.15928989 | V38: 0.15933101 | W38: 0.15960882 | X38: 0.1597044 | Y38: 0.1598307 | Z38: 0.15998699 | AA38: 0.1601725 | AB38: 0.16034913 | AC38: 0.16055453 | AD38: 0.16078796 | AE38: 0.1610486 | AF38: 0.16133555 | AG38: 0.16201754 | AH38: 0.16259777 | AI38: 0.16320166 | AJ38: 0.16382837 | AK38: 0.1644771 | AL38: 0.1651456 | AM38: 0.16583452 | AN38: 0.16654308 | AO38: 0.16727044 | AP38: 0.1680158
A41: Water heaters (shower propose)
A42: Residential Energy Consumption (ktep)
A44: Energetic used | B44: 2010 | C44: 2011 | D44: 2012 | E44: 2013 | F44: 2014 | G44: 2015 | H44: 2016 | I44: 2017 | J44: 2018 | K44: 2019 | L44: 2020 | M44: 2021 | N44: 2022 | O44: 2023 | P44: 2024 | Q44: 2025 | R44: 2026 | S44: 2027 | T44: 2028 | U44: 2029 | V44: 2030 | W44: 2031 | X44: 2032 | Y44: 2033 | Z44: 2034 | AA44: 2035 | AB44: 2036 | AC44: 2037 | AD44: 2038 | AE44: 2039 | AF44: 2040 | AG44: 2041 | AH44: 2042 | AI44: 2043 | AJ44: 2044 | AK44: 2045 | AL44: 2046 | AM44: 2047 | AN44: 2048 | AO44: 2049 | AP44: 2050
A45: Solar | B45: 0 | C45: 0 | D45: 0 | E45: 0 | F45: 0 | G45: 0 | H45: 0 | I45: 0 | J45: 0 | K45: 0 | L45: 0 | M45: 0 | N45: 0 | O45: 0 | P45: 0 | Q45: 0 | R45: 0 | S45: 0 | T45: 0 | U45: 0 | V45: 0 | W45: 0 | X45: 0 | Y45: 0 | Z45: 0 | AA45: 0 | AB45: 0 | AC45: 0 | AD45: 0 | AE45: 0 | AF45: 0 | AG45: 0 | AH45: 0 | AI45: 0 | AJ45: 0 | AK45: 0 | AL45: 0 | AM45: 0 | AN45: 0 | AO45: 0 | AP45: 0
A46: Natural gas | B46: 141.70927 | C46: 140.83056 | D46: 139.94945 | E46: 139.06593 | F46: 146.47133 | G46: 153.74879 | H46: 160.8983 | I46: 167.91987 | J46: 174.81349 | K46: 181.57918 | L46: 188.21691 | M46: 199.50993 | N46: 210.80294 | O46: 222.09596 | P46: 233.38897 | Q46: 244.68199 | R46: 255.975 | S46: 267.26802 | T46: 278.56103 | U46: 289.85405 | V46: 301.14706 | W46: 312.44008 | X46: 323.73309 | Y46: 335.02611 | Z46: 346.31912 | AA46: 357.61214 | AB46: 368.90515 | AC46: 380.19817 | AD46: 391.49118 | AE46: 402.7842 | AF46: 414.07721 | AG46: 429.13456 | AH46: 444.19192 | AI46: 459.24927 | AJ46: 474.30662 | AK46: 489.36398 | AL46: 504.42133 | AM46: 519.47868 | AN46: 534.53604 | AO46: 549.59339 | AP46: 564.65074
A47: LPG | B47: 93.617303 | C47: 89.975622 | D47: 86.379928 | E47: 82.830221 | F47: 82.164531 | G47: 81.498841 | H47: 80.833151 | I47: 80.16746 | J47: 79.50177 | K47: 78.83608 | L47: 78.17039 | M47: 79.733798 | N47: 81.297206 | O47: 82.860614 | P47: 84.424021 | Q47: 85.987429 | R47: 87.550837 | S47: 89.114245 | T47: 90.677653 | U47: 92.24106 | V47: 93.804468 | W47: 95.758728 | X47: 97.712988 | Y47: 99.667248 | Z47: 101.62151 | AA47: 103.57577 | AB47: 105.53003 | AC47: 107.48429 | AD47: 109.43855 | AE47: 111.39281 | AF47: 113.34707 | AG47: 116.86473 | AH47: 120.3824 | AI47: 123.90007 | AJ47: 127.41774 | AK47: 130.9354 | AL47: 134.45307 | AM47: 137.97074 | AN47: 141.48841 | AO47: 145.00607 | AP47: 148.52374
A48: Electricity | B48: 1653.1692 | C48: 1620.1468 | D48: 1587.4569 | E48: 1555.0996 | F48: 1534.1811 | G48: 1513.3525 | H48: 1481.4794 | I48: 1463.7073 | J48: 1445.9628 | K48: 1428.246 | L48: 1410.5568 | M48: 1405.7998 | N48: 1401.0428 | O48: 1396.2858 | P48: 1391.5288 | Q48: 1386.7718 | R48: 1382.0147 | S48: 1377.2577 | T48: 1372.5007 | U48: 1367.7437 | V48: 1362.9867 | W48: 1358.2297 | X48: 1353.4727 | Y48: 1348.7157 | Z48: 1343.9587 | AA48: 1339.2017 | AB48: 1334.4447 | AC48: 1329.6876 | AD48: 1324.9306 | AE48: 1320.1736 | AF48: 1315.4166 | AG48: 1307.5572 | AH48: 1299.6978 | AI48: 1291.8384 | AJ48: 1283.979 | AK48: 1276.1196 | AL48: 1268.2602 | AM48: 1260.4008 | AN48: 1252.5414 | AO48: 1244.6819 | AP48: 1236.8225

Sheet urban-residential-other
A1: Notes:
A2: 1. Others represents cooking components.
A3: 2. MOP computes the energy demand in ktep, to convert to BTU we assume the factor: 1 tep = 3,968e+7 BTU or 1 ktep = 3,968e+10 BTU;
A4: 3.9683051e+10
A6: Figure 97 - Energy Use of Cooking in the REF Scenario by Energy (2010-2050)
A27: The table below is from the excel file that generated the results for buildings sector.
A28: Energy consumption
A29: ktep
A30: Residential consumption Cooking | B30: 2010 | C30: 2011 | D30: 2012 | E30: 2013 | F30: 2014 | G30: 2015 | H30: 2016 | I30: 2017 | J30: 2018 | K30: 2019 | L30: 2020 | M30: 2021 | N30: 2022 | O30: 2023 | P30: 2024 | Q30: 2025 | R30: 2026 | S30: 2027 | T30: 2028 | U30: 2029 | V30: 2030 | W30: 2031 | X30: 2032 | Y30: 2033 | Z30: 2034 | AA30: 2035 | AB30: 2036 | AC30: 2037 | AD30: 2038 | AE30: 2039 | AF30: 2040 | AG30: 2041 | AH30: 2042 | AI30: 2043 | AJ30: 2044 | AK30: 2045 | AL30: 2046 | AM30: 2047 | AN30: 2048 | AO30: 2049 | AP30: 2050
A31: Natural gas | B31: 112 | C31: 122.95489 | D31: 156.11389 | E31: 192.79091 | F31: 227.16976 | G31: 261.79515 | H31: 296.63822 | I31: 331.66814 | J31: 366.85033 | K31: 402.15347 | L31: 437.54631 | M31: 475.05248 | N31: 512.90986 | O31: 551.09236 | P31: 589.57068 | Q31: 628.31597 | R31: 667.2979 | S31: 706.48629 | T31: 745.85184 | U31: 785.36295 | V31: 824.98659 | W31: 864.69259 | X31: 904.47644 | Y31: 944.30072 | Z31: 984.12742 | AA31: 1023.9173 | AB31: 1063.629 | AC31: 1103.2208 | AD31: 1142.6521 | AE31: 1181.8848 | AF31: 1220.8802 | AG31: 1259.598 | AH31: 1298.0002 | AI31: 1336.053 | AJ31: 1373.7223 | AK31: 1410.9761 | AL31: 1447.7826 | AM31: 1484.1112 | AN31: 1519.9343 | AO31: 1555.2251 | AP31: 1589.9589
A32: Firewood (biomass) | B32: 7276 | C32: 6112.1163 | D32: 6114.2115 | E32: 6213.2603 | F32: 6203.2166 | G32: 6184.927 | H32: 6158.3735 | I32: 6123.4708 | J32: 6080.0731 | K32: 6028.1125 | L32: 5967.5257 | M32: 6097.0064 | N32: 6226.133 | O32: 6354.8414 | P32: 6483.0315 | Q32: 6610.6139 | R32: 6737.4877 | S32: 6863.5581 | T32: 6988.7421 | U32: 7112.9376 | V32: 7236.0334 | W32: 7357.9477 | X32: 7478.8114 | Y32: 7598.4684 | Z32: 7716.7673 | AA32: 7833.5551 | AB32: 7948.6707 | AC32: 8061.9571 | AD32: 8173.2732 | AE32: 8282.4979 | AF32: 8389.5122 | AG32: 8494.1857 | AH32: 8596.4083 | AI32: 8696.0977 | AJ32: 8793.17 | AK32: 8887.5541 | AL32: 8979.1797 | AM32: 9067.9805 | AN32: 9153.9096 | AO32: 9236.9223 | AP32: 9316.9824
A33: LPG | B33: 6203.53 | C33: 6287.6665 | D33: 6286.6372 | E33: 6390.8767 | F33: 6388.7391 | G33: 6384.0668 | H33: 6376.9849 | I33: 6367.5406 | J33: 6355.7094 | K33: 6341.5384 | L33: 6325.0701 | M33: 6319.5874 | N33: 6311.8077 | O33: 6301.772 | P33: 6289.4863 | Q33: 6274.9692 | R33: 6258.2306 | S33: 6239.2885 | T33: 6218.1732 | U33: 6194.8992 | V33: 6169.4756 | W33: 6141.9386 | X33: 6112.4989 | Y33: 6081.1235 | Z33: 6047.7891 | AA33: 6012.4762 | AB33: 5975.1643 | AC33: 5935.8413 | AD33: 5894.5113 | AE33: 5851.1958 | AF33: 5805.9202 | AG33: 5758.7036 | AH33: 5709.5816 | AI33: 5658.6088 | AJ33: 5605.8383 | AK33: 5551.3312 | AL33: 5495.1482 | AM33: 5437.3515 | AN33: 5378.0137 | AO33: 5317.2068 | AP33: 5255.0056
A34: Charcoal (biomass) | B34: 509 | C34: 444.70434 | D34: 428.42003 | E34: 419.13337 | F34: 402.7024 | G34: 386.22728 | H34: 369.73874 | I34: 353.26181 | J34: 336.81715 | K34: 320.42915 | L34: 304.12143 | M34: 301.21182 | N34: 298.15614 | O34: 294.95838 | P34: 291.6209 | Q34: 288.14671 | R34: 284.53845 | S34: 280.79917 | T34: 276.93253 | U34: 272.94149 | V34: 268.82886 | W34: 264.59864 | X34: 260.26231 | Y34: 255.82073 | Z34: 251.27533 | AA34: 246.62781 | AB34: 241.87997 | AC34: 237.0341 | AD34: 232.09323 | AE34: 227.06119 | AF34: 221.94198 | AG34: 216.73948 | AH34: 211.45819 | AI34: 206.10337 | AJ34: 200.68022 | AK34: 195.19419 | AL34: 189.65072 | AM34: 184.05526 | AN34: 178.41355 | AO34: 172.73127 | AP34: 167.01413

Sheet commercial-residential-cooling
A1: Notes:
A2: 1. According to MOP Building Book, the approach to estimate commercial cooling follows an indirect method, c
A3: onsidering that in the commercial sector there is no disaggregated statistics on sales or ownership of air conditioning equipment.
A4: Additionally, only air conditioning is considered, disregarding the ventilators;
A5: 2. MOP computes the energy demand in ktep, to convert to BTU we assume the factor: 1 tep = 3,968e+7 BTU or 1 ktep = 3,968e+10 BTU;
A6: 3.9683051e+10
A8: Figure 122 - Total Energy Consumption by End Use in the Commercial, Services and Public Sectors in the REF scenario (2010-2050)
A31: Sector | B31: Demand | C31: Energetic / End Use | D31: 2010 | E31: 2011 | F31: 2012 | G31: 2013 | H31: 2014 | I31: 2015 | J31: 2016 | K31: 2017 | L31: 2018 | M31: 2019 | N31: 2020 | O31: 2021 | P31: 2022 | Q31: 2023 | R31: 2024 | S31: 2025 | T31: 2026 | U31: 2027 | V31: 2028 | W31: 2029 | X31: 2030 | Y31: 2031 | Z31: 2032 | AA31: 2033 | AB31: 2034 | AC31: 2035 | AD31: 2036 | AE31: 2037 | AF31: 2038 | AG31: 2039 | AH31: 2040 | AI31: 2041 | AJ31: 2042 | AK31: 2043 | AL31: 2044 | AM31: 2045 | AN31: 2046 | AO31: 2047 | AP31: 2048 | AQ31: 2049 | AR31: 2050
A32: Residential | B32: Water heating | C32: Natural gas | D32: 143
A33: Residential | B33: Water heating | C33: LPG | D33: 94.47
A34: Residential | B34: Water heating | C34: Electricity | D34: 1649
A35: Residential | B35: Water heating | C35: Solar | D35: 0
A36: Residential | B36: Cooking | C36: Natural gas | D36: 112
A37: Residential | B37: Cooking | C37: LPG | D37: 6203.53
A38: Residential | B38: Cooking | C38: Firewood | D38: 7276
A39: Residential | B39: Cooking | C39: Charcoal | D39: 509
A40: Residential | B40: Cooking | C40: Electricity | D40: 0 | E40: 0 | F40: 0 | G40: 0 | H40: 0 | I40: 0 | J40: 0 | K40: 0 | L40: 0 | M40: 0 | N40: 0 | O40: 0 | P40: 0 | Q40: 0 | R40: 0 | S40: 0 | T40: 0 | U40: 0 | V40: 0 | W40: 0 | X40: 0 | Y40: 0 | Z40: 0 | AA40: 0 | AB40: 0 | AC40: 0 | AD40: 0 | AE40: 0 | AF40: 0 | AG40: 0 | AH40: 0 | AI40: 0 | AJ40: 0 | AK40: 0 | AL40: 0 | AM40: 0 | AN40: 0 | AO40: 0 | AP40: 0 | AQ40: 0 | AR40: 0
A41: Residential | B41: Cooking | C41: Solar | D41: 0 | E41: 0 | F41: 0 | G41: 0 | H41: 0 | I41: 0 | J41: 0 | K41: 0 | L41: 0 | M41: 0 | N41: 0 | O41: 0 | P41: 0 | Q41: 0 | R41: 0 | S41: 0 | T41: 0 | U41: 0 | V41: 0 | W41: 0 | X41: 0 | Y41: 0 | Z41: 0 | AA41: 0 | AB41: 0 | AC41: 0 | AD41: 0 | AE41: 0 | AF41: 0 | AG41: 0 | AH41: 0 | AI41: 0 | AJ41: 0 | AK41: 0 | AL41: 0 | AM41: 0 | AN41: 0 | AO41: 0 | AP41: 0 | AQ41: 0 | AR41: 0
A42: Residential | B42: Lighting | C42: Electricity | D42: 1469.5035 | E42: 1510.4945 | F42: 1554.129 | G42: 1561.5737 | H42: 1597.2765 | I42: 1633.2376 | J42: 840.54232 | K42: 860.87933 | L42: 881.41056 | M42: 902.1359 | N42: 923.05523 | O42: 943.27573 | P42: 963.67751 | Q42: 984.26111 | R42: 1005.0261 | S42: 1025.9722 | T42: 1047.0981 | U42: 1068.4031 | V42: 1089.8876 | W42: 1111.5506 | X42: 1133.3915 | Y42: 1153.3292 | Z42: 1173.4237 | AA42: 1193.6749 | AB42: 1214.0829 | AC42: 1234.6476 | AD42: 1255.3691 | AE42: 1276.2474 | AF42: 1297.2824 | AG42: 1318.4741 | AH42: 1339.8227 | AI42: 1357.4019 | AJ42: 1375.0937 | AK42: 1392.8981 | AL42: 1410.8149 | AM42: 1428.8443 | AN42: 1446.9863 | AO42: 1465.2408 | AP42: 1483.6078 | AQ42: 1502.0873 | AR42: 1520.6794
A43: Residential | B43: Climatization | C43: Electricity | D43: 503 | E43: 533.32042 | F43: 572.10388 | G43: 610.31558 | H43: 660.48007 | I43: 711.10575 | J43: 758.78876 | K43: 811.23331 | L43: 871.4355 | M43: 932.29996 | N43: 986.67045 | O43: 1033.7892 | P43: 1073.513 | Q43: 1105.7979 | R43: 1135.5336 | S43: 1165.1267 | T43: 1194.5644 | U43: 1223.822 | V43: 1252.8592 | W43: 1281.6492 | X43: 1310.1654 | Y43: 1337.1299 | Z43: 1364.3634 | AA43: 1391.1548 | AB43: 1417.4795 | AC43: 1443.3122 | AD43: 1468.6267 | AE43: 1493.3959 | AF43: 1517.5919 | AG43: 1541.1861 | AH43: 1564.1487 | AI43: 1584.8023 | AJ43: 1604.6151 | AK43: 1623.5704 | AL43: 1641.6511 | AM43: 1658.8399 | AN43: 1675.1192 | AO43: 1690.471 | AP43: 1704.8769 | AQ43: 1718.3186 | AR43: 1730.7769
A44: Residential | B44: Cooling | C44: Electricity | D44: 2113 | E44: 2179.4516 | F44: 2251.1509 | G44: 2269.8381 | H44: 2330.3514 | I44: 2391.3793 | J44: 2452.9241 | K44: 2514.9756 | L44: 2577.5072 | M44: 2640.5049 | N44: 2703.9554 | O44: 2765.204 | P44: 2826.8313 | Q44: 2888.838 | R44: 2951.2124 | S44: 3013.9425 | T44: 3077.0059 | U44: 3140.3904 | V44: 3204.0957 | W44: 3268.1098 | X44: 3332.4199 | Y44: 3390.5292 | Z44: 3448.8307 | AA44: 3507.3146 | AB44: 3565.9711 | AC44: 3624.7903 | AD44: 3683.7625 | AE44: 3742.8775 | AF44: 3802.1255 | AG44: 3861.4964 | AH44: 3920.9801 | AI44: 3969.0867 | AJ44: 4017.1773 | AK44: 4065.2443 | AL44: 4113.28 | AM44: 4161.2767 | AN44: 4209.2265 | AO44: 4257.1217 | AP44: 4304.9544 | AQ44: 4352.7167 | AR44: 4400.4008
A45: Residential | B45: Others | C45: Electricity | D45: 3485 | E45: 3716.0276 | F45: 3864.0408 | G45: 3971.2619 | H45: 4140.8104 | I45: 4324.4473 | J45: 4516.6381 | K45: 4727.5973 | L45: 4960.2854 | M45: 5218.2018 | N45: 5505.4717 | O45: 5605.1595 | P45: 5806.5187 | Q45: 5933.718 | R45: 6085.7212 | S45: 6244.9617 | T45: 6412.285 | U45: 6588.1474 | V45: 6773.3026 | W45: 6813.1499 | X45: 6910.4825 | Y45: 6997.4141 | Z45: 7094.1214 | AA45: 7191.3229 | AB45: 7288.9952 | AC45: 7387.1176 | AD45: 7485.3369 | AE45: 7583.9646 | AF45: 7682.9819 | AG45: 7782.3747 | AH45: 7882.1347 | AI45: 7962.7447 | AJ45: 8049.6705 | AK45: 8136.75 | AL45: 8223.9861 | AM45: 8311.381 | AN45: 8398.9255 | AO45: 8486.6393 | AP45: 8574.5283 | AQ45: 8662.6028 | AR45: 8750.873
A46: Residential | B46: Lighting | C46: Kerosene | D46: 4
A47: Commercial | B47: Water heating | C47: Natural gas
A48: Commercial | B48: Water heating | C48: LPG
A49: Commercial | B49: Water heating | C49: Electricity
A50: Commercial | B50: Water heating | C50: Solar
A51: Commercial | B51: Cooking | C51: Natural gas
A52: Commercial | B52: Cooking | C52: LPG
A53: Commercial | B53: Cooking | C53: Firewood
A54: Commercial | B54: Cooking | C54: Charcoal
A55: Commercial | B55: Cooking | C55: Electricity
A56: Commercial | B56: Cooking | C56: Solar
A57: Commercial | B57: Climatization | C57: Natural gas
A58: Commercial | B58: Climatization | C58: Electricity | D58: 1262 | E58: 1436 | F58: 1609 | G58: 1783 | H58: 1956 | I58: 2130 | J58: 2303 | K58: 2477 | L58: 2650 | M58: 2824 | N58: 2997 | O58: 3171 | P58: 3345 | Q58: 3518 | R58: 3692 | S58: 3865 | T58: 4039 | U58: 4212 | V58: 4386 | W58: 4559 | X58: 4733 | Y58: 4906 | Z58: 5080 | AA58: 5253 | AB58: 5427 | AC58: 5601 | AD58: 5774 | AE58: 5948 | AF58: 6121 | AG58: 6295 | AH58: 6468 | AI58: 6642 | AJ58: 6815 | AK58: 6989 | AL58: 7162 | AM58: 7336 | AN58: 7509 | AO58: 7683 | AP58: 7857 | AQ58: 8030 | AR58: 8204
A59: Commercial | B59: Climatization | C59: Solar
A60: Commercial | B60: Lighting | C60: Electricity
A61: Commercial | B61: Street lighting | C61: Electricity
A62: Commercial | B62: Cooling | C62: Electricity
A63: Commercial | B63: Others | C63: Electricity
...

Sheet commercial-residential-lighting
A1: Notes:
A2: 1. According to MOP's analysis the lighting for commercial sector track the energy demand for commercial building and street lighting;
A3: 2. MOP computes the energy demand in MWh, to convert to BTU we assume the factor: 1 Wh = 3.412128 BTU or 1 MWh = 3412128.220 BTU;
A4: 3412128.2
A6: Figure 112 - Energy Consumption of Public Lighting in the REF Scenario (2010-2050) | I6: Table 69 - Energy Consumption of the Commercial Sector and Services in the REF Scenario (2050 in ktep)
A28: The table below is from the excel file that generated the results for buildings sector.
A30: Commercial | C30: 2010 | D30: 2011 | E30: 2012 | F30: 2013 | G30: 2014 | H30: 2015 | I30: 2016 | J30: 2017 | K30: 2018 | L30: 2019 | M30: 2020 | N30: 2021 | O30: 2022 | P30: 2023 | Q30: 2024 | R30: 2025 | S30: 2026 | T30: 2027 | U30: 2028 | V30: 2029 | W30: 2030 | X30: 2031 | Y30: 2032 | Z30: 2033 | AA30: 2034 | AB30: 2035 | AC30: 2036 | AD30: 2037 | AE30: 2038 | AF30: 2039 | AG30: 2040 | AH30: 2041 | AI30: 2042 | AJ30: 2043 | AK30: 2044 | AL30: 2045 | AM30: 2046 | AN30: 2047 | AO30: 2048 | AP30: 2049 | AQ30: 2050
A31: Total consumption | B31: MWh | C31: 37543097 | D31: 35179381 | E31: 32792513 | F31: 30380304 | G31: 27940762 | H31: 25472062 | I31: 25352523 | J31: 25237069 | K31: 25125539 | L31: 25017780 | M31: 24913647 | N31: 25084365 | O31: 25254708 | P31: 25424601 | Q31: 25593964 | R31: 25762716 | S31: 25961468 | T31: 26159920 | U31: 26357997 | V31: 26555626 | W31: 26752730 | X31: 26935005 | Y31: 27116527 | Z31: 27297224 | AA31: 27477023 | AB31: 27655846 | AC31: 27806611 | AD31: 27956060 | AE31: 28104120 | AF31: 28250720 | AG31: 28395784 | AH31: 28711936 | AI31: 29031760 | AJ31: 29355302 | AK31: 29682604 | AL31: 30013712 | AM31: 30306298 | AN31: 30601887 | AO31: 30900511 | AP31: 31202202 | AQ31: 31506992
A32: CONSUMPTION - INC | B32: MWh
A33: Southeast | C33: 6299517.3 | D33: 5084593.9 | E33: 3847481.6 | F33: 2587881 | G33: 1305489.3 | H33: 0 | I33: 0 | J33: 0 | K33: 0 | L33: 0 | M33: 0 | N33: 0 | O33: 0 | P33: 0 | Q33: 0 | R33: 0 | S33: 0 | T33: 0 | U33: 0 | V33: 0 | W33: 0 | X33: 0 | Y33: 0 | Z33: 0 | AA33: 0 | AB33: 0 | AC33: 0 | AD33: 0 | AE33: 0 | AF33: 0 | AG33: 0 | AH33: 0 | AI33: 0 | AJ33: 0 | AK33: 0 | AL33: 0 | AM33: 0 | AN33: 0 | AO33: 0 | AP33: 0 | AQ33: 0
A34: South | C34: 1915389.1 | D34: 1545987.6 | E34: 1169839.5 | F34: 786853.78 | G34: 396938.35 | H34: 0 | I34: 0 | J34: 0 | K34: 0 | L34: 0 | M34: 0 | N34: 0 | O34: 0 | P34: 0 | Q34: 0 | R34: 0 | S34: 0 | T34: 0 | U34: 0 | V34: 0 | W34: 0 | X34: 0 | Y34: 0 | Z34: 0 | AA34: 0 | AB34: 0 | AC34: 0 | AD34: 0 | AE34: 0 | AF34: 0 | AG34: 0 | AH34: 0 | AI34: 0 | AJ34: 0 | AK34: 0 | AL34: 0 | AM34: 0 | AN34: 0 | AO34: 0 | AP34: 0 | AQ34: 0
A35: Midwest | C35: 986824.99 | D35: 796506.16 | E35: 602711.42 | F35: 405393.87 | G35: 204506.06 | H35: 0 | I35: 0 | J35: 0 | K35: 0 | L35: 0 | M35: 0 | N35: 0 | O35: 0 | P35: 0 | Q35: 0 | R35: 0 | S35: 0 | T35: 0 | U35: 0 | V35: 0 | W35: 0 | X35: 0 | Y35: 0 | Z35: 0 | AA35: 0 | AB35: 0 | AC35: 0 | AD35: 0 | AE35: 0 | AF35: 0 | AG35: 0 | AH35: 0 | AI35: 0 | AJ35: 0 | AK35: 0 | AL35: 0 | AM35: 0 | AN35: 0 | AO35: 0 | AP35: 0 | AQ35: 0
A36: North | C36: 702864.22 | D36: 567310 | E36: 429280.06 | F36: 288741.01 | G36: 145659.05 | H36: 0 | I36: 0 | J36: 0 | K36: 0 | L36: 0 | M36: 0 | N36: 0 | O36: 0 | P36: 0 | Q36: 0 | R36: 0 | S36: 0 | T36: 0 | U36: 0 | V36: 0 | W36: 0 | X36: 0 | Y36: 0 | Z36: 0 | AA36: 0 | AB36: 0 | AC36: 0 | AD36: 0 | AE36: 0 | AF36: 0 | AG36: 0 | AH36: 0 | AI36: 0 | AJ36: 0 | AK36: 0 | AL36: 0 | AM36: 0 | AN36: 0 | AO36: 0 | AP36: 0 | AQ36: 0
A37: Northeast | C37: 1873631 | D37: 1512283 | E37: 1144335.4 | F37: 769699.3 | G37: 388284.55 | H37: 0 | I37: 0 | J37: 0 | K37: 0 | L37: 0 | M37: 0 | N37: 0 | O37: 0 | P37: 0 | Q37: 0 | R37: 0 | S37: 0 | T37: 0 | U37: 0 | V37: 0 | W37: 0 | X37: 0 | Y37: 0 | Z37: 0 | AA37: 0 | AB37: 0 | AC37: 0 | AD37: 0 | AE37: 0 | AF37: 0 | AG37: 0 | AH37: 0 | AI37: 0 | AJ37: 0 | AK37: 0 | AL37: 0 | AM37: 0 | AN37: 0 | AO37: 0 | AP37: 0 | AQ37: 0
A39: CONSUMPTION - FC | B39: MWh
A40: Southeast | C40: 2952898.7 | D40: 3086712.7 | E40: 3216633.6 | F40: 3343023.7 | G40: 3466207.7 | H40: 3586477.3 | I40: 3493393.9 | J40: 3400699.4 | K40: 3308337.7 | L40: 3216255.1 | M40: 3124399.3 | N40: 3082560.7 | O40: 3038217.4 | P40: 2991292.9 | Q40: 2941708.9 | R40: 2889385.3 | S40: 2833351.9 | T40: 2774448.8 | U40: 2712592.2 | V40: 2647696.3 | W40: 2579673.3 | X40: 2505030.6 | Y40: 2427285.2 | Z40: 2346356.2 | AA40: 2262160.6 | AB40: 2174613.8 | AC40: 2080494 | AD40: 1983136.7 | AE40: 1882467.1 | AF40: 1778408.8 | AG40: 1670883.9 | AH40: 1692969.1 | AI40: 1715346.2 | AJ40: 1738019.1 | AK40: 1760991.7 | AL40: 1784267.9 | AM40: 1805238.4 | AN40: 1826455.4 | AO40: 1847921.7 | AP40: 1869640.4 | AQ40: 1891614.2
A41: South | C41: 897838.63 | D41: 938525.21 | E41: 978028.08 | F41: 1016457.4 | G41: 1053911.9 | H41: 1090480.3 | I41: 1062178 | J41: 1033993.9 | K41: 1005911 | L41: 977913 | M41: 949983.94 | N41: 937262.79 | O41: 923780.05 | P41: 909512.5 | Q41: 894436.34 | R41: 878527.15 | S41: 861490.03 | T41: 843580.34 | U41: 824772.63 | V41: 805040.82 | W41: 784358.21 | X41: 761662.84 | Y41: 738024.11 | Z41: 713417.37 | AA41: 687817.42 | AB41: 661198.52 | AC41: 632581.08 | AD41: 602979.28 | AE41: 572370.34 | AF41: 540731.07 | AG41: 508037.77 | AH41: 514752.85 | AI41: 521556.69 | AJ41: 528450.46 | AK41: 535435.35 | AL41: 542512.57 | AM41: 548888.72 | AN41: 555339.81 | AO41: 561866.72 | AP41: 568470.34 | AQ41: 575151.57
A42: Midwest | C42: 462574.22 | D42: 483536.3 | E42: 503888.52 | F42: 523687.64 | G42: 542984.53 | H42: 561824.87 | I42: 547243.27 | J42: 532722.58 | K42: 518254.05 | L42: 503829.23 | M42: 489439.93 | N42: 482885.89 | O42: 475939.46 | P42: 468588.7 | Q42: 460821.33 | R42: 452624.78 | S42: 443847.1 | T42: 434619.88 | U42: 424929.98 | V42: 414763.99 | W42: 404108.13 | X42: 392415.27 | Y42: 380236.39 | Z42: 367558.79 | AA42: 354369.48 | AB42: 340655.19 | AC42: 325911.24 | AD42: 310660.13 | AE42: 294890.15 | AF42: 278589.32 | AG42: 261745.45 | AH42: 265205.12 | AI42: 268710.51 | AJ42: 272262.24 | AK42: 275860.92 | AL42: 279507.16 | AM42: 282792.21 | AN42: 286115.87 | AO42: 289478.59 | AP42: 292880.83 | AQ42: 296323.06
A43: North | C43: 329467.6 | D43: 344397.81 | E43: 358893.63 | F43: 372995.52 | G43: 386739.69 | H43: 400158.69 | I43: 389772.98 | J43: 379430.64 | K43: 369125.46 | L43: 358851.41 | M43: 348602.66 | N43: 343934.55 | O43: 338986.97 | P43: 333751.41 | Q43: 328219.11 | R43: 322381.13 | S43: 316129.25 | T43: 309557.18 | U43: 302655.57 | V43: 295414.86 | W43: 287825.24 | X43: 279497.03 | Y43: 270822.65 | Z43: 261793.05 | AA43: 252398.98 | AB43: 242631.01 | AC43: 232129.66 | AD43: 221267.09 | AE43: 210034.94 | AF43: 198424.71 | AG43: 186427.7 | AH43: 188891.84 | AI43: 191388.55 | AJ43: 193918.26 | AK43: 196481.41 | AL43: 199078.44 | AM43: 201418.21 | AN43: 203785.48 | AO43: 206180.57 | AP43: 208603.81 | AQ43: 211055.53
A44: Northeast | C44: 878264.52 | D44: 918064.09 | E44: 956705.74 | F44: 994297.26 | G44: 1030935.2 | H44: 1066706.3 | I44: 1039021.1 | J44: 1011451.4 | K44: 983980.8 | L44: 956593.17 | M44: 929273 | N44: 916829.18 | O44: 903640.39 | P44: 889683.89 | Q44: 874936.41 | R44: 859374.06 | S44: 842708.37 | T44: 825189.14 | U44: 806791.46 | V44: 787489.84 | W44: 767258.13 | X44: 745057.55 | Y44: 721934.18 | Z44: 697863.9 | AA44: 672822.07 | AB44: 646783.49 | AC44: 618789.95 | AD44: 589833.51 | AE44: 559891.89 | AF44: 528942.39 | AG44: 496961.85 | AH44: 503530.54 | AI44: 510186.05 | AJ44: 516929.52 | AK44: 523762.13 | AL44: 530685.06 | AM44: 536922.2 | AN44: 543232.64 | AO44: 549617.26 | AP44: 556076.91 | AQ44: 562612.48
A46: CONSUMPTION - FT | B46: MWh
A47: Southeast | C47: 10827295 | D47: 10597530 | E47: 10383466 | F47: 10183684 | G47: 9996932 | H47: 9822101 | I47: 9569592.7 | J47: 9317964.4 | K47: 9067070.4 | L47: 8816769.7 | M47: 8566925.9 | N47: 8395083.3 | O47: 8218772.1 | P47: 8037876.6 | Q47: 7852278.7 | R47: 7661858.4 | S47: 7478357.2 | T47: 7289014.1 | U47: 7093691 | V47: 6892246.9 | W47: 6684537.9 | X47: 6468230.6 | Y47: 6245460.4 | Z47: 6016087.3 | AA47: 5779968.9 | AB47: 5536959.7 | AC47: 5282305.4 | AD47: 5020893.4 | AE47: 4752591.8 | AF47: 4477266.3 | AG47: 4194780.6 | AH47: 4240182.7 | AI47: 4286100.1 | AJ47: 4332538.9 | AK47: 4379505 | AL47: 4427004.6 | AM47: 4469971.3 | AN47: 4513373.4 | AO47: 4557215.6 | AP47: 4601502.3 | AQ47: 4646238.2
A48: South | C48: 3292075 | D48: 3222214.1 | E48: 3157127.3 | F48: 3096382.9 | G48: 3039600.3 | H48: 2986442.3 | I48: 2909666.3 | J48: 2833157.9 | K48: 2756872.7 | L48: 2680768 | M48: 2604802.2 | N48: 2552552.9 | O48: 2498944.9 | P48: 2443943 | Q48: 2387511.3 | R48: 2329613.4 | S48: 2273819.2 | T48: 2216248.9 | U48: 2156860.2 | V48: 2095610.5 | W48: 2032455.9 | X48: 1966686.9 | Y48: 1898952.9 | Z48: 1829211.3 | AA48: 1757418.7 | AB48: 1683530.9 | AC48: 1606102.4 | AD48: 1526619.3 | AE48: 1445041.2 | AF48: 1361327.6 | AG48: 1275436.9 | AH48: 1289241.6 | AI48: 1303202.9 | AJ48: 1317322.8 | AK48: 1331603 | AL48: 1346045.4 | AM48: 1359109.6 | AN48: 1372306.1 | AO48: 1385636.5 | AP48: 1399102 | AQ48: 1412704.1
A49: Midwest | C49: 1696105.5 | D49: 1660112.5 | E49: 1626579.3 | F49: 1595283.2 | G49: 1566028.3 | H49: 1538640.9 | I49: 1499085.2 | J49: 1459667.4 | K49: 1420364.7 | L49: 1381154.8 | M49: 1342016.6 | N49: 1315097.3 | O49: 1287478 | P49: 1259140.5 | Q49: 1230066.4 | R49: 1200236.9 | S49: 1171491.3 | T49: 1141830.6 | U49: 1111233 | V49: 1079676.6 | W49: 1047138.8 | X49: 1013254.1 | Y49: 978356.93 | Z49: 942425.44 | AA49: 905437.28 | AB49: 867369.67 | AC49: 827477.85 | AD49: 786527.43 | AE49: 744497.73 | AF49: 701367.76 | AG49: 657116.12 | AH49: 664228.4 | AI49: 671421.41 | AJ49: 678696.08 | AK49: 686053.36 | AL49: 693494.22 | AM49: 700224.99 | AN49: 707023.97 | AO49: 713891.88 | AP49: 720829.44 | AQ49: 727837.36
A50: North | C50: 1208047.9 | D50: 1182412 | E50: 1158528 | F50: 1136237.4 | G50: 1115400.7 | H50: 1095894 | I50: 1067720.6 | J50: 1039645.3 | K50: 1011652 | L50: 983724.9 | M50: 955848.75 | N50: 936675.53 | O50: 917003.73 | P50: 896820.44 | Q50: 876112.48 | R50: 854866.48 | S50: 834392.45 | T50: 813266.64 | U50: 791473.6 | V50: 768997.62 | W50: 745822.63 | X50: 721688.29 | Y50: 696832.86 | Z50: 671240.72 | AA50: 644895.97 | AB50: 617782.39 | AC50: 589369.52 | AD50: 560202.66 | AE50: 530267.09 | AF50: 499547.85 | AG50: 468029.7 | AH50: 473095.41 | AI50: 478218.62 | AJ50: 483399.99 | AK50: 488640.2 | AL50: 493939.94 | AM50: 498733.91 | AN50: 503576.48 | AO50: 508468.13 | AP50: 513409.39 | AQ50: 518400.77
A51: Northeast | C51: 3220303.2 | D51: 3151965.4 | E51: 3088297.7 | F51: 3028877.6 | G51: 2973332.8 | H51: 2921333.8 | I51: 2846231.6 | J51: 2771391.2 | K51: 2696769.2 | L51: 2622323.6 | M51: 2548013.9 | N51: 2496903.7 | O51: 2444464.5 | P51: 2390661.7 | Q51: 2335460.3 | R51: 2278824.7 | S51: 2224246.9 | T51: 2167931.6 | U51: 2109837.7 | V51: 2049923.3 | W51: 1988145.6 | X51: 1923810.5 | Y51: 1857553.1 | Z51: 1789332 | AA51: 1719104.5 | AB51: 1646827.6 | AC51: 1571087.2 | AD51: 1493336.9 | AE51: 1413537.4 | AF51: 1331648.8 | AG51: 1247630.7 | AH51: 1261134.4 | AI51: 1274791.3 | AJ51: 1288603.4 | AK51: 1302572.2 | AL51: 1316699.8 | AM51: 1329479.1 | AN51: 1342388 | AO51: 1355427.7 | AP51: 1368599.7 | AQ51: 1381905.2
A53: CONSUMPTION - LED | B53: MWh
A54: Southeast | C54: 0 | D54: 46654.529 | E54: 91306.811 | F54: 134142.95 | G54: 175328.02 | H54: 215008.98 | I54: 496665.89 | J54: 779238.58 | K54: 1062842.9 | L54: 1347592 | M54: 1633596.7 | N54: 1938585.3 | O54: 2250347.1 | P54: 2569033.4 | Q54: 2894798 | R54: 3227797.8 | S54: 3573634.2 | T54: 3928020.9 | U54: 4291141.2 | V54: 4663181.9 | W54: 5044333.8 | X54: 5432772.8 | Y54: 5830374.4 | Z54: 6237321.2 | AA54: 6653799.3 | AB54: 7079998 | AC54: 7509408 | AD54: 7948108.9 | AE54: 8396269.4 | AF54: 8854061.1 | AG54: 9321658.8 | AH54: 9423263.2 | AI54: 9526025 | AJ54: 9629957.6 | AK54: 9735074.7 | AL54: 9841389.9 | AM54: 9933940.6 | AN54: 10027416 | AO54: 10121825 | AP54: 10217177 | AQ54: 10313483
A55: South | C55: 0 | D55: 14185.464 | E55: 27762.138 | F55: 40786.607 | G55: 53309.063 | H55: 65374.191 | I55: 151012.91 | J55: 236930.07 | K55: 323160.9 | L55: 409739.82 | M55: 496700.48 | N55: 589433.27 | O55: 684225.49 | P55: 781123.11 | Q55: 880172.92 | R55: 981422.6 | S55: 1086575.3 | T55: 1194327.8 | U55: 1304735.7 | V55: 1417855.9 | W55: 1533746.4 | X55: 1651852.5 | Y55: 1772744.6 | Z55: 1896478.2 | AA55: 2023109.7 | AB55: 2152696.8 | AC55: 2283260.4 | AD55: 2416648.8 | AE55: 2552913.5 | AF55: 2692106.6 | AG55: 2834281.2 | AH55: 2865174.4 | AI55: 2896419.4 | AJ55: 2928020.5 | AK55: 2959981.7 | AL55: 2992307.2 | AM55: 3020447.5 | AN55: 3048868.9 | AO55: 3077574.3 | AP55: 3106566.5 | AQ55: 3135848.5
A56: Midwest | C56: 0 | D56: 7308.4735 | E56: 14303.293 | F56: 21013.612 | G56: 27465.29 | H56: 33681.348 | I56: 77803.155 | J56: 122068.42 | K56: 166495.29 | L56: 211101.49 | M56: 255904.38 | N56: 303681.11 | O56: 352518.89 | P56: 402441.37 | Q56: 453472.69 | R56: 505637.4 | S56: 559812.99 | T56: 615327.97 | U56: 672211.09 | V56: 730491.61 | W56: 790199.39 | X56: 851048.69 | Y56: 913333.34 | Z56: 977081.93 | AA56: 1042323.6 | AB56: 1109088 | AC56: 1176355.5 | AD56: 1245078.3 | AE56: 1315283.1 | AF56: 1386996.6 | AG56: 1460246.1 | AH56: 1476162.6 | AI56: 1492260.3 | AJ56: 1508541.4 | AK56: 1525008.1 | AL56: 1541662.5 | AM56: 1556160.6 | AN56: 1570803.6 | AO56: 1585592.9 | AP56: 1600529.9 | AQ56: 1615616.2
A57: North | C57: 0 | D57: 5205.4463 | E57: 10187.493 | F57: 14966.905 | G57: 19562.1 | H57: 23989.476 | I57: 55415.149 | J57: 86942.998 | K57: 118585.95 | L57: 150356.64 | M57: 182267.4 | N57: 216296.29 | O57: 251080.9 | P57: 286638.1 | Q57: 322985.06 | R57: 360139.28 | S57: 398725.73 | T57: 438266.18 | U57: 478781.06 | V57: 520291.25 | W57: 562818.01 | X57: 606157.81 | Y57: 650519.93 | Z57: 695924.74 | AA57: 742392.99 | AB57: 789945.81 | AC57: 837856.93 | AD57: 886804.67 | AE57: 936807.86 | AF57: 987885.66 | AG57: 1040057.5 | AH57: 1051394 | AI57: 1062859.6 | AJ57: 1074455.8 | AK57: 1086184.1 | AL57: 1098046.2 | AM57: 1108372.5 | AN57: 1118801.9 | AO57: 1129335.5 | AP57: 1139974.4 | AQ57: 1150719.6
A58: Northeast | C58: 0 | D58: 13876.201 | E58: 27156.886 | F58: 39897.403 | G58: 52146.853 | H58: 63948.944 | I58: 147720.62 | J58: 231764.67 | K58: 316115.55 | L58: 400806.93 | M58: 485871.73 | N58: 576582.82 | O58: 669308.45 | P58: 764093.56 | Q58: 860983.96 | R58: 960026.25 | S58: 1062886.5 | T58: 1168289.8 | U58: 1276290.7 | V58: 1386944.7 | W58: 1500308.6 | X58: 1615839.9 | Y58: 1734096.4 | Z58: 1855132.3 | AA58: 1979003.1 | AB58: 2105765.1 | AC58: 2233482.2 | AD58: 2363962.6 | AE58: 2497256.5 | AF58: 2633415 | AG58: 2772490 | AH58: 2802709.7 | AI58: 2833273.5 | AJ58: 2864185.6 | AK58: 2895450 | AL58: 2927070.8 | AM58: 2954597.6 | AN58: 2982399.4 | AO58: 3010479 | AP58: 3038839.1 | AQ58: 3067482.7
A60: Street Lighting
A61: TOTAL CONSUMPTION | B61: MWh | C61: 12804741 | D61: 13101128 | E61: 13073554 | F61: 12730026 | G61: 12615503 | H61: 12488258 | I61: 12348343 | J61: 12371182 | K61: 12387389 | L61: 12396936 | M61: 12399798 | N61: 12384013 | O61: 12485791 | P61: 12585019 | Q61: 12681694 | R61: 12775807 | S61: 12867311 | T61: 13015877 | U61: 13163570 | V61: 13310387 | W61: 13456328 | X61: 13572451 | Y61: 13687690 | Z61: 13802043 | AA61: 13915511 | AB61: 14028093 | AC61: 14139791 | AD61: 14126033 | AE61: 14108734 | AF61: 14087894 | AG61: 14063514 | AH61: 13995115 | AI61: 13837201 | AJ61: 13675474 | AK61: 13509934 | AL61: 13340581 | AM61: 13167416 | AN61: 13260890 | AO61: 13354364 | AP61: 13447838 | AQ61: 13541312
A62: Southeast | C62: 5840598.2 | D62: 5956761.2 | E62: 5928246.5 | F62: 5772299.7 | G62: 5705061.4 | H62: 5632800.7 | I62: 5555624.7 | J62: 5552236.1 | K62: 5546094.8 | L62: 5537127.1 | M62: 5525286.3 | N62: 5505877.2 | O62: 5538509.9 | P62: 5569665.6 | Q62: 5599278.1 | R62: 5627275.2 | S62: 5653500 | T62: 5703985.7 | U62: 5753122.9 | V62: 5800746.9 | W62: 5846624.2 | X62: 5897078.5 | Y62: 5947148.3 | Z62: 5996833.4 | AA62: 6046134 | AB62: 6095049.9 | AC62: 6143581.3 | AD62: 6137603.5 | AE62: 6130087.3 | AF62: 6121032.8 | AG62: 6110439.8 | AH62: 6080721.2 | AI62: 6012109.2 | AJ62: 5941840.6 | AK62: 5869915.3 | AL62: 5796333.5 | AM62: 5721095.1 | AN62: 5761708.6 | AO62: 5802322.1 | AP62: 5842935.5 | AQ62: 5883549
A63: South | C63: 2154584.3 | D63: 2194636.7 | E63: 2192423 | F63: 2134739 | G63: 2109044.6 | H63: 2081619.6 | I63: 2052683.7 | J63: 2051326.1 | K63: 2049079.6 | L63: 2045924.9 | M63: 2041837.7 | N63: 2034904 | O63: 2047179.1 | P63: 2059071.7 | Q63: 2070558.6 | R63: 2081605.4 | S63: 2091996.5 | T63: 2111364.4 | U63: 2130428 | V63: 2149132.2 | W63: 2167412.3 | X63: 2186116.3 | Y63: 2204677.7 | Z63: 2223096.6 | AA63: 2241372.9 | AB63: 2259506.6 | AC63: 2277497.8 | AD63: 2275281.7 | AE63: 2272495.4 | AF63: 2269138.8 | AG63: 2265211.8 | AH63: 2254194.8 | AI63: 2228759.5 | AJ63: 2202710.1 | AK63: 2176046.6 | AL63: 2148768.9 | AM63: 2120877.2 | AN63: 2135933.1 | AO63: 2150989 | AP63: 2166044.9 | AQ63: 2181100.8
A64: Midwest | C64: 1346223.1 | D64: 1391842.8 | E64: 1388053.5 | F64: 1351766.5 | G64: 1356547.3 | H64: 1359597.5 | I64: 1360829.2 | J64: 1379800.4 | K64: 1398133.1 | L64: 1415808 | M64: 1432806.6 | N64: 1446851.4 | O64: 1475014.5 | P64: 1503379.6 | Q64: 1531995.9 | R64: 1560912.3 | S64: 1590244.3 | T64: 1627553.3 | U64: 1665814.5 | V64: 1705168 | W64: 1745803.9 | X64: 1760869.6 | Y64: 1775820.4 | Z64: 1790656.4 | AA64: 1805377.6 | AB64: 1819983.9 | AC64: 1834475.4 | AD64: 1832690.4 | AE64: 1830446.1 | AF64: 1827742.4 | AG64: 1824579.3 | AH64: 1815705.3 | AI64: 1795217.8 | AJ64: 1774235.5 | AK64: 1752758.6 | AL64: 1730787.1 | AM64: 1708320.8 | AN64: 1720448 | AO64: 1732575.2 | AP64: 1744702.5 | AQ64: 1756829.7
A65: North | C65: 697158.3 | D65: 714857.55 | E65: 717327.34 | F65: 698613.22 | G65: 704332.13 | H65: 708842.32 | I65: 712051.26 | J65: 724199.18 | K65: 735739.54 | L65: 746689.36 | M65: 757057.9 | N65: 765589.7 | O65: 781425.45 | P65: 797235.13 | Q65: 813065.35 | R65: 828960.63 | S65: 845008.69 | T65: 865251.62 | U65: 885976.57 | V65: 907286.19 | W65: 929301.14 | X65: 937320.68 | Y65: 945279.1 | Z65: 953176.38 | AA65: 961012.54 | AB65: 968787.56 | AC65: 976501.46 | AD65: 975551.31 | AE65: 974356.64 | AF65: 972917.45 | AG65: 971233.74 | AH65: 966510.06 | AI65: 955604.42 | AJ65: 944435.46 | AK65: 933003.18 | AL65: 921307.6 | AM65: 909348.71 | AN65: 915804.08 | AO65: 922259.46 | AP65: 928714.84 | AQ65: 935170.22
A66: Northeast | C66: 2766177 | D66: 2843030.1 | E66: 2847503.6 | F66: 2772607.7 | G66: 2740517.6 | H66: 2705398.3 | I66: 2667153.9 | J66: 2663620.3 | K66: 2658342.4 | L66: 2651386.6 | M66: 2642809.4 | N66: 2630790.7 | O66: 2643661.7 | P66: 2655667.1 | Q66: 2666796.2 | R66: 2677054 | S66: 2686561.7 | T66: 2707722.3 | U66: 2728227.9 | V66: 2748053.3 | W66: 2767186.4 | X66: 2791066.2 | Y66: 2814764.1 | Z66: 2838279.9 | AA66: 2861613.6 | AB66: 2884765.4 | AC66: 2907735.1 | AD66: 2904905.8 | AE66: 2901348.5 | AF66: 2897063 | AG66: 2892049.4 | AH66: 2877983.6 | AI66: 2845509.8 | AJ66: 2812251.9 | AK66: 2778210 | AL66: 2743384 | AM66: 2707773.9 | AN66: 2726996.1 | AO66: 2746218.3 | AP66: 2765440.5 | AQ66: 2784662.8

Sheet commercial-residential-appl
A1: Notes:
A2: 1. Appliances represent equipaments to water heating and cooking;
A3: 2. MOP computes the electric demand in MWh, to convert to BTU we assume the factor: 1 Wh = 3.412128 BTU or 1 MWh = 3412128.220 BTU;
A4: 3. MOP computes the fuel demand in tep, to convert to BTU we assume the factor: 1 tep = 3,968e+7 BTU.
A5: 3412128.2 | B5: MWh/BTU
A6: 39683051 | B6: TEP/BTU
A8: Table 69 - Energy Consumption of the Commercial Sector and Services in the REF Scenario (2050 in ktep)
A29: The table below is from the excel file that generated the results for buildings sector.
A30: ELECTRIC COOKING - SERVICES | C30: 2010 | D30: 2011 | E30: 2012 | F30: 2013 | G30: 2014 | H30: 2015 | I30: 2016 | J30: 2017 | K30: 2018 | L30: 2019 | M30: 2020 | N30: 2021 | O30: 2022 | P30: 2023 | Q30: 2024 | R30: 2025 | S30: 2026 | T30: 2027 | U30: 2028 | V30: 2029 | W30: 2030 | X30: 2031 | Y30: 2032 | Z30: 2033 | AA30: 2034 | AB30: 2035 | AC30: 2036 | AD30: 2037 | AE30: 2038 | AF30: 2039 | AG30: 2040 | AH30: 2041 | AI30: 2042 | AJ30: 2043 | AK30: 2044 | AL30: 2045 | AM30: 2046 | AN30: 2047 | AO30: 2048 | AP30: 2049 | AQ30: 2050
A31: CONSUMPTION | B31: MWh | C31: 598171.78 | D31: 603510.65 | E31: 608897.16 | F31: 614331.75 | G31: 619814.85 | H31: 625346.89 | I31: 633693.68 | J31: 642151.88 | K31: 650722.97 | L31: 659408.47 | M31: 668209.89 | N31: 680190.9 | O31: 692386.73 | P31: 704801.23 | Q31: 717438.33 | R31: 730302 | S31: 743163.51 | T31: 756251.53 | U31: 769570.04 | V31: 783123.11 | W31: 796914.86 | X31: 809849.48 | Y31: 822994.03 | Z31: 836351.93 | AA31: 849926.64 | AB31: 863721.68 | AC31: 876419.95 | AD31: 889304.9 | AE31: 902379.29 | AF31: 915645.89 | AG31: 929107.54 | AH31: 941388.19 | AI31: 953831.16 | AJ31: 966438.6 | AK31: 901569.33 | AL31: 992155.6 | AM31: 1003816.4 | AN31: 1015614.3 | AO31: 1027550.8 | AP31: 1039627.6 | AQ31: 1051846.3
A32: Southeast | C32: 329963.19 | D32: 332908.21 | E32: 335879.51 | F32: 338877.34 | G32: 341901.92 | H32: 344953.5 | I32: 349557.75 | J32: 354223.46 | K32: 358951.44 | L32: 363742.53 | M32: 368597.57 | N32: 375206.53 | O32: 381933.98 | P32: 388782.06 | Q32: 395752.93 | R32: 402848.78 | S32: 409943.44 | T32: 417163.05 | U32: 424509.8 | V32: 431985.93 | W32: 439593.73 | X32: 446728.72 | Y32: 453979.51 | Z32: 461347.99 | AA32: 468836.06 | AB32: 476445.67 | AC32: 483450.28 | AD32: 490557.88 | AE32: 497769.96 | AF32: 505088.08 | AG32: 512513.78 | AH32: 519288.03 | AI32: 526151.81 | AJ32: 533106.32 | AK32: 540152.75 | AL32: 547292.32 | AM32: 553724.65 | AN32: 560232.57 | AO32: 566816.99 | AP32: 573478.79 | AQ32: 580218.88
A33: South | C33: 101459.04 | D33: 102364.59 | E33: 103278.23 | F33: 104200.02 | G33: 105130.04 | H33: 106068.35 | I33: 107484.1 | J33: 108918.74 | K33: 110372.52 | L33: 111845.72 | M33: 113338.57 | N33: 115370.73 | O33: 117439.33 | P33: 119545.02 | Q33: 121688.46 | R33: 123870.34 | S33: 126051.85 | T33: 128271.77 | U33: 130530.8 | V33: 132829.6 | W33: 135168.89 | X33: 137362.8 | Y33: 139592.32 | Z33: 141858.02 | AA33: 144160.5 | AB33: 146500.35 | AC33: 148654.17 | AD33: 150839.65 | AE33: 153057.27 | AF33: 155307.49 | AG33: 157590.79 | AH33: 159673.77 | AI33: 161784.29 | AJ33: 163922.7 | AK33: 166089.38 | AL33: 168284.7 | AM33: 170262.55 | AN33: 172263.64 | AO33: 174288.26 | AP33: 176336.67 | AQ33: 178409.15
A34: Midwest | C34: 47441.113 | D34: 47864.539 | E34: 48291.745 | F34: 48722.763 | G34: 49157.628 | H34: 49596.375 | I34: 50258.361 | J34: 50929.182 | K34: 51608.957 | L34: 52297.805 | M34: 52995.848 | N34: 53946.064 | O34: 54913.318 | P34: 55897.914 | Q34: 56900.164 | R34: 57920.385 | S34: 58940.433 | T34: 59978.446 | U34: 61034.74 | V34: 62109.636 | W34: 63203.463 | X34: 64229.309 | Y34: 65271.806 | Z34: 66331.224 | AA34: 67407.836 | AB34: 68501.923 | AC34: 69509.025 | AD34: 70530.933 | AE34: 71567.865 | AF34: 72620.042 | AG34: 73687.688 | AH34: 74661.668 | AI34: 75648.523 | AJ34: 76648.421 | AK34: 18.181818 | AL34: 78688.041 | AM34: 79612.862 | AN34: 80548.552 | AO34: 81495.239 | AP34: 82453.052 | AQ34: 83422.123
